Workbook
Name UPDATE: 'Data Sheet'!$E$1
Name UPDATE: #REF!

Sheet AI Valuation Summary
A1: Maruti Suzuki India Ltd (MARUTI) - Institutional Valuation
A4: Current Price | B4: Intrinsic Value | C4: Margin of Safety | D4: Verdict | E4: WACC | F4: Altman Z-Score | G4: DuPont ROE
A5: =DCF!D44 | B5: =DCF!D42 | C5: =(B5-A5)/A5 | D5: =IF(C5>0.15,"UNDERVALUED / BUY",IF(C5<-0.15,"OVERVALUED / SELL","FAIRLY VALUED / HOLD")) | E5: =DCF!D20 | F5: ='Altman''s Z Score'!I89 | G5: ='Dupont Analysis'!I78
A7: THE 4 CORE VALUATION PILLARS
A8: Pillar 1: FCF Engine | B8: CFO ₹19100.0 Cr vs PAT ₹14680.0 Cr | EBIT Mgn 10.56% | CCC -19.0 days
A9: Pillar 2: Growth Trajectory | B9: 3Y Sales CAGR 11.6% | 5Y CAGR 17.42% | Forecast g 5.2% | Terminal g 4.0%
A10: Pillar 3: Cost of Capital (WACC) | B10: WACC 12.05% | Ke 12.73% | Beta 0.88 | ERP 6.5% | Rf 7.0%
A11: Pillar 4: Relative Multiples | B11: P/E 26.6x | P/B 3.55x | EV/EBITDA 5.6x | EV/Sales 0.66x
A13: 5-Year Discounted Cash Flow (DCF) Schedule (Amounts in ₹ Cr)
A14: Year | B14: EBIT | C14: NOPAT | D14: Reinvest Rate | E14: FCFF | F14: Discount Factor | G14: PV of FCFF
A15: Year 1 | B15: =DCF!I8 | C15: =DCF!I10 | D15: =DCF!I11 | E15: =DCF!I12 | F15: =DCF!I14 | G15: =DCF!I16
A16: Year 2 | B16: =DCF!J8 | C16: =DCF!J10 | D16: =DCF!J11 | E16: =DCF!J12 | F16: =DCF!J14 | G16: =DCF!J16
A17: Year 3 | B17: =DCF!K8 | C17: =DCF!K10 | D17: =DCF!K11 | E17: =DCF!K12 | F17: =DCF!K14 | G17: =DCF!K16
A18: Year 4 | B18: =DCF!L8 | C18: =DCF!L10 | D18: =DCF!L11 | E18: =DCF!L12 | F18: =DCF!L14 | G18: =DCF!L16
A19: Year 5 | B19: =DCF!M8 | C19: =DCF!M10 | D19: =DCF!M11 | E19: =DCF!M12 | F19: =DCF!M14 | G19: =DCF!M16
A21: Enterprise to Equity Value Bridge
A22: PV of 5-Year FCFFs | B22: =DCF!D33
A23: Terminal Value | B23: =DCF!D29
A24: PV of Terminal Value | B24: =DCF!D34
A25: Enterprise Value (Operating Assets) | B25: =DCF!D35
A26: Add: Estimated Cash & Liquid Assets | B26: =DCF!D37
A27: Less: Total Debt & Borrowings | B27: =DCF!D38
A28: Net Equity Value | B28: =DCF!D39
A29: Shares Outstanding | B29: =DCF!D40
A30: Intrinsic Value per Share | B30: =DCF!D42
A31: Current Market Price | B31: =DCF!D44
A32: Margin of Safety / Discount | B32: =(B5-A5)/A5

Sheet Profit & Loss
A1: ='Data Sheet'!B1 | H1: =UPDATE | M1: SCREENER.IN
A3: Narration | B3: ='Data Sheet'!B16 | C3: ='Data Sheet'!C16 | D3: ='Data Sheet'!D16 | E3: ='Data Sheet'!E16 | F3: ='Data Sheet'!F16 | G3: ='Data Sheet'!G16 | H3: ='Data Sheet'!H16 | I3: ='Data Sheet'!I16 | ... K3: ='Data Sheet'!K16 | L3: Trailing | M3: Best Case | N3: Worst Case
A4: Sales | B4: ='Data Sheet'!B17 | C4: ='Data Sheet'!C17 | D4: ='Data Sheet'!D17 | E4: ='Data Sheet'!E17 | F4: ='Data Sheet'!F17 | G4: ='Data Sheet'!G17 | H4: ='Data Sheet'!H17 | I4: ='Data Sheet'!I17 | ... K4: ='Data Sheet'!K17 | L4: =SUM(Quarters!H4:K4) | M4: =$K4+M23*K4 | N4: =$K4+N23*L4
A5: Expenses | B5: =SUM('Data Sheet'!B18,'Data Sheet'!B20:B24, -1*'Data Sheet'!B19) | C5: =SUM('Data Sheet'!C18,'Data Sheet'!C20:C24, -1*'Data Sheet'!C19) | D5: =SUM('Data Sheet'!D18,'Data Sheet'!D20:D24, -1*'Data Sheet'!D19) | E5: =SUM('Data Sheet'!E18,'Data Sheet'!E20:E24, -1*'Data Sheet'!E19) | F5: =SUM('Data Sheet'!F18,'Data Sheet'!F20:F24, -1*'Data Sheet'!F19) | G5: =SUM('Data Sheet'!G18,'Data Sheet'!G20:G24, -1*'Data Sheet'!G19) | H5: =SUM('Data Sheet'!H18,'Data Sheet'!H20:H24, -1*'Data Sheet'!H19) | I5: =SUM('Data Sheet'!I18,'Data Sheet'!I20:I24, -1*'Data Sheet'!I19) | ... K5: =SUM('Data Sheet'!K18,'Data Sheet'!K20:K24, -1*'Data Sheet'!K19) | L5: =SUM(Quarters!H5:K5) | M5: =M4-M6 | N5: =N4-N6
A6: Operating Profit | B6: =B4-B5 | C6: =C4-C5 | D6: =D4-D5 | E6: =E4-E5 | F6: =F4-F5 | G6: =G4-G5 | H6: =H4-H5 | I6: =I4-I5 | ... K6: =K4-K5 | L6: =SUM(Quarters!H6:K6) | M6: =M4*M24 | N6: =N4*N24
A7: Other Income | B7: ='Data Sheet'!B25 | C7: ='Data Sheet'!C25 | D7: ='Data Sheet'!D25 | E7: ='Data Sheet'!E25 | F7: ='Data Sheet'!F25 | G7: ='Data Sheet'!G25 | H7: ='Data Sheet'!H25 | I7: ='Data Sheet'!I25 | ... K7: ='Data Sheet'!K25 | L7: =SUM(Quarters!H7:K7) | M7: 0 | N7: 0
A8: Depreciation | B8: ='Data Sheet'!B26 | C8: ='Data Sheet'!C26 | D8: ='Data Sheet'!D26 | E8: ='Data Sheet'!E26 | F8: ='Data Sheet'!F26 | G8: ='Data Sheet'!G26 | H8: ='Data Sheet'!H26 | I8: ='Data Sheet'!I26 | ... K8: ='Data Sheet'!K26 | L8: =SUM(Quarters!H8:K8) | M8: =+$L8 | N8: =+$L8
A9: Interest | B9: ='Data Sheet'!B27 | C9: ='Data Sheet'!C27 | D9: ='Data Sheet'!D27 | E9: ='Data Sheet'!E27 | F9: ='Data Sheet'!F27 | G9: ='Data Sheet'!G27 | H9: ='Data Sheet'!H27 | I9: ='Data Sheet'!I27 | ... K9: ='Data Sheet'!K27 | L9: =SUM(Quarters!H9:K9) | M9: =+$L9 | N9: =+$L9
A10: Profit before tax | B10: ='Data Sheet'!B28 | C10: ='Data Sheet'!C28 | D10: ='Data Sheet'!D28 | E10: ='Data Sheet'!E28 | F10: ='Data Sheet'!F28 | G10: ='Data Sheet'!G28 | H10: ='Data Sheet'!H28 | I10: ='Data Sheet'!I28 | ... K10: ='Data Sheet'!K28 | L10: =SUM(Quarters!H10:K10) | M10: =M6+M7-SUM(M8:M9) | N10: =N6+N7-SUM(N8:N9)
A11: Tax | B11: ='Data Sheet'!B29 | C11: ='Data Sheet'!C29 | D11: ='Data Sheet'!D29 | E11: ='Data Sheet'!E29 | F11: ='Data Sheet'!F29 | G11: ='Data Sheet'!G29 | H11: ='Data Sheet'!H29 | I11: ='Data Sheet'!I29 | ... K11: ='Data Sheet'!K29 | L11: =SUM(Quarters!H11:K11) | M11: =IF($L10>0,$L11/$L10,0) | N11: =IF($L10>0,$L11/$L10,0)
A12: Net profit | B12: ='Data Sheet'!B30 | C12: ='Data Sheet'!C30 | D12: ='Data Sheet'!D30 | E12: ='Data Sheet'!E30 | F12: ='Data Sheet'!F30 | G12: ='Data Sheet'!G30 | H12: ='Data Sheet'!H30 | I12: ='Data Sheet'!I30 | ... K12: ='Data Sheet'!K30 | L12: =SUM(Quarters!H12:K12) | M12: =M10-M11*M10 | N12: =N10-N11*N10
A13: EPS | B13: =IF('Data Sheet'!B93>0,B12/'Data Sheet'!B93,0) | C13: =IF('Data Sheet'!C93>0,C12/'Data Sheet'!C93,0) | D13: =IF('Data Sheet'!D93>0,D12/'Data Sheet'!D93,0) | E13: =IF('Data Sheet'!E93>0,E12/'Data Sheet'!E93,0) | F13: =IF('Data Sheet'!F93>0,F12/'Data Sheet'!F93,0) | G13: =IF('Data Sheet'!G93>0,G12/'Data Sheet'!G93,0) | H13: =IF('Data Sheet'!H93>0,H12/'Data Sheet'!H93,0) | I13: =IF('Data Sheet'!I93>0,I12/'Data Sheet'!I93,0) | ... K13: =IF('Data Sheet'!K93>0,K12/'Data Sheet'!K93,0) | L13: =IF('Data Sheet'!$B6>0,'Profit & Loss'!L12/'Data Sheet'!$B6,0) | M13: =IF('Data Sheet'!$B6>0,'Profit & Loss'!M12/'Data Sheet'!$B6,0) | N13: =IF('Data Sheet'!$B6>0,'Profit & Loss'!N12/'Data Sheet'!$B6,0)
A14: Price to earning | B14: =IF(B15>0,B15/B13,"") | C14: =IF(C15>0,C15/C13,"") | D14: =IF(D15>0,D15/D13,"") | E14: =IF(E15>0,E15/E13,"") | F14: =IF(F15>0,F15/F13,"") | G14: =IF(G15>0,G15/G13,"") | H14: =IF(H15>0,H15/H13,"") | I14: =IF(I15>0,I15/I13,"") | ... K14: =IF(K15>0,K15/K13,"") | L14: =IF(L13>0,L15/L13,0) | M14: =M25 | N14: =N25
A15: Price | B15: ='Data Sheet'!B90 | C15: ='Data Sheet'!C90 | D15: ='Data Sheet'!D90 | E15: ='Data Sheet'!E90 | F15: ='Data Sheet'!F90 | G15: ='Data Sheet'!G90 | H15: ='Data Sheet'!H90 | I15: ='Data Sheet'!I90 | ... K15: ='Data Sheet'!K90 | L15: ='Data Sheet'!B8 | M15: =M13*M14 | N15: =N13*N14
A17: RATIOS:
A18: Dividend Payout | B18: =IF('Data Sheet'!B30>0, 'Data Sheet'!B31/'Data Sheet'!B30, 0) | C18: =IF('Data Sheet'!C30>0, 'Data Sheet'!C31/'Data Sheet'!C30, 0) | D18: =IF('Data Sheet'!D30>0, 'Data Sheet'!D31/'Data Sheet'!D30, 0) | E18: =IF('Data Sheet'!E30>0, 'Data Sheet'!E31/'Data Sheet'!E30, 0) | F18: =IF('Data Sheet'!F30>0, 'Data Sheet'!F31/'Data Sheet'!F30, 0) | G18: =IF('Data Sheet'!G30>0, 'Data Sheet'!G31/'Data Sheet'!G30, 0) | H18: =IF('Data Sheet'!H30>0, 'Data Sheet'!H31/'Data Sheet'!H30, 0) | I18: =IF('Data Sheet'!I30>0, 'Data Sheet'!I31/'Data Sheet'!I30, 0) | ... K18: =IF('Data Sheet'!K30>0, 'Data Sheet'!K31/'Data Sheet'!K30, 0)
A19: OPM | B19: =IF(B6>0,B6/B4,0) | C19: =IF(C6>0,C6/C4,0) | D19: =IF(D6>0,D6/D4,0) | E19: =IF(E6>0,E6/E4,0) | F19: =IF(F6>0,F6/F4,0) | G19: =IF(G6>0,G6/G4,0) | H19: =IF(H6>0,H6/H4,0) | I19: =IF(I6>0,I6/I4,0) | ... L19: =IF(L6>0,L6/L4,0)
G22: TRENDS: | H22: 10 YEARS | I22: 7 YEARS | J22: 5 YEARS | K22: 3 YEARS | L22: RECENT | M22: BEST | N22: WORST
G23: Sales Growth | H23: =IF(B4=0,"",POWER($K4/B4,1/9)-1) | I23: =IF(D4=0,"",POWER($K4/D4,1/7)-1) | J23: =IF(F4=0,"",POWER($K4/F4,1/5)-1) | K23: =IF(H4=0,"",POWER($K4/H4, 1/3)-1) | L23: =IF(ISERROR(MAX(IF(J4=0,"",(K4-J4)/J4),IF(K4=0,"",(L4-K4)/K4))),"",MAX(IF(J4=0,"",(K4-J4)/J4),IF(K4=0,"",(L4-K4)/K4))) | M23: =MAX(K23:L23) | N23: =MIN(H23:L23)
G24: OPM | H24: =IF(SUM(B4:$K$4)=0,"",SUMPRODUCT(B19:$K$19,B4:$K$4)/SUM(B4:$K$4)) | I24: =IF(SUM(E4:$K$4)=0,"",SUMPRODUCT(E19:$K$19,E4:$K$4)/SUM(E4:$K$4)) | J24: =IF(SUM(G4:$K$4)=0,"",SUMPRODUCT(G19:$K$19,G4:$K$4)/SUM(G4:$K$4)) | K24: =IF(SUM(I4:$K$4)=0, "", SUMPRODUCT(I19:$K$19,I4:$K$4)/SUM(I4:$K$4)) | L24: =L19 | M24: =MAX(K24:L24) | N24: =MIN(H24:L24)
G25: Price to Earning | H25: =IF(ISERROR(AVERAGEIF(B14:$L14,">0")),"",AVERAGEIF(B14:$L14,">0")) | I25: =IF(ISERROR(AVERAGEIF(E14:$L14,">0")),"",AVERAGEIF(E14:$L14,">0")) | J25: =IF(ISERROR(AVERAGEIF(G14:$L14,">0")),"",AVERAGEIF(G14:$L14,">0")) | K25: =IF(ISERROR(AVERAGEIF(I14:$L14,">0")),"",AVERAGEIF(I14:$L14,">0")) | L25: =L14 | M25: =MAX(K25:L25) | N25: =MIN(H25:L25)

Sheet Quarters
A1: ='Profit & Loss'!A1 | E1: =UPDATE | J1: SCREENER.IN
A3: Narration | B3: ='Data Sheet'!B41 | C3: ='Data Sheet'!C41 | D3: ='Data Sheet'!D41 | E3: ='Data Sheet'!E41 | F3: ='Data Sheet'!F41 | G3: ='Data Sheet'!G41 | H3: ='Data Sheet'!H41 | I3: ='Data Sheet'!I41 | ... K3: ='Data Sheet'!K41
A4: Sales | B4: ='Data Sheet'!B42 | C4: ='Data Sheet'!C42 | D4: ='Data Sheet'!D42 | E4: ='Data Sheet'!E42 | F4: ='Data Sheet'!F42 | G4: ='Data Sheet'!G42 | H4: ='Data Sheet'!H42 | I4: ='Data Sheet'!I42 | ... K4: ='Data Sheet'!K42
A5: Expenses | B5: ='Data Sheet'!B43 | C5: ='Data Sheet'!C43 | D5: ='Data Sheet'!D43 | E5: ='Data Sheet'!E43 | F5: ='Data Sheet'!F43 | G5: ='Data Sheet'!G43 | H5: ='Data Sheet'!H43 | I5: ='Data Sheet'!I43 | ... K5: ='Data Sheet'!K43
A6: Operating Profit | B6: ='Data Sheet'!B50 | C6: ='Data Sheet'!C50 | D6: ='Data Sheet'!D50 | E6: ='Data Sheet'!E50 | F6: ='Data Sheet'!F50 | G6: ='Data Sheet'!G50 | H6: ='Data Sheet'!H50 | I6: ='Data Sheet'!I50 | ... K6: ='Data Sheet'!K50
A7: Other Income | B7: ='Data Sheet'!B44 | C7: ='Data Sheet'!C44 | D7: ='Data Sheet'!D44 | E7: ='Data Sheet'!E44 | F7: ='Data Sheet'!F44 | G7: ='Data Sheet'!G44 | H7: ='Data Sheet'!H44 | I7: ='Data Sheet'!I44 | ... K7: ='Data Sheet'!K44
A8: Depreciation | B8: ='Data Sheet'!B45 | C8: ='Data Sheet'!C45 | D8: ='Data Sheet'!D45 | E8: ='Data Sheet'!E45 | F8: ='Data Sheet'!F45 | G8: ='Data Sheet'!G45 | H8: ='Data Sheet'!H45 | I8: ='Data Sheet'!I45 | ... K8: ='Data Sheet'!K45
A9: Interest | B9: ='Data Sheet'!B46 | C9: ='Data Sheet'!C46 | D9: ='Data Sheet'!D46 | E9: ='Data Sheet'!E46 | F9: ='Data Sheet'!F46 | G9: ='Data Sheet'!G46 | H9: ='Data Sheet'!H46 | I9: ='Data Sheet'!I46 | ... K9: ='Data Sheet'!K46
A10: Profit before tax | B10: ='Data Sheet'!B47 | C10: ='Data Sheet'!C47 | D10: ='Data Sheet'!D47 | E10: ='Data Sheet'!E47 | F10: ='Data Sheet'!F47 | G10: ='Data Sheet'!G47 | H10: ='Data Sheet'!H47 | I10: ='Data Sheet'!I47 | ... K10: ='Data Sheet'!K47
A11: Tax | B11: ='Data Sheet'!B48 | C11: ='Data Sheet'!C48 | D11: ='Data Sheet'!D48 | E11: ='Data Sheet'!E48 | F11: ='Data Sheet'!F48 | G11: ='Data Sheet'!G48 | H11: ='Data Sheet'!H48 | I11: ='Data Sheet'!I48 | ... K11: ='Data Sheet'!K48
A12: Net profit | B12: ='Data Sheet'!B49 | C12: ='Data Sheet'!C49 | D12: ='Data Sheet'!D49 | E12: ='Data Sheet'!E49 | F12: ='Data Sheet'!F49 | G12: ='Data Sheet'!G49 | H12: ='Data Sheet'!H49 | I12: ='Data Sheet'!I49 | ... K12: ='Data Sheet'!K49
A14: OPM | B14: =IF(B4>0,B6/B4,"") | C14: =IF(C4>0,C6/C4,"") | D14: =IF(D4>0,D6/D4,"") | E14: =IF(E4>0,E6/E4,"") | F14: =IF(F4>0,F6/F4,"") | G14: =IF(G4>0,G6/G4,"") | H14: =IF(H4>0,H6/H4,"") | I14: =IF(I4>0,I6/I4,"") | ... K14: =IF(K4>0,K6/K4,"")

Sheet Balance Sheet
A1: ='Profit & Loss'!A1 | E1: =UPDATE | J1: SCREENER.IN
A3: Narration | B3: ='Data Sheet'!B56 | C3: ='Data Sheet'!C56 | D3: ='Data Sheet'!D56 | E3: ='Data Sheet'!E56 | F3: ='Data Sheet'!F56 | G3: ='Data Sheet'!G56 | H3: ='Data Sheet'!H56 | I3: ='Data Sheet'!I56 | ... K3: ='Data Sheet'!K56
A4: Equity Share Capital | B4: ='Data Sheet'!B57 | C4: ='Data Sheet'!C57 | D4: ='Data Sheet'!D57 | E4: ='Data Sheet'!E57 | F4: ='Data Sheet'!F57 | G4: ='Data Sheet'!G57 | H4: ='Data Sheet'!H57 | I4: ='Data Sheet'!I57 | ... K4: ='Data Sheet'!K57
A5: Reserves | B5: ='Data Sheet'!B58 | C5: ='Data Sheet'!C58 | D5: ='Data Sheet'!D58 | E5: ='Data Sheet'!E58 | F5: ='Data Sheet'!F58 | G5: ='Data Sheet'!G58 | H5: ='Data Sheet'!H58 | I5: ='Data Sheet'!I58 | ... K5: ='Data Sheet'!K58
A6: Borrowings | B6: ='Data Sheet'!B59 | C6: ='Data Sheet'!C59 | D6: ='Data Sheet'!D59 | E6: ='Data Sheet'!E59 | F6: ='Data Sheet'!F59 | G6: ='Data Sheet'!G59 | H6: ='Data Sheet'!H59 | I6: ='Data Sheet'!I59 | ... K6: ='Data Sheet'!K59
A7: Other Liabilities | B7: ='Data Sheet'!B60 | C7: ='Data Sheet'!C60 | D7: ='Data Sheet'!D60 | E7: ='Data Sheet'!E60 | F7: ='Data Sheet'!F60 | G7: ='Data Sheet'!G60 | H7: ='Data Sheet'!H60 | I7: ='Data Sheet'!I60 | ... K7: ='Data Sheet'!K60
A8: Total | B8: ='Data Sheet'!B61 | C8: ='Data Sheet'!C61 | D8: ='Data Sheet'!D61 | E8: ='Data Sheet'!E61 | F8: ='Data Sheet'!F61 | G8: ='Data Sheet'!G61 | H8: ='Data Sheet'!H61 | I8: ='Data Sheet'!I61 | ... K8: ='Data Sheet'!K61
A10: Net Block | B10: ='Data Sheet'!B62 | C10: ='Data Sheet'!C62 | D10: ='Data Sheet'!D62 | E10: ='Data Sheet'!E62 | F10: ='Data Sheet'!F62 | G10: ='Data Sheet'!G62 | H10: ='Data Sheet'!H62 | I10: ='Data Sheet'!I62 | ... K10: ='Data Sheet'!K62
A11: Capital Work in Progress | B11: ='Data Sheet'!B63 | C11: ='Data Sheet'!C63 | D11: ='Data Sheet'!D63 | E11: ='Data Sheet'!E63 | F11: ='Data Sheet'!F63 | G11: ='Data Sheet'!G63 | H11: ='Data Sheet'!H63 | I11: ='Data Sheet'!I63 | ... K11: ='Data Sheet'!K63
A12: Investments | B12: ='Data Sheet'!B64 | C12: ='Data Sheet'!C64 | D12: ='Data Sheet'!D64 | E12: ='Data Sheet'!E64 | F12: ='Data Sheet'!F64 | G12: ='Data Sheet'!G64 | H12: ='Data Sheet'!H64 | I12: ='Data Sheet'!I64 | ... K12: ='Data Sheet'!K64
A13: Other Assets | B13: ='Data Sheet'!B65 | C13: ='Data Sheet'!C65 | D13: ='Data Sheet'!D65 | E13: ='Data Sheet'!E65 | F13: ='Data Sheet'!F65 | G13: ='Data Sheet'!G65 | H13: ='Data Sheet'!H65 | I13: ='Data Sheet'!I65 | ... K13: ='Data Sheet'!K65
A14: Total | B14: ='Data Sheet'!B66 | C14: ='Data Sheet'!C66 | D14: ='Data Sheet'!D66 | E14: ='Data Sheet'!E66 | F14: ='Data Sheet'!F66 | G14: ='Data Sheet'!G66 | H14: ='Data Sheet'!H66 | I14: ='Data Sheet'!I66 | ... K14: ='Data Sheet'!K66
A16: Working Capital | B16: =B13-B7 | C16: =C13-C7 | D16: =D13-D7 | E16: =E13-E7 | F16: =F13-F7 | G16: =G13-G7 | H16: =H13-H7 | I16: =I13-I7 | ... K16: =K13-K7
A17: Debtors | B17: ='Data Sheet'!B67 | C17: ='Data Sheet'!C67 | D17: ='Data Sheet'!D67 | E17: ='Data Sheet'!E67 | F17: ='Data Sheet'!F67 | G17: ='Data Sheet'!G67 | H17: ='Data Sheet'!H67 | I17: ='Data Sheet'!I67 | ... K17: ='Data Sheet'!K67
A18: Inventory | B18: ='Data Sheet'!B68 | C18: ='Data Sheet'!C68 | D18: ='Data Sheet'!D68 | E18: ='Data Sheet'!E68 | F18: ='Data Sheet'!F68 | G18: ='Data Sheet'!G68 | H18: ='Data Sheet'!H68 | I18: ='Data Sheet'!I68 | ... K18: ='Data Sheet'!K68
A20: Debtor Days | B20: =IF('Profit & Loss'!B4>0,'Balance Sheet'!B17/('Profit & Loss'!B4/365),0) | C20: =IF('Profit & Loss'!C4>0,'Balance Sheet'!C17/('Profit & Loss'!C4/365),0) | D20: =IF('Profit & Loss'!D4>0,'Balance Sheet'!D17/('Profit & Loss'!D4/365),0) | E20: =IF('Profit & Loss'!E4>0,'Balance Sheet'!E17/('Profit & Loss'!E4/365),0) | F20: =IF('Profit & Loss'!F4>0,'Balance Sheet'!F17/('Profit & Loss'!F4/365),0) | G20: =IF('Profit & Loss'!G4>0,'Balance Sheet'!G17/('Profit & Loss'!G4/365),0) | H20: =IF('Profit & Loss'!H4>0,'Balance Sheet'!H17/('Profit & Loss'!H4/365),0) | I20: =IF('Profit & Loss'!I4>0,'Balance Sheet'!I17/('Profit & Loss'!I4/365),0) | ... K20: =IF('Profit & Loss'!K4>0,'Balance Sheet'!K17/('Profit & Loss'!K4/365),0)
A21: Inventory Turnover | B21: =IF('Balance Sheet'!B18>0,'Profit & Loss'!B4/'Balance Sheet'!B18,0) | C21: =IF('Balance Sheet'!C18>0,'Profit & Loss'!C4/'Balance Sheet'!C18,0) | D21: =IF('Balance Sheet'!D18>0,'Profit & Loss'!D4/'Balance Sheet'!D18,0) | E21: =IF('Balance Sheet'!E18>0,'Profit & Loss'!E4/'Balance Sheet'!E18,0) | F21: =IF('Balance Sheet'!F18>0,'Profit & Loss'!F4/'Balance Sheet'!F18,0) | G21: =IF('Balance Sheet'!G18>0,'Profit & Loss'!G4/'Balance Sheet'!G18,0) | H21: =IF('Balance Sheet'!H18>0,'Profit & Loss'!H4/'Balance Sheet'!H18,0) | I21: =IF('Balance Sheet'!I18>0,'Profit & Loss'!I4/'Balance Sheet'!I18,0) | ... K21: =IF('Balance Sheet'!K18>0,'Profit & Loss'!K4/'Balance Sheet'!K18,0)
A23: Return on Equity | B23: =IF(SUM('Balance Sheet'!B4:B5)>0,'Profit & Loss'!B12/SUM('Balance Sheet'!B4:B5),"") | C23: =IF(SUM('Balance Sheet'!C4:C5)>0,'Profit & Loss'!C12/SUM('Balance Sheet'!C4:C5),"") | D23: =IF(SUM('Balance Sheet'!D4:D5)>0,'Profit & Loss'!D12/SUM('Balance Sheet'!D4:D5),"") | E23: =IF(SUM('Balance Sheet'!E4:E5)>0,'Profit & Loss'!E12/SUM('Balance Sheet'!E4:E5),"") | F23: =IF(SUM('Balance Sheet'!F4:F5)>0,'Profit & Loss'!F12/SUM('Balance Sheet'!F4:F5),"") | G23: =IF(SUM('Balance Sheet'!G4:G5)>0,'Profit & Loss'!G12/SUM('Balance Sheet'!G4:G5),"") | H23: =IF(SUM('Balance Sheet'!H4:H5)>0,'Profit & Loss'!H12/SUM('Balance Sheet'!H4:H5),"") | I23: =IF(SUM('Balance Sheet'!I4:I5)>0,'Profit & Loss'!I12/SUM('Balance Sheet'!I4:I5),"") | ... K23: =IF(SUM('Balance Sheet'!K4:K5)>0,'Profit & Loss'!K12/SUM('Balance Sheet'!K4:K5),"")
A24: Return on Capital Emp | C24: =IF((B4+B5+B6+C4+C5+C6)>0,('Profit & Loss'!C10+'Profit & Loss'!C9)*2/(B4+B5+B6+C4+C5+C6),"") | D24: =IF((C4+C5+C6+D4+D5+D6)>0,('Profit & Loss'!D10+'Profit & Loss'!D9)*2/(C4+C5+C6+D4+D5+D6),"") | E24: =IF((D4+D5+D6+E4+E5+E6)>0,('Profit & Loss'!E10+'Profit & Loss'!E9)*2/(D4+D5+D6+E4+E5+E6),"") | F24: =IF((E4+E5+E6+F4+F5+F6)>0,('Profit & Loss'!F10+'Profit & Loss'!F9)*2/(E4+E5+E6+F4+F5+F6),"") | G24: =IF((F4+F5+F6+G4+G5+G6)>0,('Profit & Loss'!G10+'Profit & Loss'!G9)*2/(F4+F5+F6+G4+G5+G6),"") | H24: =IF((G4+G5+G6+H4+H5+H6)>0,('Profit & Loss'!H10+'Profit & Loss'!H9)*2/(G4+G5+G6+H4+H5+H6),"") | I24: =IF((H4+H5+H6+I4+I5+I6)>0,('Profit & Loss'!I10+'Profit & Loss'!I9)*2/(H4+H5+H6+I4+I5+I6),"") | J24: =IF((I4+I5+I6+J4+J5+J6)>0,('Profit & Loss'!J10+'Profit & Loss'!J9)*2/(I4+I5+I6+J4+J5+J6),"") | K24: =IF((J4+J5+J6+K4+K5+K6)>0,('Profit & Loss'!K10+'Profit & Loss'!K9)*2/(J4+J5+J6+K4+K5+K6),"")

Sheet Cash Flow
A1: ='Balance Sheet'!A1 | E1: =UPDATE | J1: SCREENER.IN
A3: Narration | B3: ='Data Sheet'!B81 | C3: ='Data Sheet'!C81 | D3: ='Data Sheet'!D81 | E3: ='Data Sheet'!E81 | F3: ='Data Sheet'!F81 | G3: ='Data Sheet'!G81 | H3: ='Data Sheet'!H81 | I3: ='Data Sheet'!I81 | ... K3: ='Data Sheet'!K81
A4: Cash from Operating Activity | B4: ='Data Sheet'!B82 | C4: ='Data Sheet'!C82 | D4: ='Data Sheet'!D82 | E4: ='Data Sheet'!E82 | F4: ='Data Sheet'!F82 | G4: ='Data Sheet'!G82 | H4: ='Data Sheet'!H82 | I4: ='Data Sheet'!I82 | ... K4: ='Data Sheet'!K82
A5: Cash from Investing Activity | B5: ='Data Sheet'!B83 | C5: ='Data Sheet'!C83 | D5: ='Data Sheet'!D83 | E5: ='Data Sheet'!E83 | F5: ='Data Sheet'!F83 | G5: ='Data Sheet'!G83 | H5: ='Data Sheet'!H83 | I5: ='Data Sheet'!I83 | ... K5: ='Data Sheet'!K83
A6: Cash from Financing Activity | B6: ='Data Sheet'!B84 | C6: ='Data Sheet'!C84 | D6: ='Data Sheet'!D84 | E6: ='Data Sheet'!E84 | F6: ='Data Sheet'!F84 | G6: ='Data Sheet'!G84 | H6: ='Data Sheet'!H84 | I6: ='Data Sheet'!I84 | ... K6: ='Data Sheet'!K84
A7: Net Cash Flow | B7: ='Data Sheet'!B85 | C7: ='Data Sheet'!C85 | D7: ='Data Sheet'!D85 | E7: ='Data Sheet'!E85 | F7: ='Data Sheet'!F85 | G7: ='Data Sheet'!G85 | H7: ='Data Sheet'!H85 | I7: ='Data Sheet'!I85 | ... K7: ='Data Sheet'!K85

Sheet Customization
A1: How to use it?
A3: You can customize this workbook as you want.
B4: You can add custom formating, add conditional formating, add your own formulas… do ANYTHING.
B5: Please don't edit the "Data Sheet" only.
A7: After customization, you can upload this back on Screener.
B8: Upload on: | C8: https://www.screener.in/excel/
A10: Download your customized workbooks now onwards.
B11: Now whenever you will "Export to excel" from Screener, it will export your customized file.
A14: TESTING:
B15: This is a testing feature currently.
B16: You can report any formula errors on the worksheet at: support@screener.in

Sheet Common Size Statement
B2: ="Common Size Statement - "&'Data Sheet'!$B$1
B4: Particulars | C4: ='Data Sheet'!B$16 | D4: ='Data Sheet'!C$16 | E4: ='Data Sheet'!D$16 | F4: ='Data Sheet'!E$16 | G4: ='Data Sheet'!F$16 | H4: ='Data Sheet'!G$16 | I4: ='Data Sheet'!H$16 | J4: ='Data Sheet'!I$16 | ... L4: ='Data Sheet'!K$16
B6: =IF(OR(ISBLANK('Data Sheet'!B$17), 'Data Sheet'!B$17<=0), "N/A", IFERROR('Data Sheet'!B6/'Data Sheet'!B$17, "N/A")) | C6: =IF(OR(ISBLANK('Data Sheet'!C$17), 'Data Sheet'!C$17<=0), "N/A", IFERROR('Data Sheet'!C6/'Data Sheet'!C$17, "N/A")) | D6: =IF(OR(ISBLANK('Data Sheet'!D$17), 'Data Sheet'!D$17<=0), "N/A", IFERROR('Data Sheet'!D6/'Data Sheet'!D$17, "N/A")) | E6: =IF(OR(ISBLANK('Data Sheet'!E$17), 'Data Sheet'!E$17<=0), "N/A", IFERROR('Data Sheet'!E6/'Data Sheet'!E$17, "N/A")) | F6: =IF(OR(ISBLANK('Data Sheet'!F$17), 'Data Sheet'!F$17<=0), "N/A", IFERROR('Data Sheet'!F6/'Data Sheet'!F$17, "N/A")) | G6: =IF(OR(ISBLANK('Data Sheet'!G$17), 'Data Sheet'!G$17<=0), "N/A", IFERROR('Data Sheet'!G6/'Data Sheet'!G$17, "N/A")) | H6: =IF(OR(ISBLANK('Data Sheet'!H$17), 'Data Sheet'!H$17<=0), "N/A", IFERROR('Data Sheet'!H6/'Data Sheet'!H$17, "N/A")) | I6: =IF(OR(ISBLANK('Data Sheet'!I$17), 'Data Sheet'!I$17<=0), "N/A", IFERROR('Data Sheet'!I6/'Data Sheet'!I$17, "N/A")) | ... K6: =IF(OR(ISBLANK('Data Sheet'!K$17), 'Data Sheet'!K$17<=0), "N/A", IFERROR('Data Sheet'!K6/'Data Sheet'!K$17, "N/A")) | L6: ='Data Sheet'!K17/'Data Sheet'!K$17
B7: =IF(OR(ISBLANK('Data Sheet'!B$17), 'Data Sheet'!B$17<=0), "N/A", IFERROR('Data Sheet'!B7/'Data Sheet'!B$17, "N/A")) | C7: =IF(OR(ISBLANK('Data Sheet'!C$17), 'Data Sheet'!C$17<=0), "N/A", IFERROR('Data Sheet'!C7/'Data Sheet'!C$17, "N/A")) | D7: =IF(OR(ISBLANK('Data Sheet'!D$17), 'Data Sheet'!D$17<=0), "N/A", IFERROR('Data Sheet'!D7/'Data Sheet'!D$17, "N/A")) | E7: =IF(OR(ISBLANK('Data Sheet'!E$17), 'Data Sheet'!E$17<=0), "N/A", IFERROR('Data Sheet'!E7/'Data Sheet'!E$17, "N/A")) | F7: =IF(OR(ISBLANK('Data Sheet'!F$17), 'Data Sheet'!F$17<=0), "N/A", IFERROR('Data Sheet'!F7/'Data Sheet'!F$17, "N/A")) | G7: =IF(OR(ISBLANK('Data Sheet'!G$17), 'Data Sheet'!G$17<=0), "N/A", IFERROR('Data Sheet'!G7/'Data Sheet'!G$17, "N/A")) | H7: =IF(OR(ISBLANK('Data Sheet'!H$17), 'Data Sheet'!H$17<=0), "N/A", IFERROR('Data Sheet'!H7/'Data Sheet'!H$17, "N/A")) | I7: =IF(OR(ISBLANK('Data Sheet'!I$17), 'Data Sheet'!I$17<=0), "N/A", IFERROR('Data Sheet'!I7/'Data Sheet'!I$17, "N/A")) | ... K7: =IF(OR(ISBLANK('Data Sheet'!K$17), 'Data Sheet'!K$17<=0), "N/A", IFERROR('Data Sheet'!K7/'Data Sheet'!K$17, "N/A")) | L7: ='Data Sheet'!K18/'Data Sheet'!K$17
B8: =IF(OR(ISBLANK('Data Sheet'!B$17), 'Data Sheet'!B$17<=0), "N/A", IFERROR('Data Sheet'!B8/'Data Sheet'!B$17, "N/A")) | C8: =IF(OR(ISBLANK('Data Sheet'!C$17), 'Data Sheet'!C$17<=0), "N/A", IFERROR('Data Sheet'!C8/'Data Sheet'!C$17, "N/A")) | D8: =IF(OR(ISBLANK('Data Sheet'!D$17), 'Data Sheet'!D$17<=0), "N/A", IFERROR('Data Sheet'!D8/'Data Sheet'!D$17, "N/A")) | E8: =IF(OR(ISBLANK('Data Sheet'!E$17), 'Data Sheet'!E$17<=0), "N/A", IFERROR('Data Sheet'!E8/'Data Sheet'!E$17, "N/A")) | F8: =IF(OR(ISBLANK('Data Sheet'!F$17), 'Data Sheet'!F$17<=0), "N/A", IFERROR('Data Sheet'!F8/'Data Sheet'!F$17, "N/A")) | G8: =IF(OR(ISBLANK('Data Sheet'!G$17), 'Data Sheet'!G$17<=0), "N/A", IFERROR('Data Sheet'!G8/'Data Sheet'!G$17, "N/A")) | H8: =IF(OR(ISBLANK('Data Sheet'!H$17), 'Data Sheet'!H$17<=0), "N/A", IFERROR('Data Sheet'!H8/'Data Sheet'!H$17, "N/A")) | I8: =IF(OR(ISBLANK('Data Sheet'!I$17), 'Data Sheet'!I$17<=0), "N/A", IFERROR('Data Sheet'!I8/'Data Sheet'!I$17, "N/A")) | ... K8: =IF(OR(ISBLANK('Data Sheet'!K$17), 'Data Sheet'!K$17<=0), "N/A", IFERROR('Data Sheet'!K8/'Data Sheet'!K$17, "N/A")) | L8: ='Data Sheet'!K19/'Data Sheet'!K$17
B9: =IF(OR(ISBLANK('Data Sheet'!B$17), 'Data Sheet'!B$17<=0), "N/A", IFERROR('Data Sheet'!B9/'Data Sheet'!B$17, "N/A")) | C9: =IF(OR(ISBLANK('Data Sheet'!C$17), 'Data Sheet'!C$17<=0), "N/A", IFERROR('Data Sheet'!C9/'Data Sheet'!C$17, "N/A")) | D9: =IF(OR(ISBLANK('Data Sheet'!D$17), 'Data Sheet'!D$17<=0), "N/A", IFERROR('Data Sheet'!D9/'Data Sheet'!D$17, "N/A")) | E9: =IF(OR(ISBLANK('Data Sheet'!E$17), 'Data Sheet'!E$17<=0), "N/A", IFERROR('Data Sheet'!E9/'Data Sheet'!E$17, "N/A")) | F9: =IF(OR(ISBLANK('Data Sheet'!F$17), 'Data Sheet'!F$17<=0), "N/A", IFERROR('Data Sheet'!F9/'Data Sheet'!F$17, "N/A")) | G9: =IF(OR(ISBLANK('Data Sheet'!G$17), 'Data Sheet'!G$17<=0), "N/A", IFERROR('Data Sheet'!G9/'Data Sheet'!G$17, "N/A")) | H9: =IF(OR(ISBLANK('Data Sheet'!H$17), 'Data Sheet'!H$17<=0), "N/A", IFERROR('Data Sheet'!H9/'Data Sheet'!H$17, "N/A")) | I9: =IF(OR(ISBLANK('Data Sheet'!I$17), 'Data Sheet'!I$17<=0), "N/A", IFERROR('Data Sheet'!I9/'Data Sheet'!I$17, "N/A")) | ... K9: =IF(OR(ISBLANK('Data Sheet'!K$17), 'Data Sheet'!K$17<=0), "N/A", IFERROR('Data Sheet'!K9/'Data Sheet'!K$17, "N/A")) | L9: ='Data Sheet'!K20/'Data Sheet'!K$17
B10: =IF(OR(ISBLANK('Data Sheet'!B$17), 'Data Sheet'!B$17<=0), "N/A", IFERROR('Data Sheet'!B10/'Data Sheet'!B$17, "N/A")) | C10: =IF(OR(ISBLANK('Data Sheet'!C$17), 'Data Sheet'!C$17<=0), "N/A", IFERROR('Data Sheet'!C10/'Data Sheet'!C$17, "N/A")) | D10: =IF(OR(ISBLANK('Data Sheet'!D$17), 'Data Sheet'!D$17<=0), "N/A", IFERROR('Data Sheet'!D10/'Data Sheet'!D$17, "N/A")) | E10: =IF(OR(ISBLANK('Data Sheet'!E$17), 'Data Sheet'!E$17<=0), "N/A", IFERROR('Data Sheet'!E10/'Data Sheet'!E$17, "N/A")) | F10: =IF(OR(ISBLANK('Data Sheet'!F$17), 'Data Sheet'!F$17<=0), "N/A", IFERROR('Data Sheet'!F10/'Data Sheet'!F$17, "N/A")) | G10: =IF(OR(ISBLANK('Data Sheet'!G$17), 'Data Sheet'!G$17<=0), "N/A", IFERROR('Data Sheet'!G10/'Data Sheet'!G$17, "N/A")) | H10: =IF(OR(ISBLANK('Data Sheet'!H$17), 'Data Sheet'!H$17<=0), "N/A", IFERROR('Data Sheet'!H10/'Data Sheet'!H$17, "N/A")) | I10: =IF(OR(ISBLANK('Data Sheet'!I$17), 'Data Sheet'!I$17<=0), "N/A", IFERROR('Data Sheet'!I10/'Data Sheet'!I$17, "N/A")) | ... K10: =IF(OR(ISBLANK('Data Sheet'!K$17), 'Data Sheet'!K$17<=0), "N/A", IFERROR('Data Sheet'!K10/'Data Sheet'!K$17, "N/A")) | L10: ='Data Sheet'!K21/'Data Sheet'!K$17
B11: =IF(OR(ISBLANK('Data Sheet'!B$17), 'Data Sheet'!B$17<=0), "N/A", IFERROR('Data Sheet'!B11/'Data Sheet'!B$17, "N/A")) | C11: =IF(OR(ISBLANK('Data Sheet'!C$17), 'Data Sheet'!C$17<=0), "N/A", IFERROR('Data Sheet'!C11/'Data Sheet'!C$17, "N/A")) | D11: =IF(OR(ISBLANK('Data Sheet'!D$17), 'Data Sheet'!D$17<=0), "N/A", IFERROR('Data Sheet'!D11/'Data Sheet'!D$17, "N/A")) | E11: =IF(OR(ISBLANK('Data Sheet'!E$17), 'Data Sheet'!E$17<=0), "N/A", IFERROR('Data Sheet'!E11/'Data Sheet'!E$17, "N/A")) | F11: =IF(OR(ISBLANK('Data Sheet'!F$17), 'Data Sheet'!F$17<=0), "N/A", IFERROR('Data Sheet'!F11/'Data Sheet'!F$17, "N/A")) | G11: =IF(OR(ISBLANK('Data Sheet'!G$17), 'Data Sheet'!G$17<=0), "N/A", IFERROR('Data Sheet'!G11/'Data Sheet'!G$17, "N/A")) | H11: =IF(OR(ISBLANK('Data Sheet'!H$17), 'Data Sheet'!H$17<=0), "N/A", IFERROR('Data Sheet'!H11/'Data Sheet'!H$17, "N/A")) | I11: =IF(OR(ISBLANK('Data Sheet'!I$17), 'Data Sheet'!I$17<=0), "N/A", IFERROR('Data Sheet'!I11/'Data Sheet'!I$17, "N/A")) | ... K11: =IF(OR(ISBLANK('Data Sheet'!K$17), 'Data Sheet'!K$17<=0), "N/A", IFERROR('Data Sheet'!K11/'Data Sheet'!K$17, "N/A")) | L11: ='Data Sheet'!K22/'Data Sheet'!K$17
B12: =IF(OR(ISBLANK('Data Sheet'!B$17), 'Data Sheet'!B$17<=0), "N/A", IFERROR('Data Sheet'!B12/'Data Sheet'!B$17, "N/A")) | C12: =IF(OR(ISBLANK('Data Sheet'!C$17), 'Data Sheet'!C$17<=0), "N/A", IFERROR('Data Sheet'!C12/'Data Sheet'!C$17, "N/A")) | D12: =IF(OR(ISBLANK('Data Sheet'!D$17), 'Data Sheet'!D$17<=0), "N/A", IFERROR('Data Sheet'!D12/'Data Sheet'!D$17, "N/A")) | E12: =IF(OR(ISBLANK('Data Sheet'!E$17), 'Data Sheet'!E$17<=0), "N/A", IFERROR('Data Sheet'!E12/'Data Sheet'!E$17, "N/A")) | F12: =IF(OR(ISBLANK('Data Sheet'!F$17), 'Data Sheet'!F$17<=0), "N/A", IFERROR('Data Sheet'!F12/'Data Sheet'!F$17, "N/A")) | G12: =IF(OR(ISBLANK('Data Sheet'!G$17), 'Data Sheet'!G$17<=0), "N/A", IFERROR('Data Sheet'!G12/'Data Sheet'!G$17, "N/A")) | H12: =IF(OR(ISBLANK('Data Sheet'!H$17), 'Data Sheet'!H$17<=0), "N/A", IFERROR('Data Sheet'!H12/'Data Sheet'!H$17, "N/A")) | I12: =IF(OR(ISBLANK('Data Sheet'!I$17), 'Data Sheet'!I$17<=0), "N/A", IFERROR('Data Sheet'!I12/'Data Sheet'!I$17, "N/A")) | ... K12: =IF(OR(ISBLANK('Data Sheet'!K$17), 'Data Sheet'!K$17<=0), "N/A", IFERROR('Data Sheet'!K12/'Data Sheet'!K$17, "N/A")) | L12: ='Data Sheet'!K23/'Data Sheet'!K$17
B13: =IF(OR(ISBLANK('Data Sheet'!B$17), 'Data Sheet'!B$17<=0), "N/A", IFERROR('Data Sheet'!B13/'Data Sheet'!B$17, "N/A")) | C13: =IF(OR(ISBLANK('Data Sheet'!C$17), 'Data Sheet'!C$17<=0), "N/A", IFERROR('Data Sheet'!C13/'Data Sheet'!C$17, "N/A")) | D13: =IF(OR(ISBLANK('Data Sheet'!D$17), 'Data Sheet'!D$17<=0), "N/A", IFERROR('Data Sheet'!D13/'Data Sheet'!D$17, "N/A")) | E13: =IF(OR(ISBLANK('Data Sheet'!E$17), 'Data Sheet'!E$17<=0), "N/A", IFERROR('Data Sheet'!E13/'Data Sheet'!E$17, "N/A")) | F13: =IF(OR(ISBLANK('Data Sheet'!F$17), 'Data Sheet'!F$17<=0), "N/A", IFERROR('Data Sheet'!F13/'Data Sheet'!F$17, "N/A")) | G13: =IF(OR(ISBLANK('Data Sheet'!G$17), 'Data Sheet'!G$17<=0), "N/A", IFERROR('Data Sheet'!G13/'Data Sheet'!G$17, "N/A")) | H13: =IF(OR(ISBLANK('Data Sheet'!H$17), 'Data Sheet'!H$17<=0), "N/A", IFERROR('Data Sheet'!H13/'Data Sheet'!H$17, "N/A")) | I13: =IF(OR(ISBLANK('Data Sheet'!I$17), 'Data Sheet'!I$17<=0), "N/A", IFERROR('Data Sheet'!I13/'Data Sheet'!I$17, "N/A")) | ... K13: =IF(OR(ISBLANK('Data Sheet'!K$17), 'Data Sheet'!K$17<=0), "N/A", IFERROR('Data Sheet'!K13/'Data Sheet'!K$17, "N/A")) | L13: ='Data Sheet'!K24/'Data Sheet'!K$17
B14: =IF(OR(ISBLANK('Data Sheet'!B$17), 'Data Sheet'!B$17<=0), "N/A", IFERROR('Data Sheet'!B14/'Data Sheet'!B$17, "N/A")) | C14: =IF(OR(ISBLANK('Data Sheet'!C$17), 'Data Sheet'!C$17<=0), "N/A", IFERROR('Data Sheet'!C14/'Data Sheet'!C$17, "N/A")) | D14: =IF(OR(ISBLANK('Data Sheet'!D$17), 'Data Sheet'!D$17<=0), "N/A", IFERROR('Data Sheet'!D14/'Data Sheet'!D$17, "N/A")) | E14: =IF(OR(ISBLANK('Data Sheet'!E$17), 'Data Sheet'!E$17<=0), "N/A", IFERROR('Data Sheet'!E14/'Data Sheet'!E$17, "N/A")) | F14: =IF(OR(ISBLANK('Data Sheet'!F$17), 'Data Sheet'!F$17<=0), "N/A", IFERROR('Data Sheet'!F14/'Data Sheet'!F$17, "N/A")) | G14: =IF(OR(ISBLANK('Data Sheet'!G$17), 'Data Sheet'!G$17<=0), "N/A", IFERROR('Data Sheet'!G14/'Data Sheet'!G$17, "N/A")) | H14: =IF(OR(ISBLANK('Data Sheet'!H$17), 'Data Sheet'!H$17<=0), "N/A", IFERROR('Data Sheet'!H14/'Data Sheet'!H$17, "N/A")) | I14: =IF(OR(ISBLANK('Data Sheet'!I$17), 'Data Sheet'!I$17<=0), "N/A", IFERROR('Data Sheet'!I14/'Data Sheet'!I$17, "N/A")) | ... K14: =IF(OR(ISBLANK('Data Sheet'!K$17), 'Data Sheet'!K$17<=0), "N/A", IFERROR('Data Sheet'!K14/'Data Sheet'!K$17, "N/A")) | L14: ='Data Sheet'!K25/'Data Sheet'!K$17
B15: =IF(OR(ISBLANK('Data Sheet'!B$17), 'Data Sheet'!B$17<=0), "N/A", IFERROR('Data Sheet'!B15/'Data Sheet'!B$17, "N/A")) | C15: =IF(OR(ISBLANK('Data Sheet'!C$17), 'Data Sheet'!C$17<=0), "N/A", IFERROR('Data Sheet'!C15/'Data Sheet'!C$17, "N/A")) | D15: =IF(OR(ISBLANK('Data Sheet'!D$17), 'Data Sheet'!D$17<=0), "N/A", IFERROR('Data Sheet'!D15/'Data Sheet'!D$17, "N/A")) | E15: =IF(OR(ISBLANK('Data Sheet'!E$17), 'Data Sheet'!E$17<=0), "N/A", IFERROR('Data Sheet'!E15/'Data Sheet'!E$17, "N/A")) | F15: =IF(OR(ISBLANK('Data Sheet'!F$17), 'Data Sheet'!F$17<=0), "N/A", IFERROR('Data Sheet'!F15/'Data Sheet'!F$17, "N/A")) | G15: =IF(OR(ISBLANK('Data Sheet'!G$17), 'Data Sheet'!G$17<=0), "N/A", IFERROR('Data Sheet'!G15/'Data Sheet'!G$17, "N/A")) | H15: =IF(OR(ISBLANK('Data Sheet'!H$17), 'Data Sheet'!H$17<=0), "N/A", IFERROR('Data Sheet'!H15/'Data Sheet'!H$17, "N/A")) | I15: =IF(OR(ISBLANK('Data Sheet'!I$17), 'Data Sheet'!I$17<=0), "N/A", IFERROR('Data Sheet'!I15/'Data Sheet'!I$17, "N/A")) | ... K15: =IF(OR(ISBLANK('Data Sheet'!K$17), 'Data Sheet'!K$17<=0), "N/A", IFERROR('Data Sheet'!K15/'Data Sheet'!K$17, "N/A")) | L15: ='Data Sheet'!K26/'Data Sheet'!K$17
B16: =IF(OR(ISBLANK('Data Sheet'!B$17), 'Data Sheet'!B$17<=0), "N/A", IFERROR('Data Sheet'!B16/'Data Sheet'!B$17, "N/A")) | C16: =IF(OR(ISBLANK('Data Sheet'!C$17), 'Data Sheet'!C$17<=0), "N/A", IFERROR('Data Sheet'!C16/'Data Sheet'!C$17, "N/A")) | D16: =IF(OR(ISBLANK('Data Sheet'!D$17), 'Data Sheet'!D$17<=0), "N/A", IFERROR('Data Sheet'!D16/'Data Sheet'!D$17, "N/A")) | E16: =IF(OR(ISBLANK('Data Sheet'!E$17), 'Data Sheet'!E$17<=0), "N/A", IFERROR('Data Sheet'!E16/'Data Sheet'!E$17, "N/A")) | F16: =IF(OR(ISBLANK('Data Sheet'!F$17), 'Data Sheet'!F$17<=0), "N/A", IFERROR('Data Sheet'!F16/'Data Sheet'!F$17, "N/A")) | G16: =IF(OR(ISBLANK('Data Sheet'!G$17), 'Data Sheet'!G$17<=0), "N/A", IFERROR('Data Sheet'!G16/'Data Sheet'!G$17, "N/A")) | H16: =IF(OR(ISBLANK('Data Sheet'!H$17), 'Data Sheet'!H$17<=0), "N/A", IFERROR('Data Sheet'!H16/'Data Sheet'!H$17, "N/A")) | I16: =IF(OR(ISBLANK('Data Sheet'!I$17), 'Data Sheet'!I$17<=0), "N/A", IFERROR('Data Sheet'!I16/'Data Sheet'!I$17, "N/A")) | ... K16: =IF(OR(ISBLANK('Data Sheet'!K$17), 'Data Sheet'!K$17<=0), "N/A", IFERROR('Data Sheet'!K16/'Data Sheet'!K$17, "N/A")) | L16: ='Data Sheet'!K27/'Data Sheet'!K$17
B17: =IF(OR(ISBLANK('Data Sheet'!B$17), 'Data Sheet'!B$17<=0), "N/A", IFERROR('Data Sheet'!B17/'Data Sheet'!B$17, "N/A")) | C17: =IF(OR(ISBLANK('Data Sheet'!C$17), 'Data Sheet'!C$17<=0), "N/A", IFERROR('Data Sheet'!C17/'Data Sheet'!C$17, "N/A")) | D17: =IF(OR(ISBLANK('Data Sheet'!D$17), 'Data Sheet'!D$17<=0), "N/A", IFERROR('Data Sheet'!D17/'Data Sheet'!D$17, "N/A")) | E17: =IF(OR(ISBLANK('Data Sheet'!E$17), 'Data Sheet'!E$17<=0), "N/A", IFERROR('Data Sheet'!E17/'Data Sheet'!E$17, "N/A")) | F17: =IF(OR(ISBLANK('Data Sheet'!F$17), 'Data Sheet'!F$17<=0), "N/A", IFERROR('Data Sheet'!F17/'Data Sheet'!F$17, "N/A")) | G17: =IF(OR(ISBLANK('Data Sheet'!G$17), 'Data Sheet'!G$17<=0), "N/A", IFERROR('Data Sheet'!G17/'Data Sheet'!G$17, "N/A")) | H17: =IF(OR(ISBLANK('Data Sheet'!H$17), 'Data Sheet'!H$17<=0), "N/A", IFERROR('Data Sheet'!H17/'Data Sheet'!H$17, "N/A")) | I17: =IF(OR(ISBLANK('Data Sheet'!I$17), 'Data Sheet'!I$17<=0), "N/A", IFERROR('Data Sheet'!I17/'Data Sheet'!I$17, "N/A")) | ... K17: =IF(OR(ISBLANK('Data Sheet'!K$17), 'Data Sheet'!K$17<=0), "N/A", IFERROR('Data Sheet'!K17/'Data Sheet'!K$17, "N/A")) | L17: ='Data Sheet'!K28/'Data Sheet'!K$17
... B21: =IF(OR(ISBLANK('Data Sheet'!B$17), 'Data Sheet'!B$17<=0), "N/A", IFERROR('Data Sheet'!B21/'Data Sheet'!B$17, "N/A")) | C21: =IF(OR(ISBLANK('Data Sheet'!C$17), 'Data Sheet'!C$17<=0), "N/A", IFERROR('Data Sheet'!C21/'Data Sheet'!C$17, "N/A")) | D21: =IF(OR(ISBLANK('Data Sheet'!D$17), 'Data Sheet'!D$17<=0), "N/A", IFERROR('Data Sheet'!D21/'Data Sheet'!D$17, "N/A")) | E21: =IF(OR(ISBLANK('Data Sheet'!E$17), 'Data Sheet'!E$17<=0), "N/A", IFERROR('Data Sheet'!E21/'Data Sheet'!E$17, "N/A")) | F21: =IF(OR(ISBLANK('Data Sheet'!F$17), 'Data Sheet'!F$17<=0), "N/A", IFERROR('Data Sheet'!F21/'Data Sheet'!F$17, "N/A")) | G21: =IF(OR(ISBLANK('Data Sheet'!G$17), 'Data Sheet'!G$17<=0), "N/A", IFERROR('Data Sheet'!G21/'Data Sheet'!G$17, "N/A")) | H21: =IF(OR(ISBLANK('Data Sheet'!H$17), 'Data Sheet'!H$17<=0), "N/A", IFERROR('Data Sheet'!H21/'Data Sheet'!H$17, "N/A")) | I21: =IF(OR(ISBLANK('Data Sheet'!I$17), 'Data Sheet'!I$17<=0), "N/A", IFERROR('Data Sheet'!I21/'Data Sheet'!I$17, "N/A")) | ... K21: =IF(OR(ISBLANK('Data Sheet'!K$17), 'Data Sheet'!K$17<=0), "N/A", IFERROR('Data Sheet'!K21/'Data Sheet'!K$17, "N/A")) | L21: ='Data Sheet'!K32/'Data Sheet'!K$17
B23: ="Common Size Balance Sheet - "&'Data Sheet'!$B$1
B25: Particulars | C25: ='Data Sheet'!B$16 | D25: ='Data Sheet'!C$16 | E25: ='Data Sheet'!D$16 | F25: ='Data Sheet'!E$16 | G25: ='Data Sheet'!F$16 | H25: ='Data Sheet'!G$16 | I25: ='Data Sheet'!H$16 | J25: ='Data Sheet'!I$16 | ... L25: ='Data Sheet'!K$16
B27: =IF(OR(ISBLANK('Data Sheet'!B$61), 'Data Sheet'!B$61<=0), "N/A", IFERROR('Data Sheet'!B61/'Data Sheet'!B$61, "N/A")) | C27: =IF(OR(ISBLANK('Data Sheet'!C$61), 'Data Sheet'!C$61<=0), "N/A", IFERROR('Data Sheet'!C61/'Data Sheet'!C$61, "N/A")) | D27: =IF(OR(ISBLANK('Data Sheet'!D$61), 'Data Sheet'!D$61<=0), "N/A", IFERROR('Data Sheet'!D61/'Data Sheet'!D$61, "N/A")) | E27: =IF(OR(ISBLANK('Data Sheet'!E$61), 'Data Sheet'!E$61<=0), "N/A", IFERROR('Data Sheet'!E61/'Data Sheet'!E$61, "N/A")) | F27: =IF(OR(ISBLANK('Data Sheet'!F$61), 'Data Sheet'!F$61<=0), "N/A", IFERROR('Data Sheet'!F61/'Data Sheet'!F$61, "N/A")) | G27: =IF(OR(ISBLANK('Data Sheet'!G$61), 'Data Sheet'!G$61<=0), "N/A", IFERROR('Data Sheet'!G61/'Data Sheet'!G$61, "N/A")) | H27: =IF(OR(ISBLANK('Data Sheet'!H$61), 'Data Sheet'!H$61<=0), "N/A", IFERROR('Data Sheet'!H61/'Data Sheet'!H$61, "N/A")) | I27: =IF(OR(ISBLANK('Data Sheet'!I$61), 'Data Sheet'!I$61<=0), "N/A", IFERROR('Data Sheet'!I61/'Data Sheet'!I$61, "N/A")) | ... K27: =IF(OR(ISBLANK('Data Sheet'!K$61), 'Data Sheet'!K$61<=0), "N/A", IFERROR('Data Sheet'!K61/'Data Sheet'!K$61, "N/A")) | L27: ='Data Sheet'!K61/'Data Sheet'!K$61
B28: =IF(OR(ISBLANK('Data Sheet'!B$61), 'Data Sheet'!B$61<=0), "N/A", IFERROR('Data Sheet'!B57/'Data Sheet'!B$61, "N/A")) | C28: =IF(OR(ISBLANK('Data Sheet'!C$61), 'Data Sheet'!C$61<=0), "N/A", IFERROR('Data Sheet'!C57/'Data Sheet'!C$61, "N/A")) | D28: =IF(OR(ISBLANK('Data Sheet'!D$61), 'Data Sheet'!D$61<=0), "N/A", IFERROR('Data Sheet'!D57/'Data Sheet'!D$61, "N/A")) | E28: =IF(OR(ISBLANK('Data Sheet'!E$61), 'Data Sheet'!E$61<=0), "N/A", IFERROR('Data Sheet'!E57/'Data Sheet'!E$61, "N/A")) | F28: =IF(OR(ISBLANK('Data Sheet'!F$61), 'Data Sheet'!F$61<=0), "N/A", IFERROR('Data Sheet'!F57/'Data Sheet'!F$61, "N/A")) | G28: =IF(OR(ISBLANK('Data Sheet'!G$61), 'Data Sheet'!G$61<=0), "N/A", IFERROR('Data Sheet'!G57/'Data Sheet'!G$61, "N/A")) | H28: =IF(OR(ISBLANK('Data Sheet'!H$61), 'Data Sheet'!H$61<=0), "N/A", IFERROR('Data Sheet'!H57/'Data Sheet'!H$61, "N/A")) | I28: =IF(OR(ISBLANK('Data Sheet'!I$61), 'Data Sheet'!I$61<=0), "N/A", IFERROR('Data Sheet'!I57/'Data Sheet'!I$61, "N/A")) | ... K28: =IF(OR(ISBLANK('Data Sheet'!K$61), 'Data Sheet'!K$61<=0), "N/A", IFERROR('Data Sheet'!K57/'Data Sheet'!K$61, "N/A")) | L28: ='Data Sheet'!K57/'Data Sheet'!K$61
B29: =IF(OR(ISBLANK('Data Sheet'!B$61), 'Data Sheet'!B$61<=0), "N/A", IFERROR('Data Sheet'!B58/'Data Sheet'!B$61, "N/A")) | C29: =IF(OR(ISBLANK('Data Sheet'!C$61), 'Data Sheet'!C$61<=0), "N/A", IFERROR('Data Sheet'!C58/'Data Sheet'!C$61, "N/A")) | D29: =IF(OR(ISBLANK('Data Sheet'!D$61), 'Data Sheet'!D$61<=0), "N/A", IFERROR('Data Sheet'!D58/'Data Sheet'!D$61, "N/A")) | E29: =IF(OR(ISBLANK('Data Sheet'!E$61), 'Data Sheet'!E$61<=0), "N/A", IFERROR('Data Sheet'!E58/'Data Sheet'!E$61, "N/A")) | F29: =IF(OR(ISBLANK('Data Sheet'!F$61), 'Data Sheet'!F$61<=0), "N/A", IFERROR('Data Sheet'!F58/'Data Sheet'!F$61, "N/A")) | G29: =IF(OR(ISBLANK('Data Sheet'!G$61), 'Data Sheet'!G$61<=0), "N/A", IFERROR('Data Sheet'!G58/'Data Sheet'!G$61, "N/A")) | H29: =IF(OR(ISBLANK('Data Sheet'!H$61), 'Data Sheet'!H$61<=0), "N/A", IFERROR('Data Sheet'!H58/'Data Sheet'!H$61, "N/A")) | I29: =IF(OR(ISBLANK('Data Sheet'!I$61), 'Data Sheet'!I$61<=0), "N/A", IFERROR('Data Sheet'!I58/'Data Sheet'!I$61, "N/A")) | ... K29: =IF(OR(ISBLANK('Data Sheet'!K$61), 'Data Sheet'!K$61<=0), "N/A", IFERROR('Data Sheet'!K58/'Data Sheet'!K$61, "N/A")) | L29: ='Data Sheet'!K58/'Data Sheet'!K$61
B30: =IF(OR(ISBLANK('Data Sheet'!B$61), 'Data Sheet'!B$61<=0), "N/A", IFERROR('Data Sheet'!B59/'Data Sheet'!B$61, "N/A")) | C30: =IF(OR(ISBLANK('Data Sheet'!C$61), 'Data Sheet'!C$61<=0), "N/A", IFERROR('Data Sheet'!C59/'Data Sheet'!C$61, "N/A")) | D30: =IF(OR(ISBLANK('Data Sheet'!D$61), 'Data Sheet'!D$61<=0), "N/A", IFERROR('Data Sheet'!D59/'Data Sheet'!D$61, "N/A")) | E30: =IF(OR(ISBLANK('Data Sheet'!E$61), 'Data Sheet'!E$61<=0), "N/A", IFERROR('Data Sheet'!E59/'Data Sheet'!E$61, "N/A")) | F30: =IF(OR(ISBLANK('Data Sheet'!F$61), 'Data Sheet'!F$61<=0), "N/A", IFERROR('Data Sheet'!F59/'Data Sheet'!F$61, "N/A")) | G30: =IF(OR(ISBLANK('Data Sheet'!G$61), 'Data Sheet'!G$61<=0), "N/A", IFERROR('Data Sheet'!G59/'Data Sheet'!G$61, "N/A")) | H30: =IF(OR(ISBLANK('Data Sheet'!H$61), 'Data Sheet'!H$61<=0), "N/A", IFERROR('Data Sheet'!H59/'Data Sheet'!H$61, "N/A")) | I30: =IF(OR(ISBLANK('Data Sheet'!I$61), 'Data Sheet'!I$61<=0), "N/A", IFERROR('Data Sheet'!I59/'Data Sheet'!I$61, "N/A")) | ... K30: =IF(OR(ISBLANK('Data Sheet'!K$61), 'Data Sheet'!K$61<=0), "N/A", IFERROR('Data Sheet'!K59/'Data Sheet'!K$61, "N/A")) | L30: ='Data Sheet'!K59/'Data Sheet'!K$61
B31: =IF(OR(ISBLANK('Data Sheet'!B$61), 'Data Sheet'!B$61<=0), "N/A", IFERROR('Data Sheet'!B60/'Data Sheet'!B$61, "N/A")) | C31: =IF(OR(ISBLANK('Data Sheet'!C$61), 'Data Sheet'!C$61<=0), "N/A", IFERROR('Data Sheet'!C60/'Data Sheet'!C$61, "N/A")) | D31: =IF(OR(ISBLANK('Data Sheet'!D$61), 'Data Sheet'!D$61<=0), "N/A", IFERROR('Data Sheet'!D60/'Data Sheet'!D$61, "N/A")) | E31: =IF(OR(ISBLANK('Data Sheet'!E$61), 'Data Sheet'!E$61<=0), "N/A", IFERROR('Data Sheet'!E60/'Data Sheet'!E$61, "N/A")) | F31: =IF(OR(ISBLANK('Data Sheet'!F$61), 'Data Sheet'!F$61<=0), "N/A", IFERROR('Data Sheet'!F60/'Data Sheet'!F$61, "N/A")) | G31: =IF(OR(ISBLANK('Data Sheet'!G$61), 'Data Sheet'!G$61<=0), "N/A", IFERROR('Data Sheet'!G60/'Data Sheet'!G$61, "N/A")) | H31: =IF(OR(ISBLANK('Data Sheet'!H$61), 'Data Sheet'!H$61<=0), "N/A", IFERROR('Data Sheet'!H60/'Data Sheet'!H$61, "N/A")) | I31: =IF(OR(ISBLANK('Data Sheet'!I$61), 'Data Sheet'!I$61<=0), "N/A", IFERROR('Data Sheet'!I60/'Data Sheet'!I$61, "N/A")) | ... K31: =IF(OR(ISBLANK('Data Sheet'!K$61), 'Data Sheet'!K$61<=0), "N/A", IFERROR('Data Sheet'!K60/'Data Sheet'!K$61, "N/A")) | L31: ='Data Sheet'!K60/'Data Sheet'!K$61
B33: =IF(OR(ISBLANK('Data Sheet'!B$66), 'Data Sheet'!B$66<=0), "N/A", IFERROR('Data Sheet'!B66/'Data Sheet'!B$66, "N/A")) | C33: =IF(OR(ISBLANK('Data Sheet'!C$66), 'Data Sheet'!C$66<=0), "N/A", IFERROR('Data Sheet'!C66/'Data Sheet'!C$66, "N/A")) | D33: =IF(OR(ISBLANK('Data Sheet'!D$66), 'Data Sheet'!D$66<=0), "N/A", IFERROR('Data Sheet'!D66/'Data Sheet'!D$66, "N/A")) | E33: =IF(OR(ISBLANK('Data Sheet'!E$66), 'Data Sheet'!E$66<=0), "N/A", IFERROR('Data Sheet'!E66/'Data Sheet'!E$66, "N/A")) | F33: =IF(OR(ISBLANK('Data Sheet'!F$66), 'Data Sheet'!F$66<=0), "N/A", IFERROR('Data Sheet'!F66/'Data Sheet'!F$66, "N/A")) | G33: =IF(OR(ISBLANK('Data Sheet'!G$66), 'Data Sheet'!G$66<=0), "N/A", IFERROR('Data Sheet'!G66/'Data Sheet'!G$66, "N/A")) | H33: =IF(OR(ISBLANK('Data Sheet'!H$66), 'Data Sheet'!H$66<=0), "N/A", IFERROR('Data Sheet'!H66/'Data Sheet'!H$66, "N/A")) | I33: =IF(OR(ISBLANK('Data Sheet'!I$66), 'Data Sheet'!I$66<=0), "N/A", IFERROR('Data Sheet'!I66/'Data Sheet'!I$66, "N/A")) | ... K33: =IF(OR(ISBLANK('Data Sheet'!K$66), 'Data Sheet'!K$66<=0), "N/A", IFERROR('Data Sheet'!K66/'Data Sheet'!K$66, "N/A")) | L33: ='Data Sheet'!K66/'Data Sheet'!K$66
B34: =IF(OR(ISBLANK('Data Sheet'!B$66), 'Data Sheet'!B$66<=0), "N/A", IFERROR('Data Sheet'!B62/'Data Sheet'!B$66, "N/A")) | C34: =IF(OR(ISBLANK('Data Sheet'!C$66), 'Data Sheet'!C$66<=0), "N/A", IFERROR('Data Sheet'!C62/'Data Sheet'!C$66, "N/A")) | D34: =IF(OR(ISBLANK('Data Sheet'!D$66), 'Data Sheet'!D$66<=0), "N/A", IFERROR('Data Sheet'!D62/'Data Sheet'!D$66, "N/A")) | E34: =IF(OR(ISBLANK('Data Sheet'!E$66), 'Data Sheet'!E$66<=0), "N/A", IFERROR('Data Sheet'!E62/'Data Sheet'!E$66, "N/A")) | F34: =IF(OR(ISBLANK('Data Sheet'!F$66), 'Data Sheet'!F$66<=0), "N/A", IFERROR('Data Sheet'!F62/'Data Sheet'!F$66, "N/A")) | G34: =IF(OR(ISBLANK('Data Sheet'!G$66), 'Data Sheet'!G$66<=0), "N/A", IFERROR('Data Sheet'!G62/'Data Sheet'!G$66, "N/A")) | H34: =IF(OR(ISBLANK('Data Sheet'!H$66), 'Data Sheet'!H$66<=0), "N/A", IFERROR('Data Sheet'!H62/'Data Sheet'!H$66, "N/A")) | I34: =IF(OR(ISBLANK('Data Sheet'!I$66), 'Data Sheet'!I$66<=0), "N/A", IFERROR('Data Sheet'!I62/'Data Sheet'!I$66, "N/A")) | ... K34: =IF(OR(ISBLANK('Data Sheet'!K$66), 'Data Sheet'!K$66<=0), "N/A", IFERROR('Data Sheet'!K62/'Data Sheet'!K$66, "N/A")) | L34: ='Data Sheet'!K62/'Data Sheet'!K$66
B35: ='Data Sheet'!A63 | C35: ='Data Sheet'!B63/'Data Sheet'!B$66 | D35: ='Data Sheet'!C63/'Data Sheet'!C$66 | E35: ='Data Sheet'!D63/'Data Sheet'!D$66 | F35: ='Data Sheet'!E63/'Data Sheet'!E$66 | G35: ='Data Sheet'!F63/'Data Sheet'!F$66 | H35: ='Data Sheet'!G63/'Data Sheet'!G$66 | I35: ='Data Sheet'!H63/'Data Sheet'!H$66 | J35: ='Data Sheet'!I63/'Data Sheet'!I$66 | ... L35: ='Data Sheet'!K63/'Data Sheet'!K$66
B36: ='Data Sheet'!A64 | C36: ='Data Sheet'!B64/'Data Sheet'!B$66 | D36: ='Data Sheet'!C64/'Data Sheet'!C$66 | E36: ='Data Sheet'!D64/'Data Sheet'!D$66 | F36: ='Data Sheet'!E64/'Data Sheet'!E$66 | G36: ='Data Sheet'!F64/'Data Sheet'!F$66 | H36: ='Data Sheet'!G64/'Data Sheet'!G$66 | I36: ='Data Sheet'!H64/'Data Sheet'!H$66 | J36: ='Data Sheet'!I64/'Data Sheet'!I$66 | ... L36: ='Data Sheet'!K64/'Data Sheet'!K$66
B37: ='Data Sheet'!A65 | C37: ='Data Sheet'!B74/'Data Sheet'!B66 | D37: ='Data Sheet'!C74/'Data Sheet'!C66 | E37: ='Data Sheet'!D74/'Data Sheet'!D66 | F37: ='Data Sheet'!E74/'Data Sheet'!E66 | G37: ='Data Sheet'!F74/'Data Sheet'!F66 | H37: ='Data Sheet'!G74/'Data Sheet'!G66 | I37: ='Data Sheet'!H74/'Data Sheet'!H66 | J37: ='Data Sheet'!I74/'Data Sheet'!I66 | ... L37: ='Data Sheet'!K74/'Data Sheet'!K66
B38: ='Data Sheet'!A67 | C38: ='Data Sheet'!B67/'Data Sheet'!B$66 | D38: ='Data Sheet'!C67/'Data Sheet'!C$66 | E38: ='Data Sheet'!D67/'Data Sheet'!D$66 | F38: ='Data Sheet'!E67/'Data Sheet'!E$66 | G38: ='Data Sheet'!F67/'Data Sheet'!F$66 | H38: ='Data Sheet'!G67/'Data Sheet'!G$66 | I38: ='Data Sheet'!H67/'Data Sheet'!H$66 | J38: ='Data Sheet'!I67/'Data Sheet'!I$66 | ... L38: ='Data Sheet'!K67/'Data Sheet'!K$66
B39: ='Data Sheet'!A68 | C39: ='Data Sheet'!B68/'Data Sheet'!B$66 | D39: ='Data Sheet'!C68/'Data Sheet'!C$66 | E39: ='Data Sheet'!D68/'Data Sheet'!D$66 | F39: ='Data Sheet'!E68/'Data Sheet'!E$66 | G39: ='Data Sheet'!F68/'Data Sheet'!F$66 | H39: ='Data Sheet'!G68/'Data Sheet'!G$66 | I39: ='Data Sheet'!H68/'Data Sheet'!H$66 | J39: ='Data Sheet'!I68/'Data Sheet'!I$66 | ... L39: ='Data Sheet'!K68/'Data Sheet'!K$66
B40: ='Data Sheet'!A69 | C40: ='Data Sheet'!B69/'Data Sheet'!B$66 | D40: ='Data Sheet'!C69/'Data Sheet'!C$66 | E40: ='Data Sheet'!D69/'Data Sheet'!D$66 | F40: ='Data Sheet'!E69/'Data Sheet'!E$66 | G40: ='Data Sheet'!F69/'Data Sheet'!F$66 | H40: ='Data Sheet'!G69/'Data Sheet'!G$66 | I40: ='Data Sheet'!H69/'Data Sheet'!H$66 | J40: ='Data Sheet'!I69/'Data Sheet'!I$66 | ... L40: ='Data Sheet'!K69/'Data Sheet'!K$66

Sheet Data Sheet
A1: COMPANY NAME | B1: Maruti Suzuki India Ltd | E1: =IF(B2<>B3, "A NEW VERSION OF THE WORKSHEET IS AVAILABLE", "")
A2: LATEST VERSION | B2: 2.1 | E2: PLEASE DO NOT MAKE ANY CHANGES TO THIS SHEET
A3: CURRENT VERSION | B3: 2.1
A5: META
A6: Number of shares | B6: =IF(B9>0, B9/B8, 0)
A7: Face Value | B7: 5
A8: Current Price | B8: 12103
A9: Market Capitalization | B9: 380521
A15: PROFIT & LOSS
A16: Report Date | B16: 43160 | C16: 43525 | D16: 43891 | E16: 44256 | F16: 44621 | G16: 44986 | H16: 45352 | I16: 45717 | J16: 46082 | K16: TTM
A17: Sales | B17: 79809 | C17: 86068 | D17: 75660 | E17: 70372 | F17: 88330 | G17: 118410 | H17: 141858 | I17: 152913 | J17: 183316 | K17: 197181
A18: Raw Material Cost | B18: 55068.21 | C18: 59386.92 | D18: 52962 | E18: 50667.84 | F18: 66247.5 | G18: 85255.2 | H18: 99300.6 | I18: 107039.1 | J18: 131987.52 | K18: 0
A19: Change in Inventory | B19: 0 | C19: 0 | D19: 0 | E19: 0 | F19: 0 | G19: 0 | H19: 0 | I19: 0 | J19: 0 | K19: 0
A20: Power and Fuel | B20: 0 | C20: 0 | D20: 0 | E20: 0 | F20: 0 | G20: 0 | H20: 0 | I20: 0 | J20: 0 | K20: 0
A21: Other Mfr. Exp | B21: 798.09 | C21: 1721.36 | D21: 756.6 | E21: 1407.44 | F21: 1766.6 | G21: 2368.2 | H21: 2837.16 | I21: 3058.26 | J21: 3666.32 | K21: 0
A22: Employee Cost | B22: 3192.36 | C22: 3442.72 | D22: 3783 | E22: 3518.6 | F22: 4416.5 | G22: 4736.4 | H22: 5674.32 | I22: 7645.65 | J22: 9165.8 | K22: 0
A23: Selling and admin | B23: 0 | C23: 0 | D23: 0 | E23: 0 | F23: 0 | G23: 0 | H23: 0 | I23: 0 | J23: 0 | K23: 0
A24: Other Expenses | B24: 8778.99 | C24: 11188.84 | D24: 10592.4 | E24: 9852.08 | F24: 10599.6 | G24: 13025.1 | H24: 14185.8 | I24: 15291.3 | J24: 16498.44 | K24: 0
A25: Other Income | B25: 2155 | C25: 2664 | D25: 3410 | E25: 3046 | F25: 1861 | G25: 2415 | H25: 4248 | I25: 5199 | J25: 4569 | K25: 4707
A26: Depreciation | B26: 2760 | C26: 3021 | D26: 3528 | E26: 3034 | F26: 2789 | G26: 4846 | H26: 5256 | I26: 5608 | J26: 6742 | K26: 6966
A27: Interest | B27: 346 | C27: 76 | D27: 134 | E27: 102 | F27: 127 | G27: 252 | H27: 194 | I27: 194 | J27: 239 | K27: 255
A28: Profit before tax | B28: 11167 | C28: 10624 | D28: 7103 | E28: 5321 | F28: 4697 | G28: 10438 | H28: 17424 | I28: 19620 | J28: 19118 | K28: 18616
... A31: Dividend Amount | B31: 2443.11 | C31: 2448.32 | D31: 1816.96 | E31: 1360.59 | F31: 1823.6 | G31: 2809.76 | H31: 3911.52 | I31: 4205 | J31: 4404 | K31: 0
A32: EBITDA | B32: =SUM(B26:B28) | C32: =SUM(C26:C28) | D32: =SUM(D26:D28) | E32: =SUM(E26:E28) | F32: =SUM(F26:F28) | G32: =SUM(G26:G28) | H32: =SUM(H26:H28) | I32: =SUM(I26:I28) | ... K32: =SUM(K26:K28)
B33: =B30+B29+B27+B26 | C33: =C30+C29+C27+C26 | D33: =D30+D29+D27+D26 | E33: =E30+E29+E27+E26 | F33: =F30+F29+F27+F26 | G33: =G30+G29+G27+G26 | H33: =H30+H29+H27+H26 | I33: =I30+I29+I27+I26 | ... K33: =K30+K29+K27+K26
A40: Quarters
A41: Report Date | B41: 45352 | C41: 45444 | D41: 45536 | E41: 45627 | F41: 45717 | G41: 45809 | H41: 45901 | I41: 45992 | J41: 46082 | K41: 46174
A42: Sales | B42: 38471 | C42: 35779 | D42: 37449 | E42: 38764 | F42: 40920 | G42: 38605 | H42: 42344 | I42: 49904 | J42: 52462 | K42: 52470
A43: Expenses | B43: 33250 | C43: 30673 | D43: 32450 | E43: 33688 | F43: 36076 | G43: 33983 | H43: 37258 | I43: 44331 | J43: 46304 | K43: 48156
A44: Other Income | B44: 1261 | C44: 1118 | D44: 1570 | E44: 1125 | F44: 1583 | G44: 1924 | H44: 1014 | I44: 1140 | J44: 581 | K44: 1972
A45: Depreciation | B45: 1298 | C45: 1332 | D45: 1386 | E45: 1429 | F45: 1462 | G45: 1556 | H45: 1703 | I45: 1735 | J45: 1748 | K45: 1780
A46: Interest | B46: 76 | C46: 57 | D46: 43 | E46: 46 | F46: 48 | G46: 47 | H46: 57 | I46: 62 | J46: 73 | K46: 64
A47: Profit before tax | B47: 5108 | C47: 4836 | D47: 5141 | E47: 4726 | F47: 4918 | G47: 4944 | H47: 4339 | I47: 4917 | J47: 4918 | K47: 4441
A48: Tax | B48: 5108 | C48: 4836 | D48: 5141 | E48: 4726 | F48: 4918 | G48: 4944 | H48: 4339 | I48: 4917 | J48: 4918 | K48: 4441
A49: Net profit | B49: 3952 | C49: 3760 | D49: 3102 | E49: 3727 | F49: 3911 | G49: 3792 | H49: 3349 | I49: 3879 | J49: 3659 | K49: 3447
A50: Operating Profit | B50: 5221 | C50: 5107 | D50: 4999 | E50: 5076 | F50: 4844 | G50: 4623 | H50: 5086 | I50: 5573 | J50: 6158 | K50: 4313
A55: BALANCE SHEET
A56: Report Date | B56: 42795 | C56: 43160 | D56: 43525 | E56: 43891 | F56: 44256 | G56: 44621 | H56: 44986 | I56: 45352 | J56: 45717 | K56: 46082
A57: Equity Share Capital | B57: 151 | C57: 151 | D57: 151 | E57: 151 | F57: 151 | G57: 151 | H57: 157 | I57: 157 | J57: 157 | K57: 157
A58: Reserves | B58: 36924 | C58: 42408 | D58: 46941 | E58: 49262 | F58: 52350 | G58: 55182 | H58: 74443 | I58: 85479 | J58: 96083 | K58: 106999
...

Sheet Cash Flow Statement
B2: Cash Flow Statement - Maruti Suzuki India Ltd
B4: Particulars | C4: 42064 | D4: 42430 | E4: 42795 | F4: 43160 | G4: 43525 | H4: 43891 | I4: 44256 | J4: 44621 | K4: 44986 | L4: 45352 | M4: 45717 | N4: 46082
B6: Cash from Operating Activity - | C6: 6449 | D6: 8482 | E6: 10282 | F6: 11788 | G6: 6601 | H6: 3496 | I6: 8856 | J6: 1840 | K6: 10815 | L6: 16801 | M6: 16180 | N6: 19100
B7: Profit from operations | C7: 6779 | D7: 8935 | E7: 10413 | F7: 12036 | G7: 11060 | H7: 7503 | I7: 5531 | J7: 5832 | K7: 13176 | L7: 18676 | M7: 20322 | N7: 21802
B8: Receivables | C8: 345 | D8: -204 | E8: 122 | F8: -262 | G8: -851 | H8: 340 | I8: 696 | J8: -764 | K8: -1270 | L8: -1316 | M8: -1969 | N8: 1236
B9: Inventory | C9: -982 | D9: -450 | E9: -131 | F9: 104 | G9: -162 | H9: 109 | I9: 165 | J9: -483 | K9: -1050 | L9: 125 | M9: -1595 | N9: -4407
B10: Payables | C10: 712 | D10: 1789 | E10: 979 | F10: 2128 | G10: -858 | H10: -2155 | I10: 2680 | J10: -396 | K10: 2491 | L10: 3321 | M10: 2606 | N10: 5194
B11: Working capital changes | C11: 745 | D11: 1460 | E11: 2192 | F11: 2808 | G11: -1315 | H11: -2570 | I11: 4336 | J11: -2813 | K11: -97 | L11: 1722 | M11: -335 | N11: 1635
B12: Direct taxes | C12: -1075 | D12: -1912 | E12: -2323 | F12: -3056 | G12: -3144 | H12: -1438 | I12: -1011 | J12: -1178 | K12: -2265 | L12: -3597 | M12: -3807 | N12: -4337
B13: Cash from Investing Activity - | C13: -4491 | D13: -7230 | E13: -9173 | F13: -8302 | G13: -3540 | H13: -557 | I13: -7291 | J13: -239 | K13: -8820 | L13: -11865 | M13: -14500 | N13: -14734
B14: Fixed assets purchased | C14: -3058 | D14: -2469 | E14: -3391 | F14: -3912 | G14: -4872 | H14: -3437 | I14: -2370 | J14: -3459 | K14: -8065 | L14: -9200 | M14: -10621 | N14: -10398
B15: Fixed assets sold | C15: 16 | D15: 12 | E15: 16 | F15: 26 | G15: 170 | H15: 37 | I15: 42 | J15: 136 | K15: 109 | L15: 45 | M15: 42 | N15: 52
B16: Investments purchased | C16: -17354 | D16: -12044 | E16: -17716 | F16: -47069 | G16: -52957 | H16: -44205 | I16: -44869 | J16: -60525 | K16: -66597 | L16: -65736 | M16: -73882 | N16: -108034
... B32: Net Cash Flow | C32: -45 | D32: 16 | E32: -20 | F32: 50 | G32: 113 | H32: -165 | I32: 20 | J32: -6 | K32: 780 | L32: 874 | M32: -2475 | N32: -118

Sheet Historical FS
B2: ="Historical Financial Statement - "&'Data Sheet'!$B$1
B3: Particulars | C3: ='Data Sheet'!B56 | D3: ='Data Sheet'!C56 | E3: ='Data Sheet'!D56 | F3: ='Data Sheet'!E56 | G3: ='Data Sheet'!F56 | H3: ='Data Sheet'!G56 | I3: ='Data Sheet'!H56 | J3: ='Data Sheet'!I56 | ... L3: ='Data Sheet'!K56 | M3: LTM
A5: # | B5: Income Statement
B7: Sales | C7: ='Data Sheet'!B17 | D7: ='Data Sheet'!C17 | E7: ='Data Sheet'!D17 | F7: ='Data Sheet'!E17 | G7: ='Data Sheet'!F17 | H7: ='Data Sheet'!G17 | I7: ='Data Sheet'!H17 | J7: ='Data Sheet'!I17 | ... L7: ='Data Sheet'!K17
B8: Sales Growth | C8: - | D8: =D7/C7-1 | E8: =E7/D7-1 | F8: =F7/E7-1 | G8: =G7/F7-1 | H8: =H7/G7-1 | I8: =I7/H7-1 | J8: =J7/I7-1 | K8: =K7/J7-1 | L8: =L7/K7-1
B10: Cost of Goods Sold | C10: =SUM('Data Sheet'!B18,'Data Sheet'!B20:B22)-'Data Sheet'!B19 | D10: =SUM('Data Sheet'!C18,'Data Sheet'!C20:C22)-'Data Sheet'!C19 | E10: =SUM('Data Sheet'!D18,'Data Sheet'!D20:D22)-'Data Sheet'!D19 | F10: =SUM('Data Sheet'!E18,'Data Sheet'!E20:E22)-'Data Sheet'!E19 | G10: =SUM('Data Sheet'!F18,'Data Sheet'!F20:F22)-'Data Sheet'!F19 | H10: =SUM('Data Sheet'!G18,'Data Sheet'!G20:G22)-'Data Sheet'!G19 | I10: =SUM('Data Sheet'!H18,'Data Sheet'!H20:H22)-'Data Sheet'!H19 | J10: =SUM('Data Sheet'!I18,'Data Sheet'!I20:I22)-'Data Sheet'!I19 | ... L10: =SUM('Data Sheet'!K18,'Data Sheet'!K20:K22)-'Data Sheet'!K19
B11: COGS % Sales | C11: =C10/C7 | D11: =D10/D7 | E11: =E10/E7 | F11: =F10/F7 | G11: =G10/G7 | H11: =H10/H7 | I11: =I10/I7 | J11: =J10/J7 | ... L11: =L10/L7
B13: Gross Profit | C13: =C7-C10 | D13: =D7-D10 | E13: =E7-E10 | F13: =F7-F10 | G13: =G7-G10 | H13: =H7-H10 | I13: =I7-I10 | J13: =J7-J10 | ... L13: =L7-L10
B14: Gross Profit % Sales | C14: =C13/C7 | D14: =D13/D7 | E14: =E13/E7 | F14: =F13/F7 | G14: =G13/G7 | H14: =H13/H7 | I14: =I13/I7 | J14: =J13/J7 | ... L14: =L13/L7
B16: Selling % General Expenses | C16: ='Data Sheet'!B23 | D16: ='Data Sheet'!C23 | E16: ='Data Sheet'!D23 | F16: ='Data Sheet'!E23 | G16: ='Data Sheet'!F23 | H16: ='Data Sheet'!G23 | I16: ='Data Sheet'!H23 | J16: ='Data Sheet'!I23 | ... L16: ='Data Sheet'!K23
B17: S&G % Sales | C17: =C16/C7 | D17: =D16/D7 | E17: =E16/E7 | F17: =F16/F7 | G17: =G16/G7 | H17: =H16/H7 | I17: =I16/I7 | J17: =J16/J7 | ... L17: =L16/L7
B19: EBITDA | C19: =C13-C16 | D19: =D13-D16 | E19: =E13-E16 | F19: =F13-F16 | G19: =G13-G16 | H19: =H13-H16 | I19: =I13-I16 | J19: =J13-J16 | ... L19: =L13-L16
B20: EBITDA % Sales | C20: =C19/C7 | D20: =D19/D7 | E20: =E19/E7 | F20: =F19/F7 | G20: =G19/G7 | H20: =H19/H7 | I20: =I19/I7 | J20: =J19/J7 | ... L20: =L19/L7
B22: Depreciation | C22: ='Data Sheet'!B26 | D22: ='Data Sheet'!C26 | E22: ='Data Sheet'!D26 | F22: ='Data Sheet'!E26 | G22: ='Data Sheet'!F26 | H22: ='Data Sheet'!G26 | I22: ='Data Sheet'!H26 | J22: ='Data Sheet'!I26 | ... L22: ='Data Sheet'!K26
B23: Depreciation % Sales | C23: =C22/C7 | D23: =D22/D7 | E23: =E22/E7 | F23: =F22/F7 | G23: =G22/G7 | H23: =H22/H7 | I23: =I22/I7 | J23: =J22/J7 | ... L23: =L22/L7
B25: EBIT | C25: =C19-C22 | D25: =D19-D22 | E25: =E19-E22 | F25: =F19-F22 | G25: =G19-G22 | H25: =H19-H22 | I25: =I19-I22 | J25: =J19-J22 | ... L25: =L19-L22
B26: EBIT % Sales | C26: =C25/C7 | D26: =D25/D7 | E26: =E25/E7 | F26: =F25/F7 | G26: =G25/G7 | H26: =H25/H7 | I26: =I25/I7 | J26: =J25/J7 | ... L26: =L25/L7
B28: Interest | C28: ='Data Sheet'!B27 | D28: ='Data Sheet'!C27 | E28: ='Data Sheet'!D27 | F28: ='Data Sheet'!E27 | G28: ='Data Sheet'!F27 | H28: ='Data Sheet'!G27 | I28: ='Data Sheet'!H27 | J28: ='Data Sheet'!I27 | ... L28: ='Data Sheet'!K27
B29: Interest % Sales | C29: =C28/C7 | D29: =D28/D7 | E29: =E28/E7 | F29: =F28/F7 | G29: =G28/G7 | H29: =H28/H7 | I29: =I28/I7 | J29: =J28/J7 | ... L29: =L28/L7
B31: Earning Before Tax | C31: =C25-C28 | D31: =D25-D28 | E31: =E25-E28 | F31: =F25-F28 | G31: =G25-G28 | H31: =H25-H28 | I31: =I25-I28 | J31: =J25-J28 | ... L31: =L25-L28
B32: EBT % Sales | C32: =C31/C7 | D32: =D31/D7 | E32: =E31/E7 | F32: =F31/F7 | G32: =G31/G7 | H32: =H31/H7 | I32: =I31/I7 | J32: =J31/J7 | ... L32: =L31/L7
B34: Tax Rate | C34: ='Data Sheet'!B29 | D34: ='Data Sheet'!C29 | E34: ='Data Sheet'!D29 | F34: ='Data Sheet'!E29 | G34: ='Data Sheet'!F29 | H34: ='Data Sheet'!G29 | I34: ='Data Sheet'!H29 | J34: ='Data Sheet'!I29 | ... L34: ='Data Sheet'!K29
B35: Effective Tax Rate | C35: =C34/C31 | D35: =D34/D31 | E35: =E34/E31 | F35: =F34/F31 | G35: =G34/G31 | H35: =H34/H31 | I35: =I34/I31 | J35: =J34/J31 | ... L35: =L34/L31
B37: Net Profit | C37: =C31-C34 | D37: =D31-D34 | E37: =E31-E34 | F37: =F31-F34 | G37: =G31-G34 | H37: =H31-H34 | I37: =I31-I34 | J37: =J31-J34 | ... L37: =L31-L34
B38: Net Profit % Sales | C38: =C37/C7 | D38: =D37/D7 | E38: =E37/E7 | F38: =F37/F7 | G38: =G37/G7 | H38: =H37/H7 | I38: =I37/I7 | J38: =J37/J7 | ... L38: =L37/L7
B40: No. of Equity Shares | C40: ='Data Sheet'!B93 | D40: ='Data Sheet'!C93 | E40: ='Data Sheet'!D93 | F40: ='Data Sheet'!E93 | G40: ='Data Sheet'!F93 | H40: ='Data Sheet'!G93 | I40: ='Data Sheet'!H93 | J40: ='Data Sheet'!I93 | ... L40: ='Data Sheet'!K93
B42: Earning per Share | C42: =C37/C40 | D42: =D37/D40 | E42: =E37/E40 | F42: =F37/F40 | G42: =G37/G40 | H42: =H37/H40 | I42: =I37/I40 | J42: =J37/J40 | ... L42: =L37/L40
B43: EPS Growth | C43: - | D43: =D42/C42-1 | E43: =E42/D42-1 | F43: =F42/E42-1 | G43: =G42/F42-1 | H43: =H42/G42-1 | I43: =I42/H42-1 | J43: =J42/I42-1 | K43: =K42/J42-1 | L43: =L42/K42-1
B45: Dividend per Share | C45: ='Data Sheet'!B31/'Historical FS'!C40 | D45: ='Data Sheet'!C31/'Historical FS'!D40 | E45: ='Data Sheet'!D31/'Historical FS'!E40 | F45: ='Data Sheet'!E31/'Historical FS'!F40 | G45: ='Data Sheet'!F31/'Historical FS'!G40 | H45: ='Data Sheet'!G31/'Historical FS'!H40 | I45: ='Data Sheet'!H31/'Historical FS'!I40 | J45: ='Data Sheet'!I31/'Historical FS'!J40 | ... L45: ='Data Sheet'!K31/'Historical FS'!L40
B46: Dividend Payout Ratio | C46: =C45/C42 | D46: =D45/D42 | E46: =E45/E42 | F46: =F45/F42 | G46: =G45/G42 | H46: =H45/H42 | I46: =I45/I42 | J46: =J45/J42 | ... L46: =L45/L42
B48: Retained Earnings | C48: =(1-C46) | D48: =(1-D46) | E48: =(1-E46) | F48: =(1-F46) | G48: =(1-G46) | H48: =(1-H46) | I48: =(1-I46) | J48: =(1-J46) | ... L48: =(1-L46)
B50: Balance Sheet
B51: ='Data Sheet'!A57 | C51: ='Data Sheet'!B57 | D51: ='Data Sheet'!C57 | E51: ='Data Sheet'!D57 | F51: ='Data Sheet'!E57 | G51: ='Data Sheet'!F57 | H51: ='Data Sheet'!G57 | I51: ='Data Sheet'!H57 | ... L51: ='Data Sheet'!K57
