Workbook
Name UPDATE: '[1]Data Sheet'!$E$1
Name UPDATE: 'Data Sheet'!$E$1

Sheet AI Valuation Summary
A1: BRITANNIA INDUSTRIES LTD (BRITANNIA) - Institutional Valuation
A4: Current Price | B4: Intrinsic Value | C4: Margin of Safety | D4: Verdict | E4: WACC | F4: Altman Z-Score | G4: DuPont ROE
A5: =DCF!D45 -> 4929 | B5: =DCF!D43 -> 1159.8694 | C5: =(B5-A5)/A5 -> -0.76468463 | D5: =IF(C5>0.15,"UNDERVALUED / BUY",IF(C5<-0.15,"OVERVALUED / SELL","FAIRLY VALUED / HOLD")) -> OVERVALUED / SELL | E5: =DCF!D20 -> 0.10941053 | F5: ='Altman''s Z Score'!I89 -> 22.548975 | G5: ='Dupont Analysis'!I78 -> 0.53625026
B7: KEY VALUATION PARAMETERS & LIVE MODEL INPUTS
B8: Discount Rate (WACC) | C8: =WACC!K46 -> 0.10941053 | D8: 0
B9: Cost of Equity (Ke) | C9: =WACC!K29 -> 0.10941053 | D9: 0
B10: Risk-Free Rate (Rf) | C10: =WACC!K26 -> 0.07 | D10: 0
B11: Equity Risk Premium (ERP) | C11: =WACC!K27 -> 0.065 | D11: 0
B12: Levered Beta | C12: =WACC!K28 -> 0.60631585 | D12: 0
B13: Terminal Growth Rate | C13: =DCF!D19 -> 0.04 | D13: 0
B14: Post-Tax Cost of Debt (Kd) | C14: =WACC!K43 -> 0.060375 | D14: 0
B15: Cash & Liquid Investments | C15: ='Data Sheet'!K69 -> 352 | D15: #,##0.00
B16: Total Debt & Borrowings | C16: ='Data Sheet'!K59 -> 1380 | D16: #,##0.00
B17: Shares Outstanding | C17: ='Data Sheet'!K70/10000000 -> 24 | D17: #,##0.00
B18: Sector Median EV/Revenue | C18: =Comp_Valuation!O25 -> 6.4757407 | D18: 0.00"x"
B19: Sector Median EV/EBITDA | C19: =Comp_Valuation!P25 -> 34.440046 | D19: 0.00"x"
A20: 5-Year Discounted Cash Flow (DCF) Schedule (Amounts in ₹ Cr) | B20: Sector Median P/E | C20: =Comp_Valuation!Q25 -> 19.999824 | D20: 0.00"x"
A21: Year | B21: EBIT | C21: NOPAT | D21: Reinvest Rate | E21: FCFF | F21: Discount Factor | G21: PV of FCFF
A22: Year 1 | B22: =DCF!I8 -> 3578.904 | C22: =DCF!I10 -> 2684.178 | D22: =DCF!I11 -> 0.031805628 | E22: =DCF!I12 -> 2598.806 | F22: =DCF!I14 -> 0.94941012 | G22: =DCF!I16 -> 2467.3328
A23: Year 2 | B23: =DCF!J8 -> 3765.007 | C23: =DCF!J10 -> 2823.7553 | D23: =DCF!J11 -> 0.1152531 | E23: =DCF!J12 -> 2498.3087 | F23: =DCF!J14 -> 0.8557789 | G23: =DCF!J16 -> 2137.9999
A24: Year 3 | B24: =DCF!K8 -> 3960.7874 | C24: =DCF!K10 -> 2970.5905 | D24: =DCF!K11 -> 0.19870057 | E24: =DCF!K12 -> 2380.3325 | F24: =DCF!K14 -> 0.77138163 | G24: =DCF!K16 -> 1836.1447
A25: Year 4 | B25: =DCF!L8 -> 4166.7483 | C25: =DCF!L10 -> 3125.0612 | D25: =DCF!L11 -> 0.28214805 | E25: =DCF!L12 -> 2243.3313 | F25: =DCF!L14 -> 0.69530765 | G25: =DCF!L16 -> 1559.8054
A26: Year 5 | B26: =DCF!M8 -> 4383.4192 | C26: =DCF!M10 -> 3287.5644 | D26: =DCF!M11 -> 0.36559552 | E26: =DCF!M12 -> 2085.6456 | F26: =DCF!M14 -> 0.62673612 | G26: =DCF!M16 -> 1307.1494
B28: Enterprise to Equity Value Bridge
B29: PV of 5-Year FCFFs | C29: =DCF!D33 -> 9308.4322 | D29: ₹ Cr
B30: Terminal Value | C30: =DCF!D29 -> 31249.89 | D30: ₹ Cr
B31: PV of Terminal Value | C31: =DCF!D34 -> 19585.434 | D31: ₹ Cr
B32: Enterprise Value (Operating Assets) | C32: =DCF!D35 -> 28893.867 | D32: ₹ Cr
B33: Add: Estimated Cash & Liquid Assets | C33: =DCF!D37 -> 352 | D33: ₹ Cr
B34: Less: Total Debt & Borrowings | C34: =DCF!D38 -> 1380 | D34: ₹ Cr
B35: Less: Minority Interest | C35: =DCF!D39 -> 29 | D35: ₹ Cr
B36: Net Equity Value | C36: =DCF!D40 -> 27836.867 | D36: ₹ Cr
B37: Shares Outstanding | C37: =DCF!D41 -> 24 | D37: Cr shares
B38: Intrinsic Value per Share | C38: =DCF!D43 -> 1159.8694 | D38: ₹
B39: Current Market Price | C39: =DCF!D45 -> 4929 | D39: ₹
B40: Margin of Safety / Discount | C40: =(C38-C39)/C39 -> -0.76468463 | D40: %

Sheet Profit & Loss
A1: ='Data Sheet'!B1 -> BRITANNIA INDUSTRIES LTD | H1: =UPDATE | M1: SCREENER.IN
A3: Narration | B3: ='Data Sheet'!B16 -> 42795 | C3: ='Data Sheet'!C16 -> 43160 | D3: ='Data Sheet'!D16 -> 43525 | E3: ='Data Sheet'!E16 -> 43891 | F3: ='Data Sheet'!F16 -> 44256 | G3: ='Data Sheet'!G16 -> 44621 | H3: ='Data Sheet'!H16 -> 44986 | I3: ='Data Sheet'!I16 -> 45352 | ... K3: ='Data Sheet'!K16 -> 46082 | L3: Trailing | M3: Best Case | N3: Worst Case
A4: Sales | B4: ='Data Sheet'!B17 -> 9054 | C4: ='Data Sheet'!C17 -> 9914 | D4: ='Data Sheet'!D17 -> 11055 | E4: ='Data Sheet'!E17 -> 11600 | F4: ='Data Sheet'!F17 -> 13136 | G4: ='Data Sheet'!G17 -> 14136 | H4: ='Data Sheet'!H17 -> 16301 | I4: ='Data Sheet'!I17 -> 16769 | ... K4: ='Data Sheet'!K17 -> 19152 | L4: =SUM(Quarters!H4:K4) -> 19530 | M4: =$K4+M23*K4 -> 20442.462 | N4: =$K4+N23*L4 -> 20229.985
A5: Expenses | B5: =SUM('Data Sheet'!B18,'Data Sheet'!B20:B24, -1*'Data Sheet'!B19) -> 7869.96 | C5: =SUM('Data Sheet'!C18,'Data Sheet'!C20:C24, -1*'Data Sheet'!C19) -> 8375.22 | D5: =SUM('Data Sheet'!D18,'Data Sheet'!D20:D24, -1*'Data Sheet'!D19) -> 9435.75 | E5: =SUM('Data Sheet'!E18,'Data Sheet'!E20:E24, -1*'Data Sheet'!E19) -> 9606 | F5: =SUM('Data Sheet'!F18,'Data Sheet'!F20:F24, -1*'Data Sheet'!F19) -> 10589.92 | G5: =SUM('Data Sheet'!G18,'Data Sheet'!G20:G24, -1*'Data Sheet'!G19) -> 12162.28 | H5: =SUM('Data Sheet'!H18,'Data Sheet'!H20:H24, -1*'Data Sheet'!H19) -> 13649.24 | I5: =SUM('Data Sheet'!I18,'Data Sheet'!I20:I24, -1*'Data Sheet'!I19) -> 13508.56 | ... K5: =SUM('Data Sheet'!K18,'Data Sheet'!K20:K24, -1*'Data Sheet'!K19) -> 15773.48 | L5: =SUM(Quarters!H5:K5) -> 15928 | M5: =M4-M6 -> 16674.267 | N5: =N4-N6 -> 16850.752
A6: Operating Profit | B6: =B4-B5 -> 1184.04 | C6: =C4-C5 -> 1538.78 | D6: =D4-D5 -> 1619.25 | E6: =E4-E5 -> 1994 | F6: =F4-F5 -> 2546.08 | G6: =G4-G5 -> 1973.72 | H6: =H4-H5 -> 2651.76 | I6: =I4-I5 -> 3260.44 | ... K6: =K4-K5 -> 3378.52 | L6: =SUM(Quarters!H6:K6) -> 3600 | M6: =M4*M24 -> 3768.1958 | N6: =N4*N24 -> 3379.2339
A7: Other Income | B7: ='Data Sheet'!B25 -> 151 | C7: ='Data Sheet'!C25 -> 166 | D7: ='Data Sheet'!D25 -> 206 | E7: ='Data Sheet'!E25 -> 263 | F7: ='Data Sheet'!F25 -> 313 | G7: ='Data Sheet'!G25 -> 222 | H7: ='Data Sheet'!H25 -> 597 | I7: ='Data Sheet'!I25 -> 211 | ... K7: ='Data Sheet'!K25 -> 224 | L7: =SUM(Quarters!H7:K7) -> 227 | M7: 0 | N7: 0
A8: Depreciation | B8: ='Data Sheet'!B26 -> 119 | C8: ='Data Sheet'!C26 -> 142 | D8: ='Data Sheet'!D26 -> 162 | E8: ='Data Sheet'!E26 -> 185 | F8: ='Data Sheet'!F26 -> 198 | G8: ='Data Sheet'!G26 -> 201 | H8: ='Data Sheet'!H26 -> 226 | I8: ='Data Sheet'!I26 -> 300 | ... K8: ='Data Sheet'!K26 -> 337 | L8: =SUM(Quarters!H8:K8) -> 335 | M8: =+$L8 -> 335 | N8: =+$L8 -> 335
A9: Interest | B9: ='Data Sheet'!B27 -> 5 | C9: ='Data Sheet'!C27 -> 8 | D9: ='Data Sheet'!D27 -> 9 | E9: ='Data Sheet'!E27 -> 77 | F9: ='Data Sheet'!F27 -> 111 | G9: ='Data Sheet'!G27 -> 144 | H9: ='Data Sheet'!H27 -> 169 | I9: ='Data Sheet'!I27 -> 164 | ... K9: ='Data Sheet'!K27 -> 113 | L9: =SUM(Quarters!H9:K9) -> 110 | M9: =+$L9 -> 110 | N9: =+$L9 -> 110
A10: Profit before tax | B10: ='Data Sheet'!B28 -> 1304 | C10: ='Data Sheet'!C28 -> 1518 | D10: ='Data Sheet'!D28 -> 1768 | E10: ='Data Sheet'!E28 -> 1844 | F10: ='Data Sheet'!F28 -> 2514 | G10: ='Data Sheet'!G28 -> 2078 | H10: ='Data Sheet'!H28 -> 3033 | I10: ='Data Sheet'!I28 -> 2913 | ... K10: ='Data Sheet'!K28 -> 3289 | L10: =SUM(Quarters!H10:K10) -> 3385 | M10: =M6+M7-SUM(M8:M9) -> 3323.1958 | N10: =N6+N7-SUM(N8:N9) -> 2934.2339
A11: Tax | B11: ='Data Sheet'!B29 -> 419 | C11: ='Data Sheet'!C29 -> 514 | D11: ='Data Sheet'!D29 -> 613 | E11: ='Data Sheet'!E29 -> 450 | F11: ='Data Sheet'!F29 -> 663 | G11: ='Data Sheet'!G29 -> 562 | H11: ='Data Sheet'!H29 -> 717 | I11: ='Data Sheet'!I29 -> 779 | ... K11: ='Data Sheet'!K29 -> 752 | L11: =SUM(Quarters!H11:K11) -> 775 | M11: =IF($L10>0,$L11/$L10,0) -> 0.22895126 | N11: =IF($L10>0,$L11/$L10,0) -> 0.22895126
A12: Net profit | B12: ='Data Sheet'!B30 -> 885 | C12: ='Data Sheet'!C30 -> 1004 | D12: ='Data Sheet'!D30 -> 1155 | E12: ='Data Sheet'!E30 -> 1394 | F12: ='Data Sheet'!F30 -> 1851 | G12: ='Data Sheet'!G30 -> 1516 | H12: ='Data Sheet'!H30 -> 2316 | I12: ='Data Sheet'!I30 -> 2134 | ... K12: ='Data Sheet'!K30 -> 2537 | L12: =SUM(Quarters!H12:K12) -> 2610 | M12: =M10-M11*M10 -> 2562.346 | N12: =N10-N11*N10 -> 2262.4373
A13: EPS | B13: =IF('Data Sheet'!B93>0,B12/'Data Sheet'!B93,0) -> 36.875 | C13: =IF('Data Sheet'!C93>0,C12/'Data Sheet'!C93,0) -> 41.833333 | D13: =IF('Data Sheet'!D93>0,D12/'Data Sheet'!D93,0) -> 48.125 | E13: =IF('Data Sheet'!E93>0,E12/'Data Sheet'!E93,0) -> 58.083333 | F13: =IF('Data Sheet'!F93>0,F12/'Data Sheet'!F93,0) -> 77.125 | G13: =IF('Data Sheet'!G93>0,G12/'Data Sheet'!G93,0) -> 63.166667 | H13: =IF('Data Sheet'!H93>0,H12/'Data Sheet'!H93,0) -> 96.5 | I13: =IF('Data Sheet'!I93>0,I12/'Data Sheet'!I93,0) -> 88.916667 | ... K13: =IF('Data Sheet'!K93>0,K12/'Data Sheet'!K93,0) -> 105.70833 | L13: =IF('Data Sheet'!$B6>0,'Profit & Loss'!L12/'Data Sheet'!$B6,0) -> 108.51242 | M13: =IF('Data Sheet'!$B6>0,'Profit & Loss'!M12/'Data Sheet'!$B6,0) -> 106.53117 | N13: =IF('Data Sheet'!$B6>0,'Profit & Loss'!N12/'Data Sheet'!$B6,0) -> 94.062281
A14: Price to earning | B14: =IF(B15>0,B15/B13,"") -> 41.989966 | C14: =IF(C15>0,C15/C13,"") -> 59.08996 | D14: =IF(D15>0,D15/D13,"") -> 63.942857 | E14: =IF(E15>0,E15/E13,"") -> 51.136872 | F14: =IF(F15>0,F15/F13,"") -> 43.614263 | G14: =IF(G15>0,G15/G13,"") -> 53.372296 | H14: =IF(H15>0,H15/H13,"") -> 45.719689 | I14: =IF(I15>0,I15/I13,"") -> 55.361387 | ... K14: =IF(K15>0,K15/K13,"") -> 56.783603 | L14: =IF(L13>0,L15/L13,0) -> 45.423372 | M14: =M25 -> 52.051732 | N14: =N25 -> 45.423372
A15: Price | B15: ='Data Sheet'!B90 -> 1548.38 | C15: ='Data Sheet'!C90 -> 2471.93 | D15: ='Data Sheet'!D90 -> 3077.25 | E15: ='Data Sheet'!E90 -> 2970.2 | F15: ='Data Sheet'!F90 -> 3363.75 | G15: ='Data Sheet'!G90 -> 3371.35 | H15: ='Data Sheet'!H90 -> 4411.95 | I15: ='Data Sheet'!I90 -> 4922.55 | ... K15: ='Data Sheet'!K90 -> 6002.5 | L15: ='Data Sheet'!B8 -> 4929 | M15: =M13*M14 -> 5545.1322 | N15: =N13*N14 -> 4272.6259
A17: RATIOS:
A18: Dividend Payout | B18: =IF('Data Sheet'!B30>0, 'Data Sheet'!B31/'Data Sheet'!B30, 0) -> 0.3 | C18: =IF('Data Sheet'!C30>0, 'Data Sheet'!C31/'Data Sheet'!C30, 0) -> 0.3 | D18: =IF('Data Sheet'!D30>0, 'Data Sheet'!D31/'Data Sheet'!D30, 0) -> 0.31 | E18: =IF('Data Sheet'!E30>0, 'Data Sheet'!E31/'Data Sheet'!E30, 0) -> 0.6 | F18: =IF('Data Sheet'!F30>0, 'Data Sheet'!F31/'Data Sheet'!F30, 0) -> 2.04 | G18: =IF('Data Sheet'!G30>0, 'Data Sheet'!G31/'Data Sheet'!G30, 0) -> 0.89 | H18: =IF('Data Sheet'!H30>0, 'Data Sheet'!H31/'Data Sheet'!H30, 0) -> 0.75 | I18: =IF('Data Sheet'!I30>0, 'Data Sheet'!I31/'Data Sheet'!I30, 0) -> 0.83 | ... K18: =IF('Data Sheet'!K30>0, 'Data Sheet'!K31/'Data Sheet'!K30, 0) -> 0.86
A19: OPM | B19: =IF(B6>0,B6/B4,0) -> 0.13077535 | C19: =IF(C6>0,C6/C4,0) -> 0.15521283 | D19: =IF(D6>0,D6/D4,0) -> 0.14647218 | E19: =IF(E6>0,E6/E4,0) -> 0.17189655 | F19: =IF(F6>0,F6/F4,0) -> 0.1938246 | G19: =IF(G6>0,G6/G4,0) -> 0.13962366 | H19: =IF(H6>0,H6/H4,0) -> 0.16267468 | I19: =IF(I6>0,I6/I4,0) -> 0.19443258 | ... L19: =IF(L6>0,L6/L4,0) -> 0.1843318
G22: TRENDS: | H22: 10 YEARS | I22: 7 YEARS | J22: 5 YEARS | K22: 3 YEARS | L22: RECENT | M22: BEST | N22: WORST
G23: Sales Growth | H23: =IF(B4=0,"",POWER($K4/B4,1/9)-1) -> 0.0868075 | I23: =IF(D4=0,"",POWER($K4/D4,1/7)-1) -> 0.081667115 | J23: =IF(F4=0,"",POWER($K4/F4,1/5)-1) -> 0.078326303 | K23: =IF(H4=0,"",POWER($K4/H4, 1/3)-1) -> 0.055196386 | L23: =IF(ISERROR(MAX(IF(J4=0,"",(K4-J4)/J4),IF(K4=0,"",(L4-K4)/K4))),"",MAX(IF(J4=0,"",(K4-J4)/J4),IF(K4=0,"",(L4-K4)/K4))) -> 0.067380037 | M23: =MAX(K23:L23) -> 0.067380037 | N23: =MIN(H23:L23) -> 0.055196386
G24: OPM | H24: =IF(SUM(B4:$K$4)=0,"",SUMPRODUCT(B19:$K$19,B4:$K$4)/SUM(B4:$K$4)) -> 0.16704085 | I24: =IF(SUM(E4:$K$4)=0,"",SUMPRODUCT(E19:$K$19,E4:$K$4)/SUM(E4:$K$4)) -> 0.17321304 | J24: =IF(SUM(G4:$K$4)=0,"",SUMPRODUCT(G19:$K$19,G4:$K$4)/SUM(G4:$K$4)) -> 0.17018244 | K24: =IF(SUM(I4:$K$4)=0, "", SUMPRODUCT(I19:$K$19,I4:$K$4)/SUM(I4:$K$4)) -> 0.18047434 | L24: =L19 -> 0.1843318 | M24: =MAX(K24:L24) -> 0.1843318 | N24: =MIN(H24:L24) -> 0.16704085
G25: Price to Earning | H25: =IF(ISERROR(AVERAGEIF(B14:$L14,">0")),"",AVERAGEIF(B14:$L14,">0")) -> 51.552076 | I25: =IF(ISERROR(AVERAGEIF(E14:$L14,">0")),"",AVERAGEIF(E14:$L14,">0")) -> 50.256256 | J25: =IF(ISERROR(AVERAGEIF(G14:$L14,">0")),"",AVERAGEIF(G14:$L14,">0")) -> 51.216486 | K25: =IF(ISERROR(AVERAGEIF(I14:$L14,">0")),"",AVERAGEIF(I14:$L14,">0")) -> 52.051732 | L25: =L14 -> 45.423372 | M25: =MAX(K25:L25) -> 52.051732 | N25: =MIN(H25:L25) -> 45.423372

Sheet Quarters
A1: ='Profit & Loss'!A1 -> BRITANNIA INDUSTRIES LTD | E1: =UPDATE | J1: SCREENER.IN
A3: Narration | B3: ='Data Sheet'!B41 -> 45352 | C3: ='Data Sheet'!C41 -> 45444 | D3: ='Data Sheet'!D41 -> 45536 | E3: ='Data Sheet'!E41 -> 45627 | F3: ='Data Sheet'!F41 -> 45717 | G3: ='Data Sheet'!G41 -> 45809 | H3: ='Data Sheet'!H41 -> 45901 | I3: ='Data Sheet'!I41 -> 45992 | ... K3: ='Data Sheet'!K41 -> 46174
A4: Sales | B4: ='Data Sheet'!B42 -> 4069 | C4: ='Data Sheet'!C42 -> 4250 | D4: ='Data Sheet'!D42 -> 4668 | E4: ='Data Sheet'!E42 -> 4593 | F4: ='Data Sheet'!F42 -> 4432 | G4: ='Data Sheet'!G42 -> 4622 | H4: ='Data Sheet'!H42 -> 4841 | I4: ='Data Sheet'!I42 -> 4970 | ... K4: ='Data Sheet'!K42 -> 5000
A5: Expenses | B5: ='Data Sheet'!B43 -> 3286 | C5: ='Data Sheet'!C43 -> 3497 | D5: ='Data Sheet'!D43 -> 3888 | E5: ='Data Sheet'!E43 -> 3750 | F5: ='Data Sheet'!F43 -> 3632 | G5: ='Data Sheet'!G43 -> 3870 | H5: ='Data Sheet'!H43 -> 3889 | I5: ='Data Sheet'!I43 -> 3992 | ... K5: ='Data Sheet'!K43 -> 4162
A6: Operating Profit | B6: ='Data Sheet'!B50 -> 784 | C6: ='Data Sheet'!C50 -> 753 | D6: ='Data Sheet'!D50 -> 780 | E6: ='Data Sheet'!E50 -> 843 | F6: ='Data Sheet'!F50 -> 801 | G6: ='Data Sheet'!G50 -> 752 | H6: ='Data Sheet'!H50 -> 951 | I6: ='Data Sheet'!I50 -> 977 | ... K6: ='Data Sheet'!K50 -> 838
A7: Other Income | B7: ='Data Sheet'!B44 -> 57 | C7: ='Data Sheet'!C44 -> 31 | D7: ='Data Sheet'!D44 -> 46 | E7: ='Data Sheet'!E44 -> 62 | F7: ='Data Sheet'!F44 -> 63 | G7: ='Data Sheet'!G44 -> 57 | H7: ='Data Sheet'!H44 -> 52 | I7: ='Data Sheet'!I44 -> 59 | ... K7: ='Data Sheet'!K44 -> 61
A8: Depreciation | B8: ='Data Sheet'!B45 -> 80 | C8: ='Data Sheet'!C45 -> 74 | D8: ='Data Sheet'!D45 -> 76 | E8: ='Data Sheet'!E45 -> 82 | F8: ='Data Sheet'!F45 -> 81 | G8: ='Data Sheet'!G45 -> 82 | H8: ='Data Sheet'!H45 -> 85 | I8: ='Data Sheet'!I45 -> 85 | ... K8: ='Data Sheet'!K45 -> 80
A9: Interest | B9: ='Data Sheet'!B46 -> 26 | C9: ='Data Sheet'!C46 -> 29 | D9: ='Data Sheet'!D46 -> 35 | E9: ='Data Sheet'!E46 -> 45 | F9: ='Data Sheet'!F46 -> 31 | G9: ='Data Sheet'!G46 -> 26 | H9: ='Data Sheet'!H46 -> 35 | I9: ='Data Sheet'!I46 -> 33 | ... K9: ='Data Sheet'!K46 -> 23
A10: Profit before tax | B10: ='Data Sheet'!B47 -> 735 | C10: ='Data Sheet'!C47 -> 681 | D10: ='Data Sheet'!D47 -> 715 | E10: ='Data Sheet'!E47 -> 778 | F10: ='Data Sheet'!F47 -> 752 | G10: ='Data Sheet'!G47 -> 701 | H10: ='Data Sheet'!H47 -> 884 | I10: ='Data Sheet'!I47 -> 919 | ... K10: ='Data Sheet'!K47 -> 797
A11: Tax | B11: ='Data Sheet'!B48 -> 198 | C11: ='Data Sheet'!C48 -> 176 | D11: ='Data Sheet'!D48 -> 183 | E11: ='Data Sheet'!E48 -> 196 | F11: ='Data Sheet'!F48 -> 193 | G11: ='Data Sheet'!G48 -> 181 | H11: ='Data Sheet'!H48 -> 229 | I11: ='Data Sheet'!I48 -> 237 | ... K11: ='Data Sheet'!K48 -> 204
A12: Net profit | B12: ='Data Sheet'!B49 -> 537 | C12: ='Data Sheet'!C49 -> 505 | D12: ='Data Sheet'!D49 -> 532 | E12: ='Data Sheet'!E49 -> 582 | F12: ='Data Sheet'!F49 -> 559 | G12: ='Data Sheet'!G49 -> 520 | H12: ='Data Sheet'!H49 -> 655 | I12: ='Data Sheet'!I49 -> 682 | ... K12: ='Data Sheet'!K49 -> 593
A14: OPM | B14: =IF(B4>0,B6/B4,"") -> 0.19267633 | C14: =IF(C4>0,C6/C4,"") -> 0.17717647 | D14: =IF(D4>0,D6/D4,"") -> 0.16709512 | E14: =IF(E4>0,E6/E4,"") -> 0.18354017 | F14: =IF(F4>0,F6/F4,"") -> 0.18073105 | G14: =IF(G4>0,G6/G4,"") -> 0.16270013 | H14: =IF(H4>0,H6/H4,"") -> 0.19644702 | I14: =IF(I4>0,I6/I4,"") -> 0.19657948 | ... K14: =IF(K4>0,K6/K4,"") -> 0.1676

Sheet Balance Sheet
A1: ='Profit & Loss'!A1 -> BRITANNIA INDUSTRIES LTD | E1: =UPDATE | J1: SCREENER.IN
A3: Narration | B3: ='Data Sheet'!B56 -> 42795 | C3: ='Data Sheet'!C56 -> 43160 | D3: ='Data Sheet'!D56 -> 43525 | E3: ='Data Sheet'!E56 -> 43891 | F3: ='Data Sheet'!F56 -> 44256 | G3: ='Data Sheet'!G56 -> 44621 | H3: ='Data Sheet'!H56 -> 44986 | I3: ='Data Sheet'!I56 -> 45352 | ... K3: ='Data Sheet'!K56 -> 46082
A4: Equity Share Capital | B4: ='Data Sheet'!B57 -> 24 | C4: ='Data Sheet'!C57 -> 24 | D4: ='Data Sheet'!D57 -> 24 | E4: ='Data Sheet'!E57 -> 24 | F4: ='Data Sheet'!F57 -> 24 | G4: ='Data Sheet'!G57 -> 24 | H4: ='Data Sheet'!H57 -> 24 | I4: ='Data Sheet'!I57 -> 24 | ... K4: ='Data Sheet'!K57 -> 24
A5: Reserves | B5: ='Data Sheet'!B58 -> 2672 | C5: ='Data Sheet'!C58 -> 3382 | D5: ='Data Sheet'!D58 -> 4229 | E5: ='Data Sheet'!E58 -> 4379 | F5: ='Data Sheet'!F58 -> 3524 | G5: ='Data Sheet'!G58 -> 2534 | H5: ='Data Sheet'!H58 -> 3510 | I5: ='Data Sheet'!I58 -> 3917 | ... K5: ='Data Sheet'!K58 -> 5082
A6: Borrowings | B6: ='Data Sheet'!B59 -> 125 | C6: ='Data Sheet'!C59 -> 201 | D6: ='Data Sheet'!D59 -> 156 | E6: ='Data Sheet'!E59 -> 1538 | F6: ='Data Sheet'!F59 -> 2107 | G6: ='Data Sheet'!G59 -> 2481 | H6: ='Data Sheet'!H59 -> 2997 | I6: ='Data Sheet'!I59 -> 2065 | ... K6: ='Data Sheet'!K59 -> 1380
A7: Other Liabilities | B7: ='Data Sheet'!B60 -> 1288 | C7: ='Data Sheet'!C60 -> 1581 | D7: ='Data Sheet'!D60 -> 1829 | E7: ='Data Sheet'!E60 -> 1889 | F7: ='Data Sheet'!F60 -> 2345 | G7: ='Data Sheet'!G60 -> 2487 | H7: ='Data Sheet'!H60 -> 2819 | I7: ='Data Sheet'!I60 -> 3065 | ... K7: ='Data Sheet'!K60 -> 3243
A8: Total | B8: ='Data Sheet'!B61 -> 4109 | C8: ='Data Sheet'!C61 -> 5188 | D8: ='Data Sheet'!D61 -> 6238 | E8: ='Data Sheet'!E61 -> 7830 | F8: ='Data Sheet'!F61 -> 8000 | G8: ='Data Sheet'!G61 -> 7527 | H8: ='Data Sheet'!H61 -> 9351 | I8: ='Data Sheet'!I61 -> 9072 | ... K8: ='Data Sheet'!K61 -> 9730
A10: Net Block | B10: ='Data Sheet'!B62 -> 1160 | C10: ='Data Sheet'!C62 -> 1346 | D10: ='Data Sheet'!D62 -> 1688 | E10: ='Data Sheet'!E62 -> 1878 | F10: ='Data Sheet'!F62 -> 1793 | G10: ='Data Sheet'!G62 -> 1753 | H10: ='Data Sheet'!H62 -> 2655 | I10: ='Data Sheet'!I62 -> 2771 | ... K10: ='Data Sheet'!K62 -> 2850
A11: Capital Work in Progress | B11: ='Data Sheet'!B63 -> 30 | C11: ='Data Sheet'!C63 -> 203 | D11: ='Data Sheet'!D63 -> 101 | E11: ='Data Sheet'!E63 -> 40 | F11: ='Data Sheet'!F63 -> 117 | G11: ='Data Sheet'!G63 -> 536 | H11: ='Data Sheet'!H63 -> 105 | I11: ='Data Sheet'!I63 -> 188 | ... K11: ='Data Sheet'!K63 -> 39
A12: Investments | B12: ='Data Sheet'!B64 -> 487 | C12: ='Data Sheet'!C64 -> 1079 | D12: ='Data Sheet'!D64 -> 1476 | E12: ='Data Sheet'!E64 -> 2893 | F12: ='Data Sheet'!F64 -> 2781 | G12: ='Data Sheet'!G64 -> 1762 | H12: ='Data Sheet'!H64 -> 3324 | I12: ='Data Sheet'!I64 -> 2767 | ... K12: ='Data Sheet'!K64 -> 3610
A13: Other Assets | B13: ='Data Sheet'!B65 -> 2432 | C13: ='Data Sheet'!C65 -> 2560 | D13: ='Data Sheet'!D65 -> 2972 | E13: ='Data Sheet'!E65 -> 3019 | F13: ='Data Sheet'!F65 -> 3310 | G13: ='Data Sheet'!G65 -> 3475 | H13: ='Data Sheet'!H65 -> 3266 | I13: ='Data Sheet'!I65 -> 3346 | ... K13: ='Data Sheet'!K65 -> 3232
A14: Total | B14: ='Data Sheet'!B66 -> 4109 | C14: ='Data Sheet'!C66 -> 5188 | D14: ='Data Sheet'!D66 -> 6238 | E14: ='Data Sheet'!E66 -> 7830 | F14: ='Data Sheet'!F66 -> 8000 | G14: ='Data Sheet'!G66 -> 7527 | H14: ='Data Sheet'!H66 -> 9351 | I14: ='Data Sheet'!I66 -> 9072 | ... K14: ='Data Sheet'!K66 -> 9730
A16: Working Capital | B16: =B13-B7 -> 1144 | C16: =C13-C7 -> 979 | D16: =D13-D7 -> 1143 | E16: =E13-E7 -> 1130 | F16: =F13-F7 -> 965 | G16: =G13-G7 -> 988 | H16: =H13-H7 -> 447 | I16: =I13-I7 -> 281 | ... K16: =K13-K7 -> -11
A17: Debtors | B17: ='Data Sheet'!B67 -> 179 | C17: ='Data Sheet'!C67 -> 305 | D17: ='Data Sheet'!D67 -> 394 | E17: ='Data Sheet'!E67 -> 320 | F17: ='Data Sheet'!F67 -> 257 | G17: ='Data Sheet'!G67 -> 332 | H17: ='Data Sheet'!H67 -> 329 | I17: ='Data Sheet'!I67 -> 393 | ... K17: ='Data Sheet'!K67 -> 469
A18: Inventory | B18: ='Data Sheet'!B68 -> 661 | C18: ='Data Sheet'!C68 -> 653 | D18: ='Data Sheet'!D68 -> 781 | E18: ='Data Sheet'!E68 -> 741 | F18: ='Data Sheet'!F68 -> 1091 | G18: ='Data Sheet'!G68 -> 1367 | H18: ='Data Sheet'!H68 -> 1193 | I18: ='Data Sheet'!I68 -> 1181 | ... K18: ='Data Sheet'!K68 -> 1346
A20: Debtor Days | B20: =IF('Profit & Loss'!B4>0,'Balance Sheet'!B17/('Profit & Loss'!B4/365),0) -> 7.2161476 | C20: =IF('Profit & Loss'!C4>0,'Balance Sheet'!C17/('Profit & Loss'!C4/365),0) -> 11.22907 | D20: =IF('Profit & Loss'!D4>0,'Balance Sheet'!D17/('Profit & Loss'!D4/365),0) -> 13.008593 | E20: =IF('Profit & Loss'!E4>0,'Balance Sheet'!E17/('Profit & Loss'!E4/365),0) -> 10.068966 | F20: =IF('Profit & Loss'!F4>0,'Balance Sheet'!F17/('Profit & Loss'!F4/365),0) -> 7.1410627 | G20: =IF('Profit & Loss'!G4>0,'Balance Sheet'!G17/('Profit & Loss'!G4/365),0) -> 8.5724392 | H20: =IF('Profit & Loss'!H4>0,'Balance Sheet'!H17/('Profit & Loss'!H4/365),0) -> 7.366726 | I20: =IF('Profit & Loss'!I4>0,'Balance Sheet'!I17/('Profit & Loss'!I4/365),0) -> 8.5541774 | ... K20: =IF('Profit & Loss'!K4>0,'Balance Sheet'!K17/('Profit & Loss'!K4/365),0) -> 8.938231
A21: Inventory Turnover | B21: =IF('Balance Sheet'!B18>0,'Profit & Loss'!B4/'Balance Sheet'!B18,0) -> 13.697428 | C21: =IF('Balance Sheet'!C18>0,'Profit & Loss'!C4/'Balance Sheet'!C18,0) -> 15.182236 | D21: =IF('Balance Sheet'!D18>0,'Profit & Loss'!D4/'Balance Sheet'!D18,0) -> 14.15493 | E21: =IF('Balance Sheet'!E18>0,'Profit & Loss'!E4/'Balance Sheet'!E18,0) -> 15.654521 | F21: =IF('Balance Sheet'!F18>0,'Profit & Loss'!F4/'Balance Sheet'!F18,0) -> 12.04033 | G21: =IF('Balance Sheet'!G18>0,'Profit & Loss'!G4/'Balance Sheet'!G18,0) -> 10.340892 | H21: =IF('Balance Sheet'!H18>0,'Profit & Loss'!H4/'Balance Sheet'!H18,0) -> 13.663873 | I21: =IF('Balance Sheet'!I18>0,'Profit & Loss'!I4/'Balance Sheet'!I18,0) -> 14.198984 | ... K21: =IF('Balance Sheet'!K18>0,'Profit & Loss'!K4/'Balance Sheet'!K18,0) -> 14.228826
A23: Return on Equity | B23: =IF(SUM('Balance Sheet'!B4:B5)>0,'Profit & Loss'!B12/SUM('Balance Sheet'!B4:B5),"") -> 0.32826409 | C23: =IF(SUM('Balance Sheet'!C4:C5)>0,'Profit & Loss'!C12/SUM('Balance Sheet'!C4:C5),"") -> 0.29477393 | D23: =IF(SUM('Balance Sheet'!D4:D5)>0,'Profit & Loss'!D12/SUM('Balance Sheet'!D4:D5),"") -> 0.27157301 | E23: =IF(SUM('Balance Sheet'!E4:E5)>0,'Profit & Loss'!E12/SUM('Balance Sheet'!E4:E5),"") -> 0.31660232 | F23: =IF(SUM('Balance Sheet'!F4:F5)>0,'Profit & Loss'!F12/SUM('Balance Sheet'!F4:F5),"") -> 0.52170237 | G23: =IF(SUM('Balance Sheet'!G4:G5)>0,'Profit & Loss'!G12/SUM('Balance Sheet'!G4:G5),"") -> 0.59265051 | H23: =IF(SUM('Balance Sheet'!H4:H5)>0,'Profit & Loss'!H12/SUM('Balance Sheet'!H4:H5),"") -> 0.65534805 | I23: =IF(SUM('Balance Sheet'!I4:I5)>0,'Profit & Loss'!I12/SUM('Balance Sheet'!I4:I5),"") -> 0.54148693 | ... K23: =IF(SUM('Balance Sheet'!K4:K5)>0,'Profit & Loss'!K12/SUM('Balance Sheet'!K4:K5),"") -> 0.49686643
A24: Return on Capital Emp | C24: =IF((B4+B5+B6+C4+C5+C6)>0,('Profit & Loss'!C10+'Profit & Loss'!C9)*2/(B4+B5+B6+C4+C5+C6),"") -> 0.47479776 | D24: =IF((C4+C5+C6+D4+D5+D6)>0,('Profit & Loss'!D10+'Profit & Loss'!D9)*2/(C4+C5+C6+D4+D5+D6),"") -> 0.44336327 | E24: =IF((D4+D5+D6+E4+E5+E6)>0,('Profit & Loss'!E10+'Profit & Loss'!E9)*2/(D4+D5+D6+E4+E5+E6),"") -> 0.37120773 | F24: =IF((E4+E5+E6+F4+F5+F6)>0,('Profit & Loss'!F10+'Profit & Loss'!F9)*2/(E4+E5+E6+F4+F5+F6),"") -> 0.45274232 | G24: =IF((F4+F5+F6+G4+G5+G6)>0,('Profit & Loss'!G10+'Profit & Loss'!G9)*2/(F4+F5+F6+G4+G5+G6),"") -> 0.41556013 | H24: =IF((G4+G5+G6+H4+H5+H6)>0,('Profit & Loss'!H10+'Profit & Loss'!H9)*2/(G4+G5+G6+H4+H5+H6),"") -> 0.55350043 | I24: =IF((H4+H5+H6+I4+I5+I6)>0,('Profit & Loss'!I10+'Profit & Loss'!I9)*2/(H4+H5+H6+I4+I5+I6),"") -> 0.49086703 | J24: =IF((I4+I5+I6+J4+J5+J6)>0,('Profit & Loss'!J10+'Profit & Loss'!J9)*2/(I4+I5+I6+J4+J5+J6),"") -> 0.52821087 | K24: =IF((J4+J5+J6+K4+K5+K6)>0,('Profit & Loss'!K10+'Profit & Loss'!K9)*2/(J4+J5+J6+K4+K5+K6),"") -> 0.56282571

Sheet Cash Flow
A1: ='Balance Sheet'!A1 -> BRITANNIA INDUSTRIES LTD | E1: =UPDATE | J1: SCREENER.IN
A3: Narration | B3: ='Data Sheet'!B81 -> 42795 | C3: ='Data Sheet'!C81 -> 43160 | D3: ='Data Sheet'!D81 -> 43525 | E3: ='Data Sheet'!E81 -> 43891 | F3: ='Data Sheet'!F81 -> 44256 | G3: ='Data Sheet'!G81 -> 44621 | H3: ='Data Sheet'!H81 -> 44986 | I3: ='Data Sheet'!I81 -> 45352 | ... K3: ='Data Sheet'!K81 -> 46082
A4: Cash from Operating Activity | B4: ='Data Sheet'!B82 -> 441 | C4: ='Data Sheet'!C82 -> 1249 | D4: ='Data Sheet'!D82 -> 1156 | E4: ='Data Sheet'!E82 -> 1485 | F4: ='Data Sheet'!F82 -> 1851 | G4: ='Data Sheet'!G82 -> 1300 | H4: ='Data Sheet'!H82 -> 2526 | I4: ='Data Sheet'!I82 -> 2573 | ... K4: ='Data Sheet'!K82 -> 2612
A5: Cash from Investing Activity | B5: ='Data Sheet'!B83 -> -150 | C5: ='Data Sheet'!C83 -> -957 | D5: ='Data Sheet'!D83 -> -852 | E5: ='Data Sheet'!E83 -> -1526 | F5: ='Data Sheet'!F83 -> 459 | G5: ='Data Sheet'!G83 -> 914 | H5: ='Data Sheet'!H83 -> -1507 | I5: ='Data Sheet'!I83 -> 485 | ... K5: ='Data Sheet'!K83 -> -741
A6: Cash from Financing Activity | B6: ='Data Sheet'!B84 -> -295 | C6: ='Data Sheet'!C84 -> -232 | D6: ='Data Sheet'!D84 -> -353 | E6: ='Data Sheet'!E84 -> 58 | F6: ='Data Sheet'!F84 -> -2244 | G6: ='Data Sheet'!G84 -> -2246 | H6: ='Data Sheet'!H84 -> -1028 | I6: ='Data Sheet'!I84 -> -2839 | ... K6: ='Data Sheet'!K84 -> -1783
A7: Net Cash Flow | B7: ='Data Sheet'!B85 -> -4 | C7: ='Data Sheet'!C85 -> 60 | D7: ='Data Sheet'!D85 -> -49 | E7: ='Data Sheet'!E85 -> 17 | F7: ='Data Sheet'!F85 -> 66 | G7: ='Data Sheet'!G85 -> -32 | H7: ='Data Sheet'!H85 -> -9 | I7: ='Data Sheet'!I85 -> 219 | ... K7: ='Data Sheet'!K85 -> 88

Sheet Customization
A1: How to use it?
A3: You can customize this workbook as you want.
B4: You can add custom formating, add conditional formating, add your own formulas… do ANYTHING.
B5: Please don't edit the "Data Sheet" only.
A7: After customization, you can upload this back on Screener.
B8: Upload on: | C8: https://www.screener.in/excel/
A10: Download your customized workbooks now onwards.
B11: Now whenever you will "Export to excel" from Screener, it will export your customized file.
A14: TESTING:
B15: This is a testing feature currently.
B16: You can report any formula errors on the worksheet at: support@screener.in

Sheet Common Size Statement
B2: ="Common Size Statement - "&'Data Sheet'!$B$1 -> Common Size Statement - BRITANNIA INDUSTRIES LTD
B4: Particulars | C4: ='Data Sheet'!B$16 -> 42795 | D4: ='Data Sheet'!C$16 -> 43160 | E4: ='Data Sheet'!D$16 -> 43525 | F4: ='Data Sheet'!E$16 -> 43891 | G4: ='Data Sheet'!F$16 -> 44256 | H4: ='Data Sheet'!G$16 -> 44621 | I4: ='Data Sheet'!H$16 -> 44986 | J4: ='Data Sheet'!I$16 -> 45352 | ... L4: ='Data Sheet'!K$16 -> 46082
B6: ='Data Sheet'!A17 -> Sales | C6: ='Data Sheet'!B17/'Data Sheet'!B$17 -> 1 | D6: ='Data Sheet'!C17/'Data Sheet'!C$17 -> 1 | E6: ='Data Sheet'!D17/'Data Sheet'!D$17 -> 1 | F6: ='Data Sheet'!E17/'Data Sheet'!E$17 -> 1 | G6: ='Data Sheet'!F17/'Data Sheet'!F$17 -> 1 | H6: ='Data Sheet'!G17/'Data Sheet'!G$17 -> 1 | I6: ='Data Sheet'!H17/'Data Sheet'!H$17 -> 1 | J6: ='Data Sheet'!I17/'Data Sheet'!I$17 -> 1 | ... L6: ='Data Sheet'!K17/'Data Sheet'!K$17 -> 1
B7: ='Data Sheet'!A18 -> Raw Material Cost | C7: ='Data Sheet'!B18/'Data Sheet'!B$17 -> 0.62326044 | D7: ='Data Sheet'!C18/'Data Sheet'!C$17 -> 0.61539237 | E7: ='Data Sheet'!D18/'Data Sheet'!D$17 -> 0.59855269 | F7: ='Data Sheet'!E18/'Data Sheet'!E$17 -> 0.59267241 | G7: ='Data Sheet'!F18/'Data Sheet'!F$17 -> 0.58335871 | H7: ='Data Sheet'!G18/'Data Sheet'!G$17 -> 0.62507074 | I7: ='Data Sheet'!H18/'Data Sheet'!H$17 -> 0.59284706 | J7: ='Data Sheet'!I18/'Data Sheet'!I$17 -> 0.56580595 | ... L7: ='Data Sheet'!K18/'Data Sheet'!K$17 -> 0.5824457
B8: ='Data Sheet'!A19 -> Change in Inventory | C8: ='Data Sheet'!B19/'Data Sheet'!B$17 -> -0.0059642147 | D8: ='Data Sheet'!C19/'Data Sheet'!C$17 -> 0.00060520476 | E8: ='Data Sheet'!D19/'Data Sheet'!D$17 -> -0.0049751244 | F8: ='Data Sheet'!E19/'Data Sheet'!E$17 -> 0.0045689655 | G8: ='Data Sheet'!F19/'Data Sheet'!F$17 -> -0.002816687 | H8: ='Data Sheet'!G19/'Data Sheet'!G$17 -> -0.0053056027 | I8: ='Data Sheet'!H19/'Data Sheet'!H$17 -> -0.0044782529 | J8: ='Data Sheet'!I19/'Data Sheet'!I$17 -> 0.00023853539 | ... L8: ='Data Sheet'!K19/'Data Sheet'!K$17 -> -0.0011487051
B9: ='Data Sheet'!A20 -> Power and Fuel | C9: ='Data Sheet'!B20/'Data Sheet'!B$17 -> 0 | D9: ='Data Sheet'!C20/'Data Sheet'!C$17 -> 0 | E9: ='Data Sheet'!D20/'Data Sheet'!D$17 -> 0 | F9: ='Data Sheet'!E20/'Data Sheet'!E$17 -> 0 | G9: ='Data Sheet'!F20/'Data Sheet'!F$17 -> 0 | H9: ='Data Sheet'!G20/'Data Sheet'!G$17 -> 0 | I9: ='Data Sheet'!H20/'Data Sheet'!H$17 -> 0 | J9: ='Data Sheet'!I20/'Data Sheet'!I$17 -> 0 | ... L9: ='Data Sheet'!K20/'Data Sheet'!K$17 -> 0
B10: ='Data Sheet'!A21 -> Other Mfr. Exp | C10: ='Data Sheet'!B21/'Data Sheet'!B$17 -> 0.07 | D10: ='Data Sheet'!C21/'Data Sheet'!C$17 -> 0.06 | E10: ='Data Sheet'!D21/'Data Sheet'!D$17 -> 0.07 | F10: ='Data Sheet'!E21/'Data Sheet'!E$17 -> 0.07 | G10: ='Data Sheet'!F21/'Data Sheet'!F$17 -> 0.06 | H10: ='Data Sheet'!G21/'Data Sheet'!G$17 -> 0.07 | I10: ='Data Sheet'!H21/'Data Sheet'!H$17 -> 0.07 | J10: ='Data Sheet'!I21/'Data Sheet'!I$17 -> 0.07 | ... L10: ='Data Sheet'!K21/'Data Sheet'!K$17 -> 0.07
B11: ='Data Sheet'!A22 -> Employee Cost | C11: ='Data Sheet'!B22/'Data Sheet'!B$17 -> 0.04 | D11: ='Data Sheet'!C22/'Data Sheet'!C$17 -> 0.04 | E11: ='Data Sheet'!D22/'Data Sheet'!D$17 -> 0.04 | F11: ='Data Sheet'!E22/'Data Sheet'!E$17 -> 0.04 | G11: ='Data Sheet'!F22/'Data Sheet'!F$17 -> 0.04 | H11: ='Data Sheet'!G22/'Data Sheet'!G$17 -> 0.04 | I11: ='Data Sheet'!H22/'Data Sheet'!H$17 -> 0.04 | J11: ='Data Sheet'!I22/'Data Sheet'!I$17 -> 0.04 | ... L11: ='Data Sheet'!K22/'Data Sheet'!K$17 -> 0.04
B12: ='Data Sheet'!A23 -> Selling and admin | C12: ='Data Sheet'!B23/'Data Sheet'!B$17 -> 0 | D12: ='Data Sheet'!C23/'Data Sheet'!C$17 -> 0 | E12: ='Data Sheet'!D23/'Data Sheet'!D$17 -> 0 | F12: ='Data Sheet'!E23/'Data Sheet'!E$17 -> 0 | G12: ='Data Sheet'!F23/'Data Sheet'!F$17 -> 0 | H12: ='Data Sheet'!G23/'Data Sheet'!G$17 -> 0 | I12: ='Data Sheet'!H23/'Data Sheet'!H$17 -> 0 | J12: ='Data Sheet'!I23/'Data Sheet'!I$17 -> 0 | ... L12: ='Data Sheet'!K23/'Data Sheet'!K$17 -> 0
B13: ='Data Sheet'!A24 -> Other Expenses | C13: ='Data Sheet'!B24/'Data Sheet'!B$17 -> 0.13 | D13: ='Data Sheet'!C24/'Data Sheet'!C$17 -> 0.13 | E13: ='Data Sheet'!D24/'Data Sheet'!D$17 -> 0.14 | F13: ='Data Sheet'!E24/'Data Sheet'!E$17 -> 0.13 | G13: ='Data Sheet'!F24/'Data Sheet'!F$17 -> 0.12 | H13: ='Data Sheet'!G24/'Data Sheet'!G$17 -> 0.12 | I13: ='Data Sheet'!H24/'Data Sheet'!H$17 -> 0.13 | J13: ='Data Sheet'!I24/'Data Sheet'!I$17 -> 0.13 | ... L13: ='Data Sheet'!K24/'Data Sheet'!K$17 -> 0.13
B14: ='Data Sheet'!A25 -> Other Income | C14: ='Data Sheet'!B25/'Data Sheet'!B$17 -> 0.016677712 | D14: ='Data Sheet'!C25/'Data Sheet'!C$17 -> 0.016743998 | E14: ='Data Sheet'!D25/'Data Sheet'!D$17 -> 0.018634102 | F14: ='Data Sheet'!E25/'Data Sheet'!E$17 -> 0.022672414 | G14: ='Data Sheet'!F25/'Data Sheet'!F$17 -> 0.023827649 | H14: ='Data Sheet'!G25/'Data Sheet'!G$17 -> 0.015704584 | I14: ='Data Sheet'!H25/'Data Sheet'!H$17 -> 0.03662352 | J14: ='Data Sheet'!I25/'Data Sheet'!I$17 -> 0.012582742 | ... L14: ='Data Sheet'!K25/'Data Sheet'!K$17 -> 0.011695906
B15: ='Data Sheet'!A26 -> Depreciation | C15: ='Data Sheet'!B26/'Data Sheet'!B$17 -> 0.013143362 | D15: ='Data Sheet'!C26/'Data Sheet'!C$17 -> 0.014323179 | E15: ='Data Sheet'!D26/'Data Sheet'!D$17 -> 0.014654003 | F15: ='Data Sheet'!E26/'Data Sheet'!E$17 -> 0.015948276 | G15: ='Data Sheet'!F26/'Data Sheet'!F$17 -> 0.015073082 | H15: ='Data Sheet'!G26/'Data Sheet'!G$17 -> 0.014219015 | I15: ='Data Sheet'!H26/'Data Sheet'!H$17 -> 0.01386418 | J15: ='Data Sheet'!I26/'Data Sheet'!I$17 -> 0.017890154 | ... L15: ='Data Sheet'!K26/'Data Sheet'!K$17 -> 0.017596074
B16: ='Data Sheet'!A27 -> Interest | C16: ='Data Sheet'!B27/'Data Sheet'!B$17 -> 0.0005522421 | D16: ='Data Sheet'!C27/'Data Sheet'!C$17 -> 0.00080693968 | E16: ='Data Sheet'!D27/'Data Sheet'!D$17 -> 0.00081411126 | F16: ='Data Sheet'!E27/'Data Sheet'!E$17 -> 0.006637931 | G16: ='Data Sheet'!F27/'Data Sheet'!F$17 -> 0.0084500609 | H16: ='Data Sheet'!G27/'Data Sheet'!G$17 -> 0.010186757 | I16: ='Data Sheet'!H27/'Data Sheet'!H$17 -> 0.010367462 | J16: ='Data Sheet'!I27/'Data Sheet'!I$17 -> 0.0097799511 | ... L16: ='Data Sheet'!K27/'Data Sheet'!K$17 -> 0.0059001671
B17: ='Data Sheet'!A28 -> Profit before tax | C17: ='Data Sheet'!B28/'Data Sheet'!B$17 -> 0.14402474 | D17: ='Data Sheet'!C28/'Data Sheet'!C$17 -> 0.1531168 | E17: ='Data Sheet'!D28/'Data Sheet'!D$17 -> 0.15992763 | F17: ='Data Sheet'!E28/'Data Sheet'!E$17 -> 0.15896552 | G17: ='Data Sheet'!F28/'Data Sheet'!F$17 -> 0.19138246 | H17: ='Data Sheet'!G28/'Data Sheet'!G$17 -> 0.14700057 | I17: ='Data Sheet'!H28/'Data Sheet'!H$17 -> 0.1860622 | J17: ='Data Sheet'!I28/'Data Sheet'!I$17 -> 0.1737134 | ... L17: ='Data Sheet'!K28/'Data Sheet'!K$17 -> 0.17173141
... B21: ='Data Sheet'!A32 -> EBITDA | C21: ='Data Sheet'!B32/'Data Sheet'!B$17 -> 0.15772034 | D21: ='Data Sheet'!C32/'Data Sheet'!C$17 -> 0.16824692 | E21: ='Data Sheet'!D32/'Data Sheet'!D$17 -> 0.17539575 | F21: ='Data Sheet'!E32/'Data Sheet'!E$17 -> 0.18155172 | G21: ='Data Sheet'!F32/'Data Sheet'!F$17 -> 0.2149056 | H21: ='Data Sheet'!G32/'Data Sheet'!G$17 -> 0.17140634 | I21: ='Data Sheet'!H32/'Data Sheet'!H$17 -> 0.21029385 | J21: ='Data Sheet'!I32/'Data Sheet'!I$17 -> 0.20138351 | ... L21: ='Data Sheet'!K32/'Data Sheet'!K$17 -> 0.19522765
B23: ="Common Size Balance Sheet - "&'Data Sheet'!$B$1 -> Common Size Balance Sheet - BRITANNIA INDUSTRIES LTD
B25: Particulars | C25: ='Data Sheet'!B$16 -> 42795 | D25: ='Data Sheet'!C$16 -> 43160 | E25: ='Data Sheet'!D$16 -> 43525 | F25: ='Data Sheet'!E$16 -> 43891 | G25: ='Data Sheet'!F$16 -> 44256 | H25: ='Data Sheet'!G$16 -> 44621 | I25: ='Data Sheet'!H$16 -> 44986 | J25: ='Data Sheet'!I$16 -> 45352 | ... L25: ='Data Sheet'!K$16 -> 46082
B27: Total Liabilities | C27: ='Data Sheet'!B61/'Data Sheet'!B$61 -> 1 | D27: ='Data Sheet'!C61/'Data Sheet'!C$61 -> 1 | E27: ='Data Sheet'!D61/'Data Sheet'!D$61 -> 1 | F27: ='Data Sheet'!E61/'Data Sheet'!E$61 -> 1 | G27: ='Data Sheet'!F61/'Data Sheet'!F$61 -> 1 | H27: ='Data Sheet'!G61/'Data Sheet'!G$61 -> 1 | I27: ='Data Sheet'!H61/'Data Sheet'!H$61 -> 1 | J27: ='Data Sheet'!I61/'Data Sheet'!I$61 -> 1 | ... L27: ='Data Sheet'!K61/'Data Sheet'!K$61 -> 1
B28: ='Data Sheet'!A57 -> Equity Share Capital | C28: ='Data Sheet'!B57/'Data Sheet'!B$61 -> 0.0058408372 | D28: ='Data Sheet'!C57/'Data Sheet'!C$61 -> 0.0046260601 | E28: ='Data Sheet'!D57/'Data Sheet'!D$61 -> 0.003847387 | F28: ='Data Sheet'!E57/'Data Sheet'!E$61 -> 0.0030651341 | G28: ='Data Sheet'!F57/'Data Sheet'!F$61 -> 0.003 | H28: ='Data Sheet'!G57/'Data Sheet'!G$61 -> 0.0031885213 | I28: ='Data Sheet'!H57/'Data Sheet'!H$61 -> 0.0025665704 | J28: ='Data Sheet'!I57/'Data Sheet'!I$61 -> 0.0026455026 | ... L28: ='Data Sheet'!K57/'Data Sheet'!K$61 -> 0.0024665982
B29: ='Data Sheet'!A58 -> Reserves | C29: ='Data Sheet'!B58/'Data Sheet'!B$61 -> 0.65027987 | D29: ='Data Sheet'!C58/'Data Sheet'!C$61 -> 0.65188897 | E29: ='Data Sheet'!D58/'Data Sheet'!D$61 -> 0.67794165 | F29: ='Data Sheet'!E58/'Data Sheet'!E$61 -> 0.55925926 | G29: ='Data Sheet'!F58/'Data Sheet'!F$61 -> 0.4405 | H29: ='Data Sheet'!G58/'Data Sheet'!G$61 -> 0.33665471 | I29: ='Data Sheet'!H58/'Data Sheet'!H$61 -> 0.37536092 | J29: ='Data Sheet'!I58/'Data Sheet'!I$61 -> 0.43176808 | ... L29: ='Data Sheet'!K58/'Data Sheet'!K$61 -> 0.52230216
B30: ='Data Sheet'!A59 -> Borrowings | C30: ='Data Sheet'!B59/'Data Sheet'!B$61 -> 0.030421027 | D30: ='Data Sheet'!C59/'Data Sheet'!C$61 -> 0.038743254 | E30: ='Data Sheet'!D59/'Data Sheet'!D$61 -> 0.025008015 | F30: ='Data Sheet'!E59/'Data Sheet'!E$61 -> 0.19642401 | G30: ='Data Sheet'!F59/'Data Sheet'!F$61 -> 0.263375 | H30: ='Data Sheet'!G59/'Data Sheet'!G$61 -> 0.32961339 | I30: ='Data Sheet'!H59/'Data Sheet'!H$61 -> 0.32050048 | J30: ='Data Sheet'!I59/'Data Sheet'!I$61 -> 0.22762346 | ... L30: ='Data Sheet'!K59/'Data Sheet'!K$61 -> 0.14182939
B31: ='Data Sheet'!A60 -> Other Liabilities | C31: ='Data Sheet'!B60/'Data Sheet'!B$61 -> 0.31345826 | D31: ='Data Sheet'!C60/'Data Sheet'!C$61 -> 0.30474171 | E31: ='Data Sheet'!D60/'Data Sheet'!D$61 -> 0.29320295 | F31: ='Data Sheet'!E60/'Data Sheet'!E$61 -> 0.2412516 | G31: ='Data Sheet'!F60/'Data Sheet'!F$61 -> 0.293125 | H31: ='Data Sheet'!G60/'Data Sheet'!G$61 -> 0.33041052 | I31: ='Data Sheet'!H60/'Data Sheet'!H$61 -> 0.30146508 | J31: ='Data Sheet'!I60/'Data Sheet'!I$61 -> 0.33785273 | ... L31: ='Data Sheet'!K60/'Data Sheet'!K$61 -> 0.33329908
B33: Total Assets | C33: ='Data Sheet'!B66/'Data Sheet'!B$66 -> 1 | D33: ='Data Sheet'!C66/'Data Sheet'!C$66 -> 1 | E33: ='Data Sheet'!D66/'Data Sheet'!D$66 -> 1 | F33: ='Data Sheet'!E66/'Data Sheet'!E$66 -> 1 | G33: ='Data Sheet'!F66/'Data Sheet'!F$66 -> 1 | H33: ='Data Sheet'!G66/'Data Sheet'!G$66 -> 1 | I33: ='Data Sheet'!H66/'Data Sheet'!H$66 -> 1 | J33: ='Data Sheet'!I66/'Data Sheet'!I$66 -> 1 | ... L33: ='Data Sheet'!K66/'Data Sheet'!K$66 -> 1
B34: Fixed Assets Net Block | C34: ='Data Sheet'!B62/'Data Sheet'!B$66 -> 0.28230713 | D34: ='Data Sheet'!C62/'Data Sheet'!C$66 -> 0.25944487 | E34: ='Data Sheet'!D62/'Data Sheet'!D$66 -> 0.27059955 | F34: ='Data Sheet'!E62/'Data Sheet'!E$66 -> 0.23984674 | G34: ='Data Sheet'!F62/'Data Sheet'!F$66 -> 0.224125 | H34: ='Data Sheet'!G62/'Data Sheet'!G$66 -> 0.23289491 | I34: ='Data Sheet'!H62/'Data Sheet'!H$66 -> 0.28392685 | J34: ='Data Sheet'!I62/'Data Sheet'!I$66 -> 0.30544533 | ... L34: ='Data Sheet'!K62/'Data Sheet'!K$66 -> 0.29290853
B35: ='Data Sheet'!A63 -> Capital Work in Progress | C35: ='Data Sheet'!B63/'Data Sheet'!B$66 -> 0.0073010465 | D35: ='Data Sheet'!C63/'Data Sheet'!C$66 -> 0.039128759 | E35: ='Data Sheet'!D63/'Data Sheet'!D$66 -> 0.016191087 | F35: ='Data Sheet'!E63/'Data Sheet'!E$66 -> 0.0051085568 | G35: ='Data Sheet'!F63/'Data Sheet'!F$66 -> 0.014625 | H35: ='Data Sheet'!G63/'Data Sheet'!G$66 -> 0.07121031 | I35: ='Data Sheet'!H63/'Data Sheet'!H$66 -> 0.011228746 | J35: ='Data Sheet'!I63/'Data Sheet'!I$66 -> 0.020723104 | ... L35: ='Data Sheet'!K63/'Data Sheet'!K$66 -> 0.004008222
B36: ='Data Sheet'!A64 -> Investments | C36: ='Data Sheet'!B64/'Data Sheet'!B$66 -> 0.11852032 | D36: ='Data Sheet'!C64/'Data Sheet'!C$66 -> 0.20797995 | E36: ='Data Sheet'!D64/'Data Sheet'!D$66 -> 0.2366143 | F36: ='Data Sheet'!E64/'Data Sheet'!E$66 -> 0.36947637 | G36: ='Data Sheet'!F64/'Data Sheet'!F$66 -> 0.347625 | H36: ='Data Sheet'!G64/'Data Sheet'!G$66 -> 0.23409061 | I36: ='Data Sheet'!H64/'Data Sheet'!H$66 -> 0.35547 | J36: ='Data Sheet'!I64/'Data Sheet'!I$66 -> 0.30500441 | ... L36: ='Data Sheet'!K64/'Data Sheet'!K$66 -> 0.37101747
B37: ='Data Sheet'!A65 -> Other Assets | C37: ='Data Sheet'!B74/'Data Sheet'!B66 -> 0 | D37: ='Data Sheet'!C74/'Data Sheet'!C66 -> 0 | E37: ='Data Sheet'!D74/'Data Sheet'!D66 -> 0 | F37: ='Data Sheet'!E74/'Data Sheet'!E66 -> 0 | G37: ='Data Sheet'!F74/'Data Sheet'!F66 -> 0 | H37: ='Data Sheet'!G74/'Data Sheet'!G66 -> 0 | I37: ='Data Sheet'!H74/'Data Sheet'!H66 -> 0 | J37: ='Data Sheet'!I74/'Data Sheet'!I66 -> 0 | ... L37: ='Data Sheet'!K74/'Data Sheet'!K66 -> 0
B38: ='Data Sheet'!A67 -> Receivables | C38: ='Data Sheet'!B67/'Data Sheet'!B$66 -> 0.043562911 | D38: ='Data Sheet'!C67/'Data Sheet'!C$66 -> 0.058789514 | E38: ='Data Sheet'!D67/'Data Sheet'!D$66 -> 0.06316127 | F38: ='Data Sheet'!E67/'Data Sheet'!E$66 -> 0.040868455 | G38: ='Data Sheet'!F67/'Data Sheet'!F$66 -> 0.032125 | H38: ='Data Sheet'!G67/'Data Sheet'!G$66 -> 0.044107878 | I38: ='Data Sheet'!H67/'Data Sheet'!H$66 -> 0.035183403 | J38: ='Data Sheet'!I67/'Data Sheet'!I$66 -> 0.043320106 | ... L38: ='Data Sheet'!K67/'Data Sheet'!K$66 -> 0.048201439
B39: ='Data Sheet'!A68 -> Inventory | C39: ='Data Sheet'!B68/'Data Sheet'!B$66 -> 0.16086639 | D39: ='Data Sheet'!C68/'Data Sheet'!C$66 -> 0.12586739 | E39: ='Data Sheet'!D68/'Data Sheet'!D$66 -> 0.12520038 | F39: ='Data Sheet'!E68/'Data Sheet'!E$66 -> 0.094636015 | G39: ='Data Sheet'!F68/'Data Sheet'!F$66 -> 0.136375 | H39: ='Data Sheet'!G68/'Data Sheet'!G$66 -> 0.18161286 | I39: ='Data Sheet'!H68/'Data Sheet'!H$66 -> 0.12757994 | J39: ='Data Sheet'!I68/'Data Sheet'!I$66 -> 0.13018078 | ... L39: ='Data Sheet'!K68/'Data Sheet'!K$66 -> 0.13833505
B40: ='Data Sheet'!A69 -> Cash & Bank | C40: ='Data Sheet'!B69/'Data Sheet'!B$66 -> 0.029447554 | D40: ='Data Sheet'!C69/'Data Sheet'!C$66 -> 0.035851966 | E40: ='Data Sheet'!D69/'Data Sheet'!D$66 -> 0.017633857 | F40: ='Data Sheet'!E69/'Data Sheet'!E$66 -> 0.015708812 | G40: ='Data Sheet'!F69/'Data Sheet'!F$66 -> 0.026375 | H40: ='Data Sheet'!G69/'Data Sheet'!G$66 -> 0.024578185 | I40: ='Data Sheet'!H69/'Data Sheet'!H$66 -> 0.021174206 | J40: ='Data Sheet'!I69/'Data Sheet'!I$66 -> 0.049162257 | ... L40: ='Data Sheet'!K69/'Data Sheet'!K$66 -> 0.036176773

Sheet Data Sheet
A1: COMPANY NAME | B1: BRITANNIA INDUSTRIES LTD | E1: =IF(B2<>B3, "A NEW VERSION OF THE WORKSHEET IS AVAILABLE", "")
A2: LATEST VERSION | B2: 2.1 | E2: PLEASE DO NOT MAKE ANY CHANGES TO THIS SHEET
A3: CURRENT VERSION | B3: 2.1
A5: META
A6: Number of shares | B6: =IF(B9>0, B9/B8, 0) -> 24.052546
A7: Face Value | B7: 1
A8: Current Price | B8: 4929
A9: Market Capitalization | B9: 118555
A15: PROFIT & LOSS
A16: Report Date | B16: 42795 | C16: 43160 | D16: 43525 | E16: 43891 | F16: 44256 | G16: 44621 | H16: 44986 | I16: 45352 | J16: 45717 | K16: 46082
A17: Sales | B17: 9054 | C17: 9914 | D17: 11055 | E17: 11600 | F17: 13136 | G17: 14136 | H17: 16301 | I17: 16769 | J17: 17943 | K17: 19152
A18: Raw Material Cost | B18: 5643 | C18: 6101 | D18: 6617 | E18: 6875 | F18: 7663 | G18: 8836 | H18: 9664 | I18: 9488 | J18: 10669 | K18: 11155
A19: Change in Inventory | B19: -54 | C19: 6 | D19: -55 | E19: 53 | F19: -37 | G19: -75 | H19: -73 | I19: 4 | J19: -65 | K19: -22
A20: Power and Fuel | B20: 0 | C20: 0 | D20: 0 | E20: 0 | F20: 0 | G20: 0 | H20: 0 | I20: 0 | J20: 0 | K20: 0
A21: Other Mfr. Exp | B21: 633.78 | C21: 594.84 | D21: 773.85 | E21: 812 | F21: 788.16 | G21: 989.52 | H21: 1141.07 | I21: 1173.83 | J21: 1256.01 | K21: 1340.64
A22: Employee Cost | B22: 362.16 | C22: 396.56 | D22: 442.2 | E22: 464 | F22: 525.44 | G22: 565.44 | H22: 652.04 | I22: 670.76 | J22: 717.72 | K22: 766.08
A23: Selling and admin | B23: 0 | C23: 0 | D23: 0 | E23: 0 | F23: 0 | G23: 0 | H23: 0 | I23: 0 | J23: 0 | K23: 0
A24: Other Expenses | B24: 1177.02 | C24: 1288.82 | D24: 1547.7 | E24: 1508 | F24: 1576.32 | G24: 1696.32 | H24: 2119.13 | I24: 2179.97 | J24: 2153.16 | K24: 2489.76
A25: Other Income | B25: 151 | C25: 166 | D25: 206 | E25: 263 | F25: 313 | G25: 222 | H25: 597 | I25: 211 | J25: 202 | K25: 224
A26: Depreciation | B26: 119 | C26: 142 | D26: 162 | E26: 185 | F26: 198 | G26: 201 | H26: 226 | I26: 300 | J26: 313 | K26: 337
A27: Interest | B27: 5 | C27: 8 | D27: 9 | E27: 77 | F27: 111 | G27: 144 | H27: 169 | I27: 164 | J27: 139 | K27: 113
... A31: Dividend Amount | B31: 265.5 | C31: 301.2 | D31: 358.05 | E31: 836.4 | F31: 3776.04 | G31: 1349.24 | H31: 1737 | I31: 1771.22 | J31: 1807.74 | K31: 2181.82
A32: EBITDA | B32: =SUM(B26:B28) -> 1428 | C32: =SUM(C26:C28) -> 1668 | D32: =SUM(D26:D28) -> 1939 | E32: =SUM(E26:E28) -> 2106 | F32: =SUM(F26:F28) -> 2823 | G32: =SUM(G26:G28) -> 2423 | H32: =SUM(H26:H28) -> 3428 | I32: =SUM(I26:I28) -> 3377 | ... K32: =SUM(K26:K28) -> 3739
A40: Quarters
A41: Report Date | B41: 45352 | C41: 45444 | D41: 45536 | E41: 45627 | F41: 45717 | G41: 45809 | H41: 45901 | I41: 45992 | J41: 46082 | K41: 46174
A42: Sales | B42: 4069 | C42: 4250 | D42: 4668 | E42: 4593 | F42: 4432 | G42: 4622 | H42: 4841 | I42: 4970 | J42: 4719 | K42: 5000
A43: Expenses | B43: 3286 | C43: 3497 | D43: 3888 | E43: 3750 | F43: 3632 | G43: 3870 | H43: 3889 | I43: 3992 | J43: 3885 | K43: 4162
A44: Other Income | B44: 57 | C44: 31 | D44: 46 | E44: 62 | F44: 63 | G44: 57 | H44: 52 | I44: 59 | J44: 55 | K44: 61
A45: Depreciation | B45: 80 | C45: 74 | D45: 76 | E45: 82 | F45: 81 | G45: 82 | H45: 85 | I45: 85 | J45: 85 | K45: 80
A46: Interest | B46: 26 | C46: 29 | D46: 35 | E46: 45 | F46: 31 | G46: 26 | H46: 35 | I46: 33 | J46: 19 | K46: 23
A47: Profit before tax | B47: 735 | C47: 681 | D47: 715 | E47: 778 | F47: 752 | G47: 701 | H47: 884 | I47: 919 | J47: 785 | K47: 797
A48: Tax | B48: 198 | C48: 176 | D48: 183 | E48: 196 | F48: 193 | G48: 181 | H48: 229 | I48: 237 | J48: 105 | K48: 204
A49: Net profit | B49: 537 | C49: 505 | D49: 532 | E49: 582 | F49: 559 | G49: 520 | H49: 655 | I49: 682 | J49: 680 | K49: 593
A50: Operating Profit | B50: 784 | C50: 753 | D50: 780 | E50: 843 | F50: 801 | G50: 752 | H50: 951 | I50: 977 | J50: 834 | K50: 838
A55: BALANCE SHEET
A56: Report Date | B56: 42795 | C56: 43160 | D56: 43525 | E56: 43891 | F56: 44256 | G56: 44621 | H56: 44986 | I56: 45352 | J56: 45717 | K56: 46082
A57: Equity Share Capital | B57: 24 | C57: 24 | D57: 24 | E57: 24 | F57: 24 | G57: 24 | H57: 24 | I57: 24 | J57: 24 | K57: 24
A58: Reserves | B58: 2672 | C58: 3382 | D58: 4229 | E58: 4379 | F58: 3524 | G58: 2534 | H58: 3510 | I58: 3917 | J58: 4332 | K58: 5082
A59: Borrowings | B59: 125 | C59: 201 | D59: 156 | E59: 1538 | F59: 2107 | G59: 2481 | H59: 2997 | I59: 2065 | J59: 1247 | K59: 1380
A60: Other Liabilities | B60: 1288 | C60: 1581 | D60: 1829 | E60: 1889 | F60: 2345 | G60: 2487 | H60: 2819 | I60: 3065 | J60: 3235 | K60: 3243
...

Sheet Cash Flow Statement
B2: Cash Flow Statement - BRITANNIA INDUSTRIES LTD
B4: Particulars | C4: 42064 | D4: 42430 | E4: 42795 | F4: 43160 | G4: 43525 | H4: 43891 | I4: 44256 | J4: 44621 | K4: 44986 | L4: 45352 | M4: 45717 | N4: 46082
B6: Cash from Operating Activity - | C6: 584 | D6: 959 | E6: 441 | F6: 1249 | G6: 1156 | H6: 1485 | I6: 1851 | J6: 1300 | K6: 2526 | L6: 2573 | M6: 2491 | N6: 2612
B7: Profit from operations | C7: 861 | D7: 1230 | E7: 1289 | F7: 1517 | G7: 1754 | H7: 1860 | I7: 2540 | J7: 2214 | K7: 2846 | L7: 3177 | M7: 3174 | N7: 3555
B8: Receivables | C8: -25 | D8: -32 | E8: -9 | F8: -125 | G8: -87 | H8: 79 | I8: 61 | J8: -72 | K8: 1 | L8: -64 | M8: -53 | N8: -13
B9: Inventory | C9: 17 | D9: -35 | E9: -221 | F9: 9 | G9: -127 | H9: 43 | I9: -351 | J9: -275 | K9: 177 | L9: 13 | M9: -54 | N9: -105
B10: Payables | C10: 0 | D10: 0 | E10: 0 | F10: 0 | G10: 0 | H10: 0 | I10: 0 | J10: 64 | K10: 292 | L10: 237 | M10: 202 | N10: 25
B11: Working capital changes | C11: 25 | D11: 133 | E11: -451 | F11: 228 | G11: -2 | H11: 127 | I11: -56 | J11: -327 | K11: 406 | L11: 161 | M11: 6 | N11: -121
B12: Direct taxes | C12: -301 | D12: -403 | E12: -397 | F12: -496 | G12: -596 | H12: -503 | I12: -633 | J12: -587 | K12: -726 | L12: -765 | M12: -689 | N12: -822
B13: Cash from Investing Activity - | C13: -450 | D13: -705 | E13: -150 | F13: -957 | G13: -852 | H13: -1526 | I13: 459 | J13: 914 | K13: -1507 | L13: 485 | M13: 69 | N13: -741
B14: Fixed assets purchased | C14: -118 | D14: -251 | E14: -360 | F14: -423 | G14: -401 | H14: -244 | I14: -242 | J14: -550 | K14: -711 | L14: -553 | M14: -375 | N14: -206
B15: Fixed assets sold | C15: 164 | D15: 1 | E15: 8 | F15: 2 | G15: 2 | H15: 1 | I15: 2 | J15: 3 | K15: 78 | L15: 65 | M15: 5 | N15: 2
B16: Investments purchased | C16: -277 | D16: -211 | E16: 0 | F16: -537 | G16: -334 | H16: -1327 | I16: 0 | J16: -21 | K16: -1468 | L16: -191 | M16: -945 | N16: -976
... B32: Net Cash Flow | C32: -47 | D32: 8 | E32: -4 | F32: 60 | G32: -49 | H32: 17 | I32: 66 | J32: -32 | K32: -9 | L32: 219 | M32: -194 | N32: 88

Sheet Historical FS
B2: ="Historical Financial Statement - "&'Data Sheet'!$B$1 -> Historical Financial Statement - BRITANNIA INDUSTRIES LTD
B3: Particulars | C3: ='Data Sheet'!B56 -> 42795 | D3: ='Data Sheet'!C56 -> 43160 | E3: ='Data Sheet'!D56 -> 43525 | F3: ='Data Sheet'!E56 -> 43891 | G3: ='Data Sheet'!F56 -> 44256 | H3: ='Data Sheet'!G56 -> 44621 | I3: ='Data Sheet'!H56 -> 44986 | J3: ='Data Sheet'!I56 -> 45352 | ... L3: ='Data Sheet'!K56 -> 46082 | M3: LTM
A5: # | B5: Income Statement
B7: Sales | C7: ='Data Sheet'!B17 -> 9054 | D7: ='Data Sheet'!C17 -> 9914 | E7: ='Data Sheet'!D17 -> 11055 | F7: ='Data Sheet'!E17 -> 11600 | G7: ='Data Sheet'!F17 -> 13136 | H7: ='Data Sheet'!G17 -> 14136 | I7: ='Data Sheet'!H17 -> 16301 | J7: ='Data Sheet'!I17 -> 16769 | ... L7: ='Data Sheet'!K17 -> 19152
B8: Sales Growth | C8: - | D8: =D7/C7-1 -> 0.094985642 | E8: =E7/D7-1 -> 0.11508977 | F8: =F7/E7-1 -> 0.04929896 | G8: =G7/F7-1 -> 0.13241379 | H8: =H7/G7-1 -> 0.076126675 | I8: =I7/H7-1 -> 0.15315507 | J8: =J7/I7-1 -> 0.028709895 | K8: =K7/J7-1 -> 0.070010138 | L8: =L7/K7-1 -> 0.067380037
B10: Cost of Goods Sold | C10: =SUM('Data Sheet'!B18,'Data Sheet'!B20:B22)-'Data Sheet'!B19 -> 6692.94 | D10: =SUM('Data Sheet'!C18,'Data Sheet'!C20:C22)-'Data Sheet'!C19 -> 7086.4 | E10: =SUM('Data Sheet'!D18,'Data Sheet'!D20:D22)-'Data Sheet'!D19 -> 7888.05 | F10: =SUM('Data Sheet'!E18,'Data Sheet'!E20:E22)-'Data Sheet'!E19 -> 8098 | G10: =SUM('Data Sheet'!F18,'Data Sheet'!F20:F22)-'Data Sheet'!F19 -> 9013.6 | H10: =SUM('Data Sheet'!G18,'Data Sheet'!G20:G22)-'Data Sheet'!G19 -> 10465.96 | I10: =SUM('Data Sheet'!H18,'Data Sheet'!H20:H22)-'Data Sheet'!H19 -> 11530.11 | J10: =SUM('Data Sheet'!I18,'Data Sheet'!I20:I22)-'Data Sheet'!I19 -> 11328.59 | ... L10: =SUM('Data Sheet'!K18,'Data Sheet'!K20:K22)-'Data Sheet'!K19 -> 13283.72
B11: COGS % Sales | C11: =C10/C7 -> 0.73922465 | D11: =D10/D7 -> 0.71478717 | E11: =E10/E7 -> 0.71352782 | F11: =F10/F7 -> 0.69810345 | G11: =G10/G7 -> 0.6861754 | H11: =H10/H7 -> 0.74037634 | I11: =I10/I7 -> 0.70732532 | J11: =J10/J7 -> 0.67556742 | ... L11: =L10/L7 -> 0.6935944
B13: Gross Profit | C13: =C7-C10 -> 2361.06 | D13: =D7-D10 -> 2827.6 | E13: =E7-E10 -> 3166.95 | F13: =F7-F10 -> 3502 | G13: =G7-G10 -> 4122.4 | H13: =H7-H10 -> 3670.04 | I13: =I7-I10 -> 4770.89 | J13: =J7-J10 -> 5440.41 | ... L13: =L7-L10 -> 5868.28
B14: Gross Profit % Sales | C14: =C13/C7 -> 0.26077535 | D14: =D13/D7 -> 0.28521283 | E14: =E13/E7 -> 0.28647218 | F14: =F13/F7 -> 0.30189655 | G14: =G13/G7 -> 0.3138246 | H14: =H13/H7 -> 0.25962366 | I14: =I13/I7 -> 0.29267468 | J14: =J13/J7 -> 0.32443258 | ... L14: =L13/L7 -> 0.3064056
B16: Selling % General Expenses | C16: ='Data Sheet'!B23+'Data Sheet'!B24 -> 1177.02 | D16: ='Data Sheet'!C23+'Data Sheet'!C24 -> 1288.82 | E16: ='Data Sheet'!D23+'Data Sheet'!D24 -> 1547.7 | F16: ='Data Sheet'!E23+'Data Sheet'!E24 -> 1508 | G16: ='Data Sheet'!F23+'Data Sheet'!F24 -> 1576.32 | H16: ='Data Sheet'!G23+'Data Sheet'!G24 -> 1696.32 | I16: ='Data Sheet'!H23+'Data Sheet'!H24 -> 2119.13 | J16: ='Data Sheet'!I23+'Data Sheet'!I24 -> 2179.97 | ... O16: ='Data Sheet'!N23+'Data Sheet'!N24 -> 0
B17: S&G % Sales | C17: =C16/C7 -> 0.13 | D17: =D16/D7 -> 0.13 | E17: =E16/E7 -> 0.14 | F17: =F16/F7 -> 0.13 | G17: =G16/G7 -> 0.12 | H17: =H16/H7 -> 0.12 | I17: =I16/I7 -> 0.13 | J17: =J16/J7 -> 0.13 | ... L17: =L16/L7 -> 0.13
B19: EBITDA | C19: =C13-C16 -> 1184.04 | D19: =D13-D16 -> 1538.78 | E19: =E13-E16 -> 1619.25 | F19: =F13-F16 -> 1994 | G19: =G13-G16 -> 2546.08 | H19: =H13-H16 -> 1973.72 | I19: =I13-I16 -> 2651.76 | J19: =J13-J16 -> 3260.44 | ... L19: =L13-L16 -> 3378.52
B20: EBITDA % Sales | C20: =C19/C7 -> 0.13077535 | D20: =D19/D7 -> 0.15521283 | E20: =E19/E7 -> 0.14647218 | F20: =F19/F7 -> 0.17189655 | G20: =G19/G7 -> 0.1938246 | H20: =H19/H7 -> 0.13962366 | I20: =I19/I7 -> 0.16267468 | J20: =J19/J7 -> 0.19443258 | ... L20: =L19/L7 -> 0.1764056
B22: Depreciation | C22: ='Data Sheet'!B26 -> 119 | D22: ='Data Sheet'!C26 -> 142 | E22: ='Data Sheet'!D26 -> 162 | F22: ='Data Sheet'!E26 -> 185 | G22: ='Data Sheet'!F26 -> 198 | H22: ='Data Sheet'!G26 -> 201 | I22: ='Data Sheet'!H26 -> 226 | J22: ='Data Sheet'!I26 -> 300 | ... L22: ='Data Sheet'!K26 -> 337
B23: Depreciation % Sales | C23: =C22/C7 -> 0.013143362 | D23: =D22/D7 -> 0.014323179 | E23: =E22/E7 -> 0.014654003 | F23: =F22/F7 -> 0.015948276 | G23: =G22/G7 -> 0.015073082 | H23: =H22/H7 -> 0.014219015 | I23: =I22/I7 -> 0.01386418 | J23: =J22/J7 -> 0.017890154 | ... L23: =L22/L7 -> 0.017596074
B25: EBIT | C25: =C19-C22 -> 1065.04 | D25: =D19-D22 -> 1396.78 | E25: =E19-E22 -> 1457.25 | F25: =F19-F22 -> 1809 | G25: =G19-G22 -> 2348.08 | H25: =H19-H22 -> 1772.72 | I25: =I19-I22 -> 2425.76 | J25: =J19-J22 -> 2960.44 | ... L25: =L19-L22 -> 3041.52
B26: EBIT % Sales | C26: =C25/C7 -> 0.11763199 | D26: =D25/D7 -> 0.14088965 | E26: =E25/E7 -> 0.13181818 | F26: =F25/F7 -> 0.15594828 | G26: =G25/G7 -> 0.17875152 | H26: =H25/H7 -> 0.12540464 | I26: =I25/I7 -> 0.1488105 | J26: =J25/J7 -> 0.17654243 | ... L26: =L25/L7 -> 0.15880952
B28: Interest | C28: ='Data Sheet'!B27 -> 5 | D28: ='Data Sheet'!C27 -> 8 | E28: ='Data Sheet'!D27 -> 9 | F28: ='Data Sheet'!E27 -> 77 | G28: ='Data Sheet'!F27 -> 111 | H28: ='Data Sheet'!G27 -> 144 | I28: ='Data Sheet'!H27 -> 169 | J28: ='Data Sheet'!I27 -> 164 | ... L28: ='Data Sheet'!K27 -> 113
B29: Interest % Sales | C29: =C28/C7 -> 0.0005522421 | D29: =D28/D7 -> 0.00080693968 | E29: =E28/E7 -> 0.00081411126 | F29: =F28/F7 -> 0.006637931 | G29: =G28/G7 -> 0.0084500609 | H29: =H28/H7 -> 0.010186757 | I29: =I28/I7 -> 0.010367462 | J29: =J28/J7 -> 0.0097799511 | ... L29: =L28/L7 -> 0.0059001671
B31: Earning Before Tax | C31: =C25-C28 -> 1060.04 | D31: =D25-D28 -> 1388.78 | E31: =E25-E28 -> 1448.25 | F31: =F25-F28 -> 1732 | G31: =G25-G28 -> 2237.08 | H31: =H25-H28 -> 1628.72 | I31: =I25-I28 -> 2256.76 | J31: =J25-J28 -> 2796.44 | ... L31: =L25-L28 -> 2928.52
B32: EBT % Sales | C32: =C31/C7 -> 0.11707974 | D32: =D31/D7 -> 0.14008271 | E32: =E31/E7 -> 0.13100407 | F32: =F31/F7 -> 0.14931034 | G32: =G31/G7 -> 0.17030146 | H32: =H31/H7 -> 0.11521788 | I32: =I31/I7 -> 0.13844304 | J32: =J31/J7 -> 0.16676248 | ... L32: =L31/L7 -> 0.15290936
B34: Tax Rate | C34: ='Data Sheet'!B29 -> 419 | D34: ='Data Sheet'!C29 -> 514 | E34: ='Data Sheet'!D29 -> 613 | F34: ='Data Sheet'!E29 -> 450 | G34: ='Data Sheet'!F29 -> 663 | H34: ='Data Sheet'!G29 -> 562 | I34: ='Data Sheet'!H29 -> 717 | J34: ='Data Sheet'!I29 -> 779 | ... L34: ='Data Sheet'!K29 -> 752
B35: Effective Tax Rate | C35: =C34/C31 -> 0.3952681 | D35: =D34/D31 -> 0.37010902 | E35: =E34/E31 -> 0.42326946 | F35: =F34/F31 -> 0.25981524 | G35: =G34/G31 -> 0.29636848 | H35: =H34/H31 -> 0.34505624 | I35: =I34/I31 -> 0.31771212 | J35: =J34/J31 -> 0.27856847 | ... L35: =L34/L31 -> 0.256785
B37: Net Profit | C37: =C31-C34 -> 641.04 | D37: =D31-D34 -> 874.78 | E37: =E31-E34 -> 835.25 | F37: =F31-F34 -> 1282 | G37: =G31-G34 -> 1574.08 | H37: =H31-H34 -> 1066.72 | I37: =I31-I34 -> 1539.76 | J37: =J31-J34 -> 2017.44 | ... L37: =L31-L34 -> 2176.52
B38: Net Profit % Sales | C38: =C37/C7 -> 0.070801856 | D38: =D37/D7 -> 0.088236837 | E38: =E37/E7 -> 0.075554048 | F38: =F37/F7 -> 0.11051724 | G38: =G37/G7 -> 0.11982948 | H38: =H37/H7 -> 0.075461234 | I38: =I37/I7 -> 0.094458009 | J38: =J37/J7 -> 0.12030771 | ... L38: =L37/L7 -> 0.11364453
B40: No. of Equity Shares | C40: ='Data Sheet'!B93 -> 24 | D40: ='Data Sheet'!C93 -> 24 | E40: ='Data Sheet'!D93 -> 24 | F40: ='Data Sheet'!E93 -> 24 | G40: ='Data Sheet'!F93 -> 24 | H40: ='Data Sheet'!G93 -> 24 | I40: ='Data Sheet'!H93 -> 24 | J40: ='Data Sheet'!I93 -> 24 | ... L40: ='Data Sheet'!K93 -> 24
B42: Earning per Share | C42: =C37/C40 -> 26.71 | D42: =D37/D40 -> 36.449167 | E42: =E37/E40 -> 34.802083 | F42: =F37/F40 -> 53.416667 | G42: =G37/G40 -> 65.586667 | H42: =H37/H40 -> 44.446667 | I42: =I37/I40 -> 64.156667 | J42: =J37/J40 -> 84.06 | ... L42: =L37/L40 -> 90.688333
B43: EPS Growth | C43: - | D43: =D42/C42-1 -> 0.36462623 | E43: =E42/D42-1 -> -0.045188505 | F43: =F42/E42-1 -> 0.5348698 | G43: =G42/F42-1 -> 0.22783151 | H43: =H42/G42-1 -> -0.32232161 | I43: =I42/H42-1 -> 0.44345283 | J43: =J42/I42-1 -> 0.31023017 | K43: =K42/J42-1 -> -0.06757574 | L43: =L42/K42-1 -> 0.15704026
B45: Dividend per Share | C45: ='Data Sheet'!B31/'Historical FS'!C40 -> 11.0625 | D45: ='Data Sheet'!C31/'Historical FS'!D40 -> 12.55 | E45: ='Data Sheet'!D31/'Historical FS'!E40 -> 14.91875 | F45: ='Data Sheet'!E31/'Historical FS'!F40 -> 34.85 | G45: ='Data Sheet'!F31/'Historical FS'!G40 -> 157.335 | H45: ='Data Sheet'!G31/'Historical FS'!H40 -> 56.218333 | I45: ='Data Sheet'!H31/'Historical FS'!I40 -> 72.375 | J45: ='Data Sheet'!I31/'Historical FS'!J40 -> 73.800833 | ... L45: ='Data Sheet'!K31/'Historical FS'!L40 -> 90.909167
B46: Dividend Payout Ratio | C46: =C45/C42 -> 0.41417072 | D46: =D45/D42 -> 0.34431514 | E46: =E45/E42 -> 0.42867405 | F46: =F45/F42 -> 0.6524181 | G46: =G45/G42 -> 2.398887 | H46: =H45/H42 -> 1.2648493 | I46: =I45/I42 -> 1.1280979 | J46: =J45/J42 -> 0.87795424 | ... L46: =L45/L42 -> 1.0024351
B48: Retained Earnings | C48: =(1-C46) -> 0.58582928 | D48: =(1-D46) -> 0.65568486 | E48: =(1-E46) -> 0.57132595 | F48: =(1-F46) -> 0.3475819 | G48: =(1-G46) -> -1.398887 | H48: =(1-H46) -> -0.26484926 | I48: =(1-I46) -> -0.12809789 | J48: =(1-J46) -> 0.12204576 | ... L48: =(1-L46) -> -0.0024350799
B50: Balance Sheet
B51: ='Data Sheet'!A57 -> Equity Share Capital | C51: ='Data Sheet'!B57 -> 24 | D51: ='Data Sheet'!C57 -> 24 | E51: ='Data Sheet'!D57 -> 24 | F51: ='Data Sheet'!E57 -> 24 | G51: ='Data Sheet'!F57 -> 24 | H51: ='Data Sheet'!G57 -> 24 | I51: ='Data Sheet'!H57 -> 24 | ... L51: ='Data Sheet'!K57 -> 24
B52: ='Data Sheet'!A58 -> Reserves | C52: ='Data Sheet'!B58 -> 2672 | D52: ='Data Sheet'!C58 -> 3382 | E52: ='Data Sheet'!D58 -> 4229 | F52: ='Data Sheet'!E58 -> 4379 | G52: ='Data Sheet'!F58 -> 3524 | H52: ='Data Sheet'!G58 -> 2534 | I52: ='Data Sheet'!H58 -> 3510 | ... L52: ='Data Sheet'!K58 -> 5082
B53: ='Data Sheet'!A59 -> Borrowings | C53: ='Data Sheet'!B59 -> 125 | D53: ='Data Sheet'!C59 -> 201 | E53: ='Data Sheet'!D59 -> 156 | F53: ='Data Sheet'!E59 -> 1538 | G53: ='Data Sheet'!F59 -> 2107 | H53: ='Data Sheet'!G59 -> 2481 | I53: ='Data Sheet'!H59 -> 2997 | ... L53: ='Data Sheet'!K59 -> 1380
B54: ='Data Sheet'!A60 -> Other Liabilities | C54: ='Data Sheet'!B60 -> 1288 | D54: ='Data Sheet'!C60 -> 1581 | E54: ='Data Sheet'!D60 -> 1829 | F54: ='Data Sheet'!E60 -> 1889 | G54: ='Data Sheet'!F60 -> 2345 | H54: ='Data Sheet'!G60 -> 2487 | I54: ='Data Sheet'!H60 -> 2819 | ... L54: ='Data Sheet'!K60 -> 3243
B55: Total Liabilities | C55: =SUM(C51:C54) -> 4109 | D55: =SUM(D51:D54) -> 5188 | E55: =SUM(E51:E54) -> 6238 | F55: =SUM(F51:F54) -> 7830 | G55: =SUM(G51:G54) -> 8000 | H55: =SUM(H51:H54) -> 7526 | I55: =SUM(I51:I54) -> 9350 | J55: =SUM(J51:J54) -> 9071 | ... L55: =SUM(L51:L54) -> 9729
B57: Fixed Asset Net Block | C57: ='Data Sheet'!B62 -> 1160 | D57: ='Data Sheet'!C62 -> 1346 | E57: ='Data Sheet'!D62 -> 1688 | F57: ='Data Sheet'!E62 -> 1878 | G57: ='Data Sheet'!F62 -> 1793 | H57: ='Data Sheet'!G62 -> 1753 | I57: ='Data Sheet'!H62 -> 2655 | J57: ='Data Sheet'!I62 -> 2771 | ... L57: ='Data Sheet'!K62 -> 2850
B58: ='Data Sheet'!A63 -> Capital Work in Progress | C58: ='Data Sheet'!B63 -> 30 | D58: ='Data Sheet'!C63 -> 203 | E58: ='Data Sheet'!D63 -> 101 | F58: ='Data Sheet'!E63 -> 40 | G58: ='Data Sheet'!F63 -> 117 | H58: ='Data Sheet'!G63 -> 536 | I58: ='Data Sheet'!H63 -> 105 | ... L58: ='Data Sheet'!K63 -> 39
B59: ='Data Sheet'!A64 -> Investments | C59: ='Data Sheet'!B64 -> 487 | D59: ='Data Sheet'!C64 -> 1079 | E59: ='Data Sheet'!D64 -> 1476 | F59: ='Data Sheet'!E64 -> 2893 | G59: ='Data Sheet'!F64 -> 2781 | H59: ='Data Sheet'!G64 -> 1762 | I59: ='Data Sheet'!H64 -> 3324 | ... L59: ='Data Sheet'!K64 -> 3610
...

Sheet Ratio Analysis
B2: ="Ratio Analysis - "&'Data Sheet'!$B$1 -> Ratio Analysis - BRITANNIA INDUSTRIES LTD
B3: Years | C3: ='Data Sheet'!B56 -> 42795 | D3: ='Data Sheet'!C56 -> 43160 | E3: ='Data Sheet'!D56 -> 43525 | F3: ='Data Sheet'!E56 -> 43891 | G3: ='Data Sheet'!F56 -> 44256 | H3: ='Data Sheet'!G56 -> 44621 | I3: ='Data Sheet'!H56 -> 44986 | J3: ='Data Sheet'!I56 -> 45352 | ... L3: ='Data Sheet'!K56 -> 46082 | M3: Trend | N3: Mean | O3: Median
