Workbook
Name UPDATE: '[1]Data Sheet'!$E$1
Name UPDATE: 'Data Sheet'!$E$1

Sheet AI Valuation Summary
A1: Infosys Ltd (INFY) - Institutional Valuation
A4: Current Price | B4: Intrinsic Value | C4: Margin of Safety | D4: Verdict | E4: WACC | F4: Altman Z-Score | G4: DuPont ROE
A5: =DCF!D44 -> 1051 | B5: =DCF!D42 -> 711.71706 | C5: =(B5-A5)/A5 -> -0.32281917 | D5: =IF(C5>0.15,"UNDERVALUED / BUY",IF(C5<-0.15,"OVERVALUED / SELL","FAIRLY VALUED / HOLD")) -> OVERVALUED / SELL | E5: =DCF!D20 -> 0.12035248 | F5: ='Altman''s Z Score'!I89 -> 9.0746518 | G5: ='Dupont Analysis'!I78 -> 0.32146075
A7: THE 4 CORE VALUATION PILLARS
A8: Pillar 1: FCF Engine | B8: CFO ₹33986.0 Cr vs PAT ₹29474.0 Cr | EBIT Mgn 22.62% | CCC 72.0 days
A9: Pillar 2: Growth Trajectory | B9: 3Y Sales CAGR 6.3% | 5Y CAGR 8.7% | Forecast g 5.2% | Terminal g 4.0%
A10: Pillar 3: Cost of Capital (WACC) | B10: WACC 13.33% | Ke 12.73% | Beta 0.88 | ERP 6.5% | Rf 7.0%
A11: Pillar 4: Relative Multiples | B11: P/E 13.7x | P/B 4.67x | EV/EBITDA 5.9x | EV/Sales 1.39x
A13: 5-Year Discounted Cash Flow (DCF) Schedule (Amounts in ₹ Cr)
A14: Year | B14: EBIT | C14: NOPAT | D14: Reinvest Rate | E14: FCFF | F14: Discount Factor | G14: PV of FCFF
A15: Year 1 | B15: =DCF!I8 -> 42512.372 | C15: =DCF!I10 -> 29758.66 | D15: =DCF!I11 -> 0.28501193 | E15: =DCF!I12 -> 21277.087 | F15: =DCF!I14 -> 0.94476253 | G15: =DCF!I16 -> 20101.795
A16: Year 2 | B16: =DCF!J8 -> 44723.015 | C16: =DCF!J10 -> 31306.111 | D16: =DCF!J11 -> 0.29684822 | E16: =DCF!J12 -> 22012.947 | F16: =DCF!J14 -> 0.84327259 | G16: =DCF!J16 -> 18562.915
A17: Year 3 | B17: =DCF!K8 -> 47048.612 | C17: =DCF!K10 -> 32934.028 | D17: =DCF!K11 -> 0.30868451 | E17: =DCF!K12 -> 22767.804 | F17: =DCF!K14 -> 0.75268507 | G17: =DCF!K16 -> 17136.986
A18: Year 4 | B18: =DCF!L8 -> 49495.14 | C18: =DCF!L10 -> 34646.598 | D18: =DCF!L11 -> 0.3205208 | E18: =DCF!L12 -> 23541.643 | F18: =DCF!L14 -> 0.67182881 | G18: =DCF!L16 -> 15815.954
A19: Year 5 | B19: =DCF!M8 -> 52068.887 | C19: =DCF!M10 -> 36448.221 | D19: =DCF!M11 -> 0.3323571 | E19: =DCF!M12 -> 24334.396 | F19: =DCF!M14 -> 0.59965843 | G19: =DCF!M16 -> 14592.326
A21: Enterprise to Equity Value Bridge
A22: PV of 5-Year FCFFs | B22: =DCF!D33 -> 86209.976
A23: Terminal Value | B23: =DCF!D29 -> 314959.45
A24: PV of Terminal Value | B24: =DCF!D34 -> 188868.09
A25: Enterprise Value (Operating Assets) | B25: =DCF!D35 -> 275078.06
A26: Add: Estimated Cash & Liquid Assets | B26: =DCF!D37 -> 22201
A27: Less: Total Debt & Borrowings | B27: =DCF!D38 -> 9176
A28: Net Equity Value | B28: =DCF!D39 -> 288103.06
A29: Shares Outstanding | B29: =DCF!D40 -> 404.8
A30: Intrinsic Value per Share | B30: =DCF!D42 -> 711.71706
A31: Current Market Price | B31: =DCF!D44 -> 1051
A32: Margin of Safety / Discount | B32: =(B5-A5)/A5 -> -0.32281917

Sheet Profit & Loss
A1: ='Data Sheet'!B1 -> Infosys Ltd | H1: =UPDATE | M1: SCREENER.IN
A3: Narration | B3: ='Data Sheet'!B16 -> 43160 | C3: ='Data Sheet'!C16 -> 43525 | D3: ='Data Sheet'!D16 -> 43891 | E3: ='Data Sheet'!E16 -> 44256 | F3: ='Data Sheet'!F16 -> 44621 | G3: ='Data Sheet'!G16 -> 44986 | H3: ='Data Sheet'!H16 -> 45352 | I3: ='Data Sheet'!I16 -> 45717 | ... K3: ='Data Sheet'!K16 -> TTM | L3: Trailing | M3: Best Case | N3: Worst Case
A4: Sales | B4: ='Data Sheet'!B17 -> 70522 | C4: ='Data Sheet'!C17 -> 82675 | D4: ='Data Sheet'!D17 -> 90791 | E4: ='Data Sheet'!E17 -> 100472 | F4: ='Data Sheet'!F17 -> 121641 | G4: ='Data Sheet'!G17 -> 146767 | H4: ='Data Sheet'!H17 -> 153670 | I4: ='Data Sheet'!I17 -> 162990 | ... K4: ='Data Sheet'!K17 -> 184582 | L4: =SUM(Quarters!H4:K4) -> 184582 | M4: =$K4+M23*K4 -> 196210.74 | N4: =$K4+N23*L4 -> 190710.97
A5: Expenses | B5: =SUM('Data Sheet'!B18,'Data Sheet'!B20:B24, -1*'Data Sheet'!B19) -> 52186.28 | C5: =SUM('Data Sheet'!C18,'Data Sheet'!C20:C24, -1*'Data Sheet'!C19) -> 62833 | D5: =SUM('Data Sheet'!D18,'Data Sheet'!D20:D24, -1*'Data Sheet'!D19) -> 68093.25 | E5: =SUM('Data Sheet'!E18,'Data Sheet'!E20:E24, -1*'Data Sheet'!E19) -> 72339.84 | F5: =SUM('Data Sheet'!F18,'Data Sheet'!F20:F24, -1*'Data Sheet'!F19) -> 90014.34 | G5: =SUM('Data Sheet'!G18,'Data Sheet'!G20:G24, -1*'Data Sheet'!G19) -> 111542.92 | H5: =SUM('Data Sheet'!H18,'Data Sheet'!H20:H24, -1*'Data Sheet'!H19) -> 118325.9 | I5: =SUM('Data Sheet'!I18,'Data Sheet'!I20:I24, -1*'Data Sheet'!I19) -> 123872.4 | ... K5: =SUM('Data Sheet'!K18,'Data Sheet'!K20:K24, -1*'Data Sheet'!K19) -> 0 | L5: =SUM(Quarters!H5:K5) -> 140837 | M5: =M4-M6 -> 97479.66 | N5: =N4-N6 -> 145513.43
A6: Operating Profit | B6: =B4-B5 -> 18335.72 | C6: =C4-C5 -> 19842 | D6: =D4-D5 -> 22697.75 | E6: =E4-E5 -> 28132.16 | F6: =F4-F5 -> 31626.66 | G6: =G4-G5 -> 35224.08 | H6: =H4-H5 -> 35344.1 | I6: =I4-I5 -> 39117.6 | ... K6: =K4-K5 -> 184582 | L6: =SUM(Quarters!H6:K6) -> 43745 | M6: =M4*M24 -> 98731.076 | N6: =N4*N24 -> 45197.535
A7: Other Income | B7: ='Data Sheet'!B25 -> 3311 | C7: ='Data Sheet'!C25 -> 2882 | D7: ='Data Sheet'!D25 -> 2803 | E7: ='Data Sheet'!E25 -> 2201 | F7: ='Data Sheet'!F25 -> 2295 | G7: ='Data Sheet'!G25 -> 2701 | H7: ='Data Sheet'!H25 -> 4711 | I7: ='Data Sheet'!I25 -> 3600 | ... K7: ='Data Sheet'!K25 -> 2975 | L7: =SUM(Quarters!H7:K7) -> 2975 | M7: 0 | N7: 0
A8: Depreciation | B8: ='Data Sheet'!B26 -> 1863 | C8: ='Data Sheet'!C26 -> 2011 | D8: ='Data Sheet'!D26 -> 2893 | E8: ='Data Sheet'!E26 -> 3267 | F8: ='Data Sheet'!F26 -> 3476 | G8: ='Data Sheet'!G26 -> 4225 | H8: ='Data Sheet'!H26 -> 4678 | I8: ='Data Sheet'!I26 -> 4812 | ... K8: ='Data Sheet'!K26 -> 5007 | L8: =SUM(Quarters!H8:K8) -> 5007 | M8: =+$L8 -> 5007 | N8: =+$L8 -> 5007
A9: Interest | B9: ='Data Sheet'!B27 -> 0 | C9: ='Data Sheet'!C27 -> 0 | D9: ='Data Sheet'!D27 -> 170 | E9: ='Data Sheet'!E27 -> 195 | F9: ='Data Sheet'!F27 -> 200 | G9: ='Data Sheet'!G27 -> 284 | H9: ='Data Sheet'!H27 -> 470 | I9: ='Data Sheet'!I27 -> 416 | ... K9: ='Data Sheet'!K27 -> 430 | L9: =SUM(Quarters!H9:K9) -> 430 | M9: =+$L9 -> 430 | N9: =+$L9 -> 430
A10: Profit before tax | B10: ='Data Sheet'!B28 -> 20270 | C10: ='Data Sheet'!C28 -> 21041 | D10: ='Data Sheet'!D28 -> 22007 | E10: ='Data Sheet'!E28 -> 26628 | F10: ='Data Sheet'!F28 -> 30110 | G10: ='Data Sheet'!G28 -> 33322 | H10: ='Data Sheet'!H28 -> 35988 | I10: ='Data Sheet'!I28 -> 37608 | ... K10: ='Data Sheet'!K28 -> 41283 | L10: =SUM(Quarters!H10:K10) -> 41283 | M10: =M6+M7-SUM(M8:M9) -> 93294.076 | N10: =N6+N7-SUM(N8:N9) -> 39760.535
A11: Tax | B11: ='Data Sheet'!B29 -> 20270 | C11: ='Data Sheet'!C29 -> 21041 | D11: ='Data Sheet'!D29 -> 22007 | E11: ='Data Sheet'!E29 -> 26628 | F11: ='Data Sheet'!F29 -> 30110 | G11: ='Data Sheet'!G29 -> 33322 | H11: ='Data Sheet'!H29 -> 35988 | I11: ='Data Sheet'!I29 -> 37608 | ... K11: ='Data Sheet'!K29 -> 41283 | L11: =SUM(Quarters!H11:K11) -> 41283 | M11: =IF($L10>0,$L11/$L10,0) -> 1 | N11: =IF($L10>0,$L11/$L10,0) -> 1
A12: Net profit | B12: ='Data Sheet'!B30 -> 16029 | C12: ='Data Sheet'!C30 -> 15410 | D12: ='Data Sheet'!D30 -> 16639 | E12: ='Data Sheet'!E30 -> 19423 | F12: ='Data Sheet'!F30 -> 22146 | G12: ='Data Sheet'!G30 -> 24108 | H12: ='Data Sheet'!H30 -> 26248 | I12: ='Data Sheet'!I30 -> 26750 | ... K12: ='Data Sheet'!K30 -> 30325 | L12: =SUM(Quarters!H12:K12) -> 30325 | M12: =M10-M11*M10 -> 0 | N12: =N10-N11*N10 -> 0
A13: EPS | B13: =IF('Data Sheet'!B93>0,B12/'Data Sheet'!B93,0) -> 34.890403 | C13: =IF('Data Sheet'!C93>0,C12/'Data Sheet'!C93,0) -> 33.543023 | D13: =IF('Data Sheet'!D93>0,D12/'Data Sheet'!D93,0) -> 36.218193 | E13: =IF('Data Sheet'!E93>0,E12/'Data Sheet'!E93,0) -> 42.278139 | F13: =IF('Data Sheet'!F93>0,F12/'Data Sheet'!F93,0) -> 48.205307 | G13: =IF('Data Sheet'!G93>0,G12/'Data Sheet'!G93,0) -> 52.476002 | H13: =IF('Data Sheet'!H93>0,H12/'Data Sheet'!H93,0) -> 57.13415 | I13: =IF('Data Sheet'!I93>0,I12/'Data Sheet'!I93,0) -> 58.226856 | ... K13: =IF('Data Sheet'!K93>0,K12/'Data Sheet'!K93,0) -> 66.008576 | L13: =IF('Data Sheet'!$B6>0,'Profit & Loss'!L12/'Data Sheet'!$B6,0) -> 74.696144 | M13: =IF('Data Sheet'!$B6>0,'Profit & Loss'!M12/'Data Sheet'!$B6,0) -> 0 | N13: =IF('Data Sheet'!$B6>0,'Profit & Loss'!N12/'Data Sheet'!$B6,0) -> 0
A14: Price to earning | B14: =IF(B15>0,B15/B13,"") -> 14.777703 | C14: =IF(C15>0,C15/C13,"") -> 17.302555 | D14: =IF(D15>0,D15/D13,"") -> 20.48418 | E14: =IF(E15>0,E15/E13,"") -> 17.306817 | F14: =IF(F15>0,F15/F13,"") -> 25.999212 | G14: =IF(G15>0,G15/G13,"") -> 32.839773 | H14: =IF(H15>0,H15/H13,"") -> 25.891695 | I14: =IF(I15>0,I15/I13,"") -> 28.445637 | ... K14: =IF(K15>0,K15/K13,"") -> 19.695926 | L14: =IF(L13>0,L15/L13,0) -> 14.070338 | M14: =M25 -> 22.129502 | N14: =N25 -> 14.070338
A15: Price | B15: ='Data Sheet'!B90 -> 515.6 | C15: ='Data Sheet'!C90 -> 580.38 | D15: ='Data Sheet'!D90 -> 741.9 | E15: ='Data Sheet'!E90 -> 731.7 | F15: ='Data Sheet'!F90 -> 1253.3 | G15: ='Data Sheet'!G90 -> 1723.3 | H15: ='Data Sheet'!H90 -> 1479.3 | I15: ='Data Sheet'!I90 -> 1656.3 | ... K15: ='Data Sheet'!K90 -> 1300.1 | L15: ='Data Sheet'!B8 -> 1051 | M15: =M13*M14 -> 0 | N15: =N13*N14 -> 0
A17: RATIOS:
A18: Dividend Payout | B18: =IF('Data Sheet'!B30>0, 'Data Sheet'!B31/'Data Sheet'!B30, 0) -> 0.59 | C18: =IF('Data Sheet'!C30>0, 'Data Sheet'!C31/'Data Sheet'!C30, 0) -> 0.6 | D18: =IF('Data Sheet'!D30>0, 'Data Sheet'!D31/'Data Sheet'!D30, 0) -> 0.45 | E18: =IF('Data Sheet'!E30>0, 'Data Sheet'!E31/'Data Sheet'!E30, 0) -> 0.59 | F18: =IF('Data Sheet'!F30>0, 'Data Sheet'!F31/'Data Sheet'!F30, 0) -> 0.59 | G18: =IF('Data Sheet'!G30>0, 'Data Sheet'!G31/'Data Sheet'!G30, 0) -> 0.58 | H18: =IF('Data Sheet'!H30>0, 'Data Sheet'!H31/'Data Sheet'!H30, 0) -> 0.73 | I18: =IF('Data Sheet'!I30>0, 'Data Sheet'!I31/'Data Sheet'!I30, 0) -> 0.67 | ... K18: =IF('Data Sheet'!K30>0, 'Data Sheet'!K31/'Data Sheet'!K30, 0) -> 0
A19: OPM | B19: =IF(B6>0,B6/B4,0) -> 0.26 | C19: =IF(C6>0,C6/C4,0) -> 0.24 | D19: =IF(D6>0,D6/D4,0) -> 0.25 | E19: =IF(E6>0,E6/E4,0) -> 0.28 | F19: =IF(F6>0,F6/F4,0) -> 0.26 | G19: =IF(G6>0,G6/G4,0) -> 0.24 | H19: =IF(H6>0,H6/H4,0) -> 0.23 | I19: =IF(I6>0,I6/I4,0) -> 0.24 | ... L19: =IF(L6>0,L6/L4,0) -> 0.23699494
G22: TRENDS: | H22: 10 YEARS | I22: 7 YEARS | J22: 5 YEARS | K22: 3 YEARS | L22: RECENT | M22: BEST | N22: WORST
G23: Sales Growth | H23: =IF(B4=0,"",POWER($K4/B4,1/9)-1) -> 0.11283151 | I23: =IF(D4=0,"",POWER($K4/D4,1/7)-1) -> 0.10667713 | J23: =IF(F4=0,"",POWER($K4/F4,1/5)-1) -> 0.0869808 | K23: =IF(H4=0,"",POWER($K4/H4, 1/3)-1) -> 0.063000377 | L23: =IF(ISERROR(MAX(IF(J4=0,"",(K4-J4)/J4),IF(K4=0,"",(L4-K4)/K4))),"",MAX(IF(J4=0,"",(K4-J4)/J4),IF(K4=0,"",(L4-K4)/K4))) -> 0.03320459 | M23: =MAX(K23:L23) -> 0.063000377 | N23: =MIN(H23:L23) -> 0.03320459
G24: OPM | H24: =IF(SUM(B4:$K$4)=0,"",SUMPRODUCT(B19:$K$19,B4:$K$4)/SUM(B4:$K$4)) -> 0.35272717 | I24: =IF(SUM(E4:$K$4)=0,"",SUMPRODUCT(E19:$K$19,E4:$K$4)/SUM(E4:$K$4)) -> 0.37674166 | J24: =IF(SUM(G4:$K$4)=0,"",SUMPRODUCT(G19:$K$19,G4:$K$4)/SUM(G4:$K$4)) -> 0.40567789 | K24: =IF(SUM(I4:$K$4)=0, "", SUMPRODUCT(I19:$K$19,I4:$K$4)/SUM(I4:$K$4)) -> 0.50318896 | L24: =L19 -> 0.23699494 | M24: =MAX(K24:L24) -> 0.50318896 | N24: =MIN(H24:L24) -> 0.23699494
G25: Price to Earning | H25: =IF(ISERROR(AVERAGEIF(B14:$L14,">0")),"",AVERAGEIF(B14:$L14,">0")) -> 22.101813 | I25: =IF(ISERROR(AVERAGEIF(E14:$L14,">0")),"",AVERAGEIF(E14:$L14,">0")) -> 23.819438 | J25: =IF(ISERROR(AVERAGEIF(G14:$L14,">0")),"",AVERAGEIF(G14:$L14,">0")) -> 24.54158 | K25: =IF(ISERROR(AVERAGEIF(I14:$L14,">0")),"",AVERAGEIF(I14:$L14,">0")) -> 22.129502 | L25: =L14 -> 14.070338 | M25: =MAX(K25:L25) -> 22.129502 | N25: =MIN(H25:L25) -> 14.070338

Sheet Quarters
A1: ='Profit & Loss'!A1 -> Infosys Ltd | E1: =UPDATE | J1: SCREENER.IN
A3: Narration | B3: ='Data Sheet'!B41 -> 45352 | C3: ='Data Sheet'!C41 -> 45444 | D3: ='Data Sheet'!D41 -> 45536 | E3: ='Data Sheet'!E41 -> 45627 | F3: ='Data Sheet'!F41 -> 45717 | G3: ='Data Sheet'!G41 -> 45809 | H3: ='Data Sheet'!H41 -> 45901 | I3: ='Data Sheet'!I41 -> 45992 | ... K3: ='Data Sheet'!K41 -> 46174
A4: Sales | B4: ='Data Sheet'!B42 -> 37923 | C4: ='Data Sheet'!C42 -> 39315 | D4: ='Data Sheet'!D42 -> 40986 | E4: ='Data Sheet'!E42 -> 41764 | F4: ='Data Sheet'!F42 -> 40925 | G4: ='Data Sheet'!G42 -> 42279 | H4: ='Data Sheet'!H42 -> 44490 | I4: ='Data Sheet'!I42 -> 45479 | ... K4: ='Data Sheet'!K42 -> 48211
A5: Expenses | B5: ='Data Sheet'!B43 -> 29139 | C5: ='Data Sheet'!C43 -> 29878 | D5: ='Data Sheet'!D43 -> 31177 | E5: ='Data Sheet'!E43 -> 31649 | F5: ='Data Sheet'!F43 -> 31051 | G5: ='Data Sheet'!G43 -> 32336 | H5: ='Data Sheet'!H43 -> 33955 | I5: ='Data Sheet'!I43 -> 34845 | ... K5: ='Data Sheet'!K43 -> 36802
A6: Operating Profit | B6: ='Data Sheet'!B50 -> 8784 | C6: ='Data Sheet'!C50 -> 9437 | D6: ='Data Sheet'!D50 -> 9809 | E6: ='Data Sheet'!E50 -> 10115 | F6: ='Data Sheet'!F50 -> 9874 | G6: ='Data Sheet'!G50 -> 9943 | H6: ='Data Sheet'!H50 -> 10535 | I6: ='Data Sheet'!I50 -> 10634 | ... K6: ='Data Sheet'!K50 -> 11409
A7: Other Income | B7: ='Data Sheet'!B44 -> 2729 | C7: ='Data Sheet'!C44 -> 838 | D7: ='Data Sheet'!D44 -> 712 | E7: ='Data Sheet'!E44 -> 859 | F7: ='Data Sheet'!F44 -> 1190 | G7: ='Data Sheet'!G44 -> 1042 | H7: ='Data Sheet'!H44 -> 982 | I7: ='Data Sheet'!I44 -> -150 | ... K7: ='Data Sheet'!K44 -> 984
A8: Depreciation | B8: ='Data Sheet'!B45 -> 1163 | C8: ='Data Sheet'!C45 -> 1149 | D8: ='Data Sheet'!D45 -> 1160 | E8: ='Data Sheet'!E45 -> 1203 | F8: ='Data Sheet'!F45 -> 1299 | G8: ='Data Sheet'!G45 -> 1140 | H8: ='Data Sheet'!H45 -> 1182 | I8: ='Data Sheet'!I45 -> 1155 | ... K8: ='Data Sheet'!K45 -> 1246
A9: Interest | B9: ='Data Sheet'!B46 -> 110 | C9: ='Data Sheet'!C46 -> 105 | D9: ='Data Sheet'!D46 -> 108 | E9: ='Data Sheet'!E46 -> 101 | F9: ='Data Sheet'!F46 -> 102 | G9: ='Data Sheet'!G46 -> 105 | H9: ='Data Sheet'!H46 -> 106 | I9: ='Data Sheet'!I46 -> 100 | ... K9: ='Data Sheet'!K46 -> 119
A10: Profit before tax | B10: ='Data Sheet'!B47 -> 10240 | C10: ='Data Sheet'!C47 -> 9021 | D10: ='Data Sheet'!D47 -> 9253 | E10: ='Data Sheet'!E47 -> 9670 | F10: ='Data Sheet'!F47 -> 9663 | G10: ='Data Sheet'!G47 -> 9740 | H10: ='Data Sheet'!H47 -> 10229 | I10: ='Data Sheet'!I47 -> 9229 | ... K10: ='Data Sheet'!K47 -> 11028
A11: Tax | B11: ='Data Sheet'!B48 -> 10240 | C11: ='Data Sheet'!C48 -> 9021 | D11: ='Data Sheet'!D48 -> 9253 | E11: ='Data Sheet'!E48 -> 9670 | F11: ='Data Sheet'!F48 -> 9663 | G11: ='Data Sheet'!G48 -> 9740 | H11: ='Data Sheet'!H48 -> 10229 | I11: ='Data Sheet'!I48 -> 9229 | ... K11: ='Data Sheet'!K48 -> 11028
A12: Net profit | B12: ='Data Sheet'!B49 -> 7975 | C12: ='Data Sheet'!C49 -> 6374 | D12: ='Data Sheet'!D49 -> 6516 | E12: ='Data Sheet'!E49 -> 6822 | F12: ='Data Sheet'!F49 -> 7038 | G12: ='Data Sheet'!G49 -> 6924 | H12: ='Data Sheet'!H49 -> 7375 | I12: ='Data Sheet'!I49 -> 6666 | ... K12: ='Data Sheet'!K49 -> 7775
A14: OPM | B14: =IF(B4>0,B6/B4,"") -> 0.23162724 | C14: =IF(C4>0,C6/C4,"") -> 0.24003561 | D14: =IF(D4>0,D6/D4,"") -> 0.23932562 | E14: =IF(E4>0,E6/E4,"") -> 0.24219423 | F14: =IF(F4>0,F6/F4,"") -> 0.24127062 | G14: =IF(G4>0,G6/G4,"") -> 0.23517586 | H14: =IF(H4>0,H6/H4,"") -> 0.23679479 | I14: =IF(I4>0,I6/I4,"") -> 0.2338222 | ... K14: =IF(K4>0,K6/K4,"") -> 0.23664724

Sheet Balance Sheet
A1: ='Profit & Loss'!A1 -> Infosys Ltd | E1: =UPDATE | J1: SCREENER.IN
A3: Narration | B3: ='Data Sheet'!B56 -> 42795 | C3: ='Data Sheet'!C56 -> 43160 | D3: ='Data Sheet'!D56 -> 43525 | E3: ='Data Sheet'!E56 -> 43891 | F3: ='Data Sheet'!F56 -> 44256 | G3: ='Data Sheet'!G56 -> 44621 | H3: ='Data Sheet'!H56 -> 44986 | I3: ='Data Sheet'!I56 -> 45352 | ... K3: ='Data Sheet'!K56 -> 46082
A4: Equity Share Capital | B4: ='Data Sheet'!B57 -> 1144 | C4: ='Data Sheet'!C57 -> 1088 | D4: ='Data Sheet'!D57 -> 2170 | E4: ='Data Sheet'!E57 -> 2122 | F4: ='Data Sheet'!F57 -> 2124 | G4: ='Data Sheet'!G57 -> 2098 | H4: ='Data Sheet'!H57 -> 2069 | I4: ='Data Sheet'!I57 -> 2071 | ... K4: ='Data Sheet'!K57 -> 2024
A5: Reserves | B5: ='Data Sheet'!B58 -> 67838 | C5: ='Data Sheet'!C58 -> 63835 | D5: ='Data Sheet'!D58 -> 62778 | E5: ='Data Sheet'!E58 -> 63328 | F5: ='Data Sheet'!F58 -> 74227 | G5: ='Data Sheet'!G58 -> 73252 | H5: ='Data Sheet'!H58 -> 73338 | I5: ='Data Sheet'!I58 -> 86045 | ... K5: ='Data Sheet'!K58 -> 90828
A6: Borrowings | B6: ='Data Sheet'!B59 -> 0 | C6: ='Data Sheet'!C59 -> 0 | D6: ='Data Sheet'!D59 -> 0 | E6: ='Data Sheet'!E59 -> 4633 | F6: ='Data Sheet'!F59 -> 5325 | G6: ='Data Sheet'!G59 -> 5474 | H6: ='Data Sheet'!H59 -> 8299 | I6: ='Data Sheet'!I59 -> 8359 | ... K6: ='Data Sheet'!K59 -> 9176
A7: Other Liabilities | B7: ='Data Sheet'!B60 -> 14166 | C7: ='Data Sheet'!C60 -> 14426 | D7: ='Data Sheet'!D60 -> 19118 | E7: ='Data Sheet'!E60 -> 21717 | F7: ='Data Sheet'!F60 -> 25835 | G7: ='Data Sheet'!G60 -> 35905 | H7: ='Data Sheet'!H60 -> 40890 | I7: ='Data Sheet'!I60 -> 39545 | ... K7: ='Data Sheet'!K60 -> 52260
A8: Total | B8: ='Data Sheet'!B61 -> 83148 | C8: ='Data Sheet'!C61 -> 79349 | D8: ='Data Sheet'!D61 -> 84066 | E8: ='Data Sheet'!E61 -> 91800 | F8: ='Data Sheet'!F61 -> 107511 | G8: ='Data Sheet'!G61 -> 116729 | H8: ='Data Sheet'!H61 -> 124596 | I8: ='Data Sheet'!I61 -> 136020 | ... K8: ='Data Sheet'!K61 -> 154288
A10: Net Block | B10: ='Data Sheet'!B62 -> 14179 | C10: ='Data Sheet'!C62 -> 12574 | D10: ='Data Sheet'!D62 -> 15710 | E10: ='Data Sheet'!E62 -> 23789 | F10: ='Data Sheet'!F62 -> 25505 | G10: ='Data Sheet'!G62 -> 25800 | H10: ='Data Sheet'!H62 -> 29225 | I10: ='Data Sheet'!I62 -> 27622 | ... K10: ='Data Sheet'!K62 -> 33770
A11: Capital Work in Progress | B11: ='Data Sheet'!B63 -> 1365 | C11: ='Data Sheet'!C63 -> 1606 | D11: ='Data Sheet'!D63 -> 1388 | E11: ='Data Sheet'!E63 -> 954 | F11: ='Data Sheet'!F63 -> 922 | G11: ='Data Sheet'!G63 -> 416 | H11: ='Data Sheet'!H63 -> 288 | I11: ='Data Sheet'!I63 -> 293 | ... K11: ='Data Sheet'!K63 -> 526
A12: Investments | B12: ='Data Sheet'!B64 -> 16423 | C12: ='Data Sheet'!C64 -> 12163 | D12: ='Data Sheet'!D64 -> 11261 | E12: ='Data Sheet'!E64 -> 8792 | F12: ='Data Sheet'!F64 -> 14205 | G12: ='Data Sheet'!G64 -> 20324 | H12: ='Data Sheet'!H64 -> 19478 | I12: ='Data Sheet'!I64 -> 24623 | ... K12: ='Data Sheet'!K64 -> 21880
A13: Other Assets | B13: ='Data Sheet'!B65 -> 51181 | C13: ='Data Sheet'!C65 -> 53006 | D13: ='Data Sheet'!D65 -> 55707 | E13: ='Data Sheet'!E65 -> 58265 | F13: ='Data Sheet'!F65 -> 66879 | G13: ='Data Sheet'!G65 -> 70189 | H13: ='Data Sheet'!H65 -> 75605 | I13: ='Data Sheet'!I65 -> 83482 | ... K13: ='Data Sheet'!K65 -> 98112
A14: Total | B14: ='Data Sheet'!B66 -> 83148 | C14: ='Data Sheet'!C66 -> 79349 | D14: ='Data Sheet'!D66 -> 84066 | E14: ='Data Sheet'!E66 -> 91800 | F14: ='Data Sheet'!F66 -> 107511 | G14: ='Data Sheet'!G66 -> 116729 | H14: ='Data Sheet'!H66 -> 124596 | I14: ='Data Sheet'!I66 -> 136020 | ... K14: ='Data Sheet'!K66 -> 154288
A16: Working Capital | B16: =B13-B7 -> 37015 | C16: =C13-C7 -> 38580 | D16: =D13-D7 -> 36589 | E16: =E13-E7 -> 36548 | F16: =F13-F7 -> 41044 | G16: =G13-G7 -> 34284 | H16: =H13-H7 -> 34715 | I16: =I13-I7 -> 43937 | ... K16: =K13-K7 -> 45852
A17: Debtors | B17: ='Data Sheet'!B67 -> 12322 | C17: ='Data Sheet'!C67 -> 13142 | D17: ='Data Sheet'!D67 -> 14827 | E17: ='Data Sheet'!E67 -> 18487 | F17: ='Data Sheet'!F67 -> 19294 | G17: ='Data Sheet'!G67 -> 22698 | H17: ='Data Sheet'!H67 -> 25424 | I17: ='Data Sheet'!I67 -> 30193 | ... K17: ='Data Sheet'!K67 -> 35234
A18: Inventory | B18: ='Data Sheet'!B68 -> 8116.1 | C18: ='Data Sheet'!C68 -> 7495.09 | D18: ='Data Sheet'!D68 -> 7859.56 | E18: ='Data Sheet'!E68 -> 8879.33 | F18: ='Data Sheet'!F68 -> 10397.16 | G18: ='Data Sheet'!G68 -> 10864.15 | H18: ='Data Sheet'!H68 -> 11771.16 | I18: ='Data Sheet'!I68 -> 14152.88 | ... K18: ='Data Sheet'!K68 -> 18622.96
A20: Debtor Days | B20: =IF('Profit & Loss'!B4>0,'Balance Sheet'!B17/('Profit & Loss'!B4/365),0) -> 63.77485 | C20: =IF('Profit & Loss'!C4>0,'Balance Sheet'!C17/('Profit & Loss'!C4/365),0) -> 58.020321 | D20: =IF('Profit & Loss'!D4>0,'Balance Sheet'!D17/('Profit & Loss'!D4/365),0) -> 59.607836 | E20: =IF('Profit & Loss'!E4>0,'Balance Sheet'!E17/('Profit & Loss'!E4/365),0) -> 67.160552 | F20: =IF('Profit & Loss'!F4>0,'Balance Sheet'!F17/('Profit & Loss'!F4/365),0) -> 57.894213 | G20: =IF('Profit & Loss'!G4>0,'Balance Sheet'!G17/('Profit & Loss'!G4/365),0) -> 56.448452 | H20: =IF('Profit & Loss'!H4>0,'Balance Sheet'!H17/('Profit & Loss'!H4/365),0) -> 60.387584 | I20: =IF('Profit & Loss'!I4>0,'Balance Sheet'!I17/('Profit & Loss'!I4/365),0) -> 67.61424 | ... K20: =IF('Profit & Loss'!K4>0,'Balance Sheet'!K17/('Profit & Loss'!K4/365),0) -> 69.673153
A21: Inventory Turnover | B21: =IF('Balance Sheet'!B18>0,'Profit & Loss'!B4/'Balance Sheet'!B18,0) -> 8.6891487 | C21: =IF('Balance Sheet'!C18>0,'Profit & Loss'!C4/'Balance Sheet'!C18,0) -> 11.030555 | D21: =IF('Balance Sheet'!D18>0,'Profit & Loss'!D4/'Balance Sheet'!D18,0) -> 11.551664 | E21: =IF('Balance Sheet'!E18>0,'Profit & Loss'!E4/'Balance Sheet'!E18,0) -> 11.315268 | F21: =IF('Balance Sheet'!F18>0,'Profit & Loss'!F4/'Balance Sheet'!F18,0) -> 11.699445 | G21: =IF('Balance Sheet'!G18>0,'Profit & Loss'!G4/'Balance Sheet'!G18,0) -> 13.509294 | H21: =IF('Balance Sheet'!H18>0,'Profit & Loss'!H4/'Balance Sheet'!H18,0) -> 13.054788 | I21: =IF('Balance Sheet'!I18>0,'Profit & Loss'!I4/'Balance Sheet'!I18,0) -> 11.516384 | ... K21: =IF('Balance Sheet'!K18>0,'Profit & Loss'!K4/'Balance Sheet'!K18,0) -> 9.9115286
A23: Return on Equity | B23: =IF(SUM('Balance Sheet'!B4:B5)>0,'Profit & Loss'!B12/SUM('Balance Sheet'!B4:B5),"") -> 0.23236496 | C23: =IF(SUM('Balance Sheet'!C4:C5)>0,'Profit & Loss'!C12/SUM('Balance Sheet'!C4:C5),"") -> 0.2373581 | D23: =IF(SUM('Balance Sheet'!D4:D5)>0,'Profit & Loss'!D12/SUM('Balance Sheet'!D4:D5),"") -> 0.25618957 | E23: =IF(SUM('Balance Sheet'!E4:E5)>0,'Profit & Loss'!E12/SUM('Balance Sheet'!E4:E5),"") -> 0.29676089 | F23: =IF(SUM('Balance Sheet'!F4:F5)>0,'Profit & Loss'!F12/SUM('Balance Sheet'!F4:F5),"") -> 0.29005514 | G23: =IF(SUM('Balance Sheet'!G4:G5)>0,'Profit & Loss'!G12/SUM('Balance Sheet'!G4:G5),"") -> 0.31994691 | H23: =IF(SUM('Balance Sheet'!H4:H5)>0,'Profit & Loss'!H12/SUM('Balance Sheet'!H4:H5),"") -> 0.3480844 | I23: =IF(SUM('Balance Sheet'!I4:I5)>0,'Profit & Loss'!I12/SUM('Balance Sheet'!I4:I5),"") -> 0.3035771 | ... K23: =IF(SUM('Balance Sheet'!K4:K5)>0,'Profit & Loss'!K12/SUM('Balance Sheet'!K4:K5),"") -> 0.32659501
A24: Return on Capital Emp | C24: =IF((B4+B5+B6+C4+C5+C6)>0,('Profit & Loss'!C10+'Profit & Loss'!C9)*2/(B4+B5+B6+C4+C5+C6),"") -> 0.31426758 | D24: =IF((C4+C5+C6+D4+D5+D6)>0,('Profit & Loss'!D10+'Profit & Loss'!D9)*2/(C4+C5+C6+D4+D5+D6),"") -> 0.34152351 | E24: =IF((D4+D5+D6+E4+E5+E6)>0,('Profit & Loss'!E10+'Profit & Loss'!E9)*2/(D4+D5+D6+E4+E5+E6),"") -> 0.39728655 | F24: =IF((E4+E5+E6+F4+F5+F6)>0,('Profit & Loss'!F10+'Profit & Loss'!F9)*2/(E4+E5+E6+F4+F5+F6),"") -> 0.39944913 | G24: =IF((F4+F5+F6+G4+G5+G6)>0,('Profit & Loss'!G10+'Profit & Loss'!G9)*2/(F4+F5+F6+G4+G5+G6),"") -> 0.41361231 | H24: =IF((G4+G5+G6+H4+H5+H6)>0,('Profit & Loss'!H10+'Profit & Loss'!H9)*2/(G4+G5+G6+H4+H5+H6),"") -> 0.44317754 | I24: =IF((H4+H5+H6+I4+I5+I6)>0,('Profit & Loss'!I10+'Profit & Loss'!I9)*2/(H4+H5+H6+I4+I5+I6),"") -> 0.42206448 | J24: =IF((I4+I5+I6+J4+J5+J6)>0,('Profit & Loss'!J10+'Profit & Loss'!J9)*2/(I4+I5+I6+J4+J5+J6),"") -> 0.40306204 | K24: =IF((J4+J5+J6+K4+K5+K6)>0,('Profit & Loss'!K10+'Profit & Loss'!K9)*2/(J4+J5+J6+K4+K5+K6),"") -> 0.40483712

Sheet Cash Flow
A1: ='Balance Sheet'!A1 -> Infosys Ltd | E1: =UPDATE | J1: SCREENER.IN
A3: Narration | B3: ='Data Sheet'!B81 -> 42795 | C3: ='Data Sheet'!C81 -> 43160 | D3: ='Data Sheet'!D81 -> 43525 | E3: ='Data Sheet'!E81 -> 43891 | F3: ='Data Sheet'!F81 -> 44256 | G3: ='Data Sheet'!G81 -> 44621 | H3: ='Data Sheet'!H81 -> 44986 | I3: ='Data Sheet'!I81 -> 45352 | ... K3: ='Data Sheet'!K81 -> 46082
A4: Cash from Operating Activity | B4: ='Data Sheet'!B82 -> 11531 | C4: ='Data Sheet'!C82 -> 13218 | D4: ='Data Sheet'!D82 -> 14841 | E4: ='Data Sheet'!E82 -> 17003 | F4: ='Data Sheet'!F82 -> 23224 | G4: ='Data Sheet'!G82 -> 23885 | H4: ='Data Sheet'!H82 -> 22467 | I4: ='Data Sheet'!I82 -> 25210 | ... K4: ='Data Sheet'!K82 -> 33986
A5: Cash from Investing Activity | B5: ='Data Sheet'!B83 -> -14664 | C5: ='Data Sheet'!C83 -> 4533 | D5: ='Data Sheet'!D83 -> -632 | E5: ='Data Sheet'!E83 -> -331 | F5: ='Data Sheet'!F83 -> -7373 | G5: ='Data Sheet'!G83 -> -6485 | H5: ='Data Sheet'!H83 -> -1071 | I5: ='Data Sheet'!I83 -> -5093 | ... K5: ='Data Sheet'!K83 -> 3546
A6: Cash from Financing Activity | B6: ='Data Sheet'!B84 -> -6939 | C6: ='Data Sheet'!C84 -> -20505 | D6: ='Data Sheet'!D84 -> -14512 | E6: ='Data Sheet'!E84 -> -17591 | F6: ='Data Sheet'!F84 -> -9786 | G6: ='Data Sheet'!G84 -> -24642 | H6: ='Data Sheet'!H84 -> -26695 | I6: ='Data Sheet'!I84 -> -17504 | ... K6: ='Data Sheet'!K84 -> -39786
A7: Net Cash Flow | B7: ='Data Sheet'!B85 -> -10072 | C7: ='Data Sheet'!C85 -> -2754 | D7: ='Data Sheet'!D85 -> -303 | E7: ='Data Sheet'!E85 -> -919 | F7: ='Data Sheet'!F85 -> 6065 | G7: ='Data Sheet'!G85 -> -7242 | H7: ='Data Sheet'!H85 -> -5299 | I7: ='Data Sheet'!I85 -> 2613 | ... K7: ='Data Sheet'!K85 -> -2254

Sheet Customization
A1: How to use it?
A3: You can customize this workbook as you want.
B4: You can add custom formating, add conditional formating, add your own formulas… do ANYTHING.
B5: Please don't edit the "Data Sheet" only.
A7: After customization, you can upload this back on Screener.
B8: Upload on: | C8: https://www.screener.in/excel/
A10: Download your customized workbooks now onwards.
B11: Now whenever you will "Export to excel" from Screener, it will export your customized file.
A14: TESTING:
B15: This is a testing feature currently.
B16: You can report any formula errors on the worksheet at: support@screener.in

Sheet Common Size Statement
B2: ="Common Size Statement - "&'Data Sheet'!$B$1 -> Common Size Statement - Infosys Ltd
B4: Particulars | C4: ='Data Sheet'!B$16 -> 43160 | D4: ='Data Sheet'!C$16 -> 43525 | E4: ='Data Sheet'!D$16 -> 43891 | F4: ='Data Sheet'!E$16 -> 44256 | G4: ='Data Sheet'!F$16 -> 44621 | H4: ='Data Sheet'!G$16 -> 44986 | I4: ='Data Sheet'!H$16 -> 45352 | J4: ='Data Sheet'!I$16 -> 45717 | ... L4: ='Data Sheet'!K$16 -> TTM
B6: ='Data Sheet'!A17 -> Sales | C6: ='Data Sheet'!B17/'Data Sheet'!B$17 -> 1 | D6: ='Data Sheet'!C17/'Data Sheet'!C$17 -> 1 | E6: ='Data Sheet'!D17/'Data Sheet'!D$17 -> 1 | F6: ='Data Sheet'!E17/'Data Sheet'!E$17 -> 1 | G6: ='Data Sheet'!F17/'Data Sheet'!F$17 -> 1 | H6: ='Data Sheet'!G17/'Data Sheet'!G$17 -> 1 | I6: ='Data Sheet'!H17/'Data Sheet'!H$17 -> 1 | J6: ='Data Sheet'!I17/'Data Sheet'!I$17 -> 1 | ... L6: ='Data Sheet'!K17/'Data Sheet'!K$17 -> 1
B7: ='Data Sheet'!A18 -> Raw Material Cost | C7: ='Data Sheet'!B18/'Data Sheet'!B$17 -> 0 | D7: ='Data Sheet'!C18/'Data Sheet'!C$17 -> 0 | E7: ='Data Sheet'!D18/'Data Sheet'!D$17 -> 0 | F7: ='Data Sheet'!E18/'Data Sheet'!E$17 -> 0 | G7: ='Data Sheet'!F18/'Data Sheet'!F$17 -> 0 | H7: ='Data Sheet'!G18/'Data Sheet'!G$17 -> 0 | I7: ='Data Sheet'!H18/'Data Sheet'!H$17 -> 0 | J7: ='Data Sheet'!I18/'Data Sheet'!I$17 -> 0 | ... L7: ='Data Sheet'!K18/'Data Sheet'!K$17 -> 0
B8: ='Data Sheet'!A19 -> Change in Inventory | C8: ='Data Sheet'!B19/'Data Sheet'!B$17 -> 0 | D8: ='Data Sheet'!C19/'Data Sheet'!C$17 -> 0 | E8: ='Data Sheet'!D19/'Data Sheet'!D$17 -> 0 | F8: ='Data Sheet'!E19/'Data Sheet'!E$17 -> 0 | G8: ='Data Sheet'!F19/'Data Sheet'!F$17 -> 0 | H8: ='Data Sheet'!G19/'Data Sheet'!G$17 -> 0 | I8: ='Data Sheet'!H19/'Data Sheet'!H$17 -> 0 | J8: ='Data Sheet'!I19/'Data Sheet'!I$17 -> 0 | ... L8: ='Data Sheet'!K19/'Data Sheet'!K$17 -> 0
B9: ='Data Sheet'!A20 -> Power and Fuel | C9: ='Data Sheet'!B20/'Data Sheet'!B$17 -> 0 | D9: ='Data Sheet'!C20/'Data Sheet'!C$17 -> 0 | E9: ='Data Sheet'!D20/'Data Sheet'!D$17 -> 0 | F9: ='Data Sheet'!E20/'Data Sheet'!E$17 -> 0 | G9: ='Data Sheet'!F20/'Data Sheet'!F$17 -> 0 | H9: ='Data Sheet'!G20/'Data Sheet'!G$17 -> 0 | I9: ='Data Sheet'!H20/'Data Sheet'!H$17 -> 0 | J9: ='Data Sheet'!I20/'Data Sheet'!I$17 -> 0 | ... L9: ='Data Sheet'!K20/'Data Sheet'!K$17 -> 0
B10: ='Data Sheet'!A21 -> Other Mfr. Exp | C10: ='Data Sheet'!B21/'Data Sheet'!B$17 -> 0.11 | D10: ='Data Sheet'!C21/'Data Sheet'!C$17 -> 0.12 | E10: ='Data Sheet'!D21/'Data Sheet'!D$17 -> 0.12 | F10: ='Data Sheet'!E21/'Data Sheet'!E$17 -> 0.13 | G10: ='Data Sheet'!F21/'Data Sheet'!F$17 -> 0.17 | H10: ='Data Sheet'!G21/'Data Sheet'!G$17 -> 0.18 | I10: ='Data Sheet'!H21/'Data Sheet'!H$17 -> 0.18 | J10: ='Data Sheet'!I21/'Data Sheet'!I$17 -> 0.19 | ... L10: ='Data Sheet'!K21/'Data Sheet'!K$17 -> 0
B11: ='Data Sheet'!A22 -> Employee Cost | C11: ='Data Sheet'!B22/'Data Sheet'!B$17 -> 0.55 | D11: ='Data Sheet'!C22/'Data Sheet'!C$17 -> 0.55 | E11: ='Data Sheet'!D22/'Data Sheet'!D$17 -> 0.56 | F11: ='Data Sheet'!E22/'Data Sheet'!E$17 -> 0.55 | G11: ='Data Sheet'!F22/'Data Sheet'!F$17 -> 0.53 | H11: ='Data Sheet'!G22/'Data Sheet'!G$17 -> 0.53 | I11: ='Data Sheet'!H22/'Data Sheet'!H$17 -> 0.54 | J11: ='Data Sheet'!I22/'Data Sheet'!I$17 -> 0.53 | ... L11: ='Data Sheet'!K22/'Data Sheet'!K$17 -> 0
B12: ='Data Sheet'!A23 -> Selling and admin | C12: ='Data Sheet'!B23/'Data Sheet'!B$17 -> 0 | D12: ='Data Sheet'!C23/'Data Sheet'!C$17 -> 0 | E12: ='Data Sheet'!D23/'Data Sheet'!D$17 -> 0 | F12: ='Data Sheet'!E23/'Data Sheet'!E$17 -> 0 | G12: ='Data Sheet'!F23/'Data Sheet'!F$17 -> 0 | H12: ='Data Sheet'!G23/'Data Sheet'!G$17 -> 0 | I12: ='Data Sheet'!H23/'Data Sheet'!H$17 -> 0 | J12: ='Data Sheet'!I23/'Data Sheet'!I$17 -> 0 | ... L12: ='Data Sheet'!K23/'Data Sheet'!K$17 -> 0
B13: ='Data Sheet'!A24 -> Other Expenses | C13: ='Data Sheet'!B24/'Data Sheet'!B$17 -> 0.08 | D13: ='Data Sheet'!C24/'Data Sheet'!C$17 -> 0.09 | E13: ='Data Sheet'!D24/'Data Sheet'!D$17 -> 0.07 | F13: ='Data Sheet'!E24/'Data Sheet'!E$17 -> 0.04 | G13: ='Data Sheet'!F24/'Data Sheet'!F$17 -> 0.04 | H13: ='Data Sheet'!G24/'Data Sheet'!G$17 -> 0.05 | I13: ='Data Sheet'!H24/'Data Sheet'!H$17 -> 0.05 | J13: ='Data Sheet'!I24/'Data Sheet'!I$17 -> 0.04 | ... L13: ='Data Sheet'!K24/'Data Sheet'!K$17 -> 0
B14: ='Data Sheet'!A25 -> Other Income | C14: ='Data Sheet'!B25/'Data Sheet'!B$17 -> 0.046949888 | D14: ='Data Sheet'!C25/'Data Sheet'!C$17 -> 0.034859389 | E14: ='Data Sheet'!D25/'Data Sheet'!D$17 -> 0.030873104 | F14: ='Data Sheet'!E25/'Data Sheet'!E$17 -> 0.021906601 | G14: ='Data Sheet'!F25/'Data Sheet'!F$17 -> 0.018866994 | H14: ='Data Sheet'!G25/'Data Sheet'!G$17 -> 0.01840332 | I14: ='Data Sheet'!H25/'Data Sheet'!H$17 -> 0.030656602 | J14: ='Data Sheet'!I25/'Data Sheet'!I$17 -> 0.022087245 | ... L14: ='Data Sheet'!K25/'Data Sheet'!K$17 -> 0.016117498
B15: ='Data Sheet'!A26 -> Depreciation | C15: ='Data Sheet'!B26/'Data Sheet'!B$17 -> 0.026417288 | D15: ='Data Sheet'!C26/'Data Sheet'!C$17 -> 0.024324161 | E15: ='Data Sheet'!D26/'Data Sheet'!D$17 -> 0.031864392 | F15: ='Data Sheet'!E26/'Data Sheet'!E$17 -> 0.032516522 | G15: ='Data Sheet'!F26/'Data Sheet'!F$17 -> 0.028575891 | H15: ='Data Sheet'!G26/'Data Sheet'!G$17 -> 0.028787125 | I15: ='Data Sheet'!H26/'Data Sheet'!H$17 -> 0.030441856 | J15: ='Data Sheet'!I26/'Data Sheet'!I$17 -> 0.029523284 | ... L15: ='Data Sheet'!K26/'Data Sheet'!K$17 -> 0.027126155
B16: ='Data Sheet'!A27 -> Interest | C16: ='Data Sheet'!B27/'Data Sheet'!B$17 -> 0 | D16: ='Data Sheet'!C27/'Data Sheet'!C$17 -> 0 | E16: ='Data Sheet'!D27/'Data Sheet'!D$17 -> 0.0018724323 | F16: ='Data Sheet'!E27/'Data Sheet'!E$17 -> 0.0019408392 | G16: ='Data Sheet'!F27/'Data Sheet'!F$17 -> 0.0016441825 | H16: ='Data Sheet'!G27/'Data Sheet'!G$17 -> 0.0019350399 | I16: ='Data Sheet'!H27/'Data Sheet'!H$17 -> 0.003058502 | J16: ='Data Sheet'!I27/'Data Sheet'!I$17 -> 0.0025523038 | ... L16: ='Data Sheet'!K27/'Data Sheet'!K$17 -> 0.0023295879
B17: ='Data Sheet'!A28 -> Profit before tax | C17: ='Data Sheet'!B28/'Data Sheet'!B$17 -> 0.28742804 | D17: ='Data Sheet'!C28/'Data Sheet'!C$17 -> 0.25450257 | E17: ='Data Sheet'!D28/'Data Sheet'!D$17 -> 0.24239187 | F17: ='Data Sheet'!E28/'Data Sheet'!E$17 -> 0.26502906 | G17: ='Data Sheet'!F28/'Data Sheet'!F$17 -> 0.24753167 | H17: ='Data Sheet'!G28/'Data Sheet'!G$17 -> 0.22704014 | I17: ='Data Sheet'!H28/'Data Sheet'!H$17 -> 0.23419015 | J17: ='Data Sheet'!I28/'Data Sheet'!I$17 -> 0.23073808 | ... L17: ='Data Sheet'!K28/'Data Sheet'!K$17 -> 0.22365669
... B21: ='Data Sheet'!A32 -> EBITDA | C21: ='Data Sheet'!B32/'Data Sheet'!B$17 -> 0.31384532 | D21: ='Data Sheet'!C32/'Data Sheet'!C$17 -> 0.27882673 | E21: ='Data Sheet'!D32/'Data Sheet'!D$17 -> 0.27612869 | F21: ='Data Sheet'!E32/'Data Sheet'!E$17 -> 0.29948642 | G21: ='Data Sheet'!F32/'Data Sheet'!F$17 -> 0.27775174 | H21: ='Data Sheet'!G32/'Data Sheet'!G$17 -> 0.2577623 | I21: ='Data Sheet'!H32/'Data Sheet'!H$17 -> 0.26769051 | J21: ='Data Sheet'!I32/'Data Sheet'!I$17 -> 0.26281367 | ... L21: ='Data Sheet'!K32/'Data Sheet'!K$17 -> 0.25311244
B23: ="Common Size Balance Sheet - "&'Data Sheet'!$B$1 -> Common Size Balance Sheet - Infosys Ltd
B25: Particulars | C25: ='Data Sheet'!B$16 -> 43160 | D25: ='Data Sheet'!C$16 -> 43525 | E25: ='Data Sheet'!D$16 -> 43891 | F25: ='Data Sheet'!E$16 -> 44256 | G25: ='Data Sheet'!F$16 -> 44621 | H25: ='Data Sheet'!G$16 -> 44986 | I25: ='Data Sheet'!H$16 -> 45352 | J25: ='Data Sheet'!I$16 -> 45717 | ... L25: ='Data Sheet'!K$16 -> TTM
B27: Total Liabilities | C27: ='Data Sheet'!B61/'Data Sheet'!B$61 -> 1 | D27: ='Data Sheet'!C61/'Data Sheet'!C$61 -> 1 | E27: ='Data Sheet'!D61/'Data Sheet'!D$61 -> 1 | F27: ='Data Sheet'!E61/'Data Sheet'!E$61 -> 1 | G27: ='Data Sheet'!F61/'Data Sheet'!F$61 -> 1 | H27: ='Data Sheet'!G61/'Data Sheet'!G$61 -> 1 | I27: ='Data Sheet'!H61/'Data Sheet'!H$61 -> 1 | J27: ='Data Sheet'!I61/'Data Sheet'!I$61 -> 1 | ... L27: ='Data Sheet'!K61/'Data Sheet'!K$61 -> 1
B28: ='Data Sheet'!A57 -> Equity Share Capital | C28: ='Data Sheet'!B57/'Data Sheet'!B$61 -> 0.013758599 | D28: ='Data Sheet'!C57/'Data Sheet'!C$61 -> 0.013711578 | E28: ='Data Sheet'!D57/'Data Sheet'!D$61 -> 0.025813052 | F28: ='Data Sheet'!E57/'Data Sheet'!E$61 -> 0.023115468 | G28: ='Data Sheet'!F57/'Data Sheet'!F$61 -> 0.019756118 | H28: ='Data Sheet'!G57/'Data Sheet'!G$61 -> 0.017973254 | I28: ='Data Sheet'!H57/'Data Sheet'!H$61 -> 0.01660567 | J28: ='Data Sheet'!I57/'Data Sheet'!I$61 -> 0.015225702 | ... L28: ='Data Sheet'!K57/'Data Sheet'!K$61 -> 0.013118324
B29: ='Data Sheet'!A58 -> Reserves | C29: ='Data Sheet'!B58/'Data Sheet'!B$61 -> 0.8158705 | D29: ='Data Sheet'!C58/'Data Sheet'!C$61 -> 0.80448399 | E29: ='Data Sheet'!D58/'Data Sheet'!D$61 -> 0.74677039 | F29: ='Data Sheet'!E58/'Data Sheet'!E$61 -> 0.68984749 | G29: ='Data Sheet'!F58/'Data Sheet'!F$61 -> 0.69041307 | H29: ='Data Sheet'!G58/'Data Sheet'!G$61 -> 0.627539 | I29: ='Data Sheet'!H58/'Data Sheet'!H$61 -> 0.58860638 | J29: ='Data Sheet'!I58/'Data Sheet'!I$61 -> 0.6325908 | ... L29: ='Data Sheet'!K58/'Data Sheet'!K$61 -> 0.58869128
B30: ='Data Sheet'!A59 -> Borrowings | C30: ='Data Sheet'!B59/'Data Sheet'!B$61 -> 0 | D30: ='Data Sheet'!C59/'Data Sheet'!C$61 -> 0 | E30: ='Data Sheet'!D59/'Data Sheet'!D$61 -> 0 | F30: ='Data Sheet'!E59/'Data Sheet'!E$61 -> 0.05046841 | G30: ='Data Sheet'!F59/'Data Sheet'!F$61 -> 0.049529816 | H30: ='Data Sheet'!G59/'Data Sheet'!G$61 -> 0.046894945 | I30: ='Data Sheet'!H59/'Data Sheet'!H$61 -> 0.066607275 | J30: ='Data Sheet'!I59/'Data Sheet'!I$61 -> 0.061454198 | ... L30: ='Data Sheet'!K59/'Data Sheet'!K$61 -> 0.059473193
B31: ='Data Sheet'!A60 -> Other Liabilities | C31: ='Data Sheet'!B60/'Data Sheet'!B$61 -> 0.1703709 | D31: ='Data Sheet'!C60/'Data Sheet'!C$61 -> 0.18180443 | E31: ='Data Sheet'!D60/'Data Sheet'!D$61 -> 0.22741655 | F31: ='Data Sheet'!E60/'Data Sheet'!E$61 -> 0.23656863 | G31: ='Data Sheet'!F60/'Data Sheet'!F$61 -> 0.24030099 | H31: ='Data Sheet'!G60/'Data Sheet'!G$61 -> 0.3075928 | I31: ='Data Sheet'!H60/'Data Sheet'!H$61 -> 0.32818068 | J31: ='Data Sheet'!I60/'Data Sheet'!I$61 -> 0.2907293 | ... L31: ='Data Sheet'!K60/'Data Sheet'!K$61 -> 0.3387172
B33: Total Assets | C33: ='Data Sheet'!B66/'Data Sheet'!B$66 -> 1 | D33: ='Data Sheet'!C66/'Data Sheet'!C$66 -> 1 | E33: ='Data Sheet'!D66/'Data Sheet'!D$66 -> 1 | F33: ='Data Sheet'!E66/'Data Sheet'!E$66 -> 1 | G33: ='Data Sheet'!F66/'Data Sheet'!F$66 -> 1 | H33: ='Data Sheet'!G66/'Data Sheet'!G$66 -> 1 | I33: ='Data Sheet'!H66/'Data Sheet'!H$66 -> 1 | J33: ='Data Sheet'!I66/'Data Sheet'!I$66 -> 1 | ... L33: ='Data Sheet'!K66/'Data Sheet'!K$66 -> 1
B34: Fixed Assets Net Block | C34: ='Data Sheet'!B62/'Data Sheet'!B$66 -> 0.17052725 | D34: ='Data Sheet'!C62/'Data Sheet'!C$66 -> 0.1584645 | E34: ='Data Sheet'!D62/'Data Sheet'!D$66 -> 0.18687698 | F34: ='Data Sheet'!E62/'Data Sheet'!E$66 -> 0.25913943 | G34: ='Data Sheet'!F62/'Data Sheet'!F$66 -> 0.23723154 | H34: ='Data Sheet'!G62/'Data Sheet'!G$66 -> 0.22102477 | I34: ='Data Sheet'!H62/'Data Sheet'!H$66 -> 0.23455809 | J34: ='Data Sheet'!I62/'Data Sheet'!I$66 -> 0.20307308 | ... L34: ='Data Sheet'!K62/'Data Sheet'!K$66 -> 0.21887639
B35: ='Data Sheet'!A63 -> Capital Work in Progress | C35: ='Data Sheet'!B63/'Data Sheet'!B$66 -> 0.01641651 | D35: ='Data Sheet'!C63/'Data Sheet'!C$66 -> 0.020239701 | E35: ='Data Sheet'!D63/'Data Sheet'!D$66 -> 0.016510837 | F35: ='Data Sheet'!E63/'Data Sheet'!E$66 -> 0.010392157 | G35: ='Data Sheet'!F63/'Data Sheet'!F$66 -> 0.0085758667 | H35: ='Data Sheet'!G63/'Data Sheet'!G$66 -> 0.0035638102 | I35: ='Data Sheet'!H63/'Data Sheet'!H$66 -> 0.0023114707 | J35: ='Data Sheet'!I63/'Data Sheet'!I$66 -> 0.002154095 | ... L35: ='Data Sheet'!K63/'Data Sheet'!K$66 -> 0.0034092088
B36: ='Data Sheet'!A64 -> Investments | C36: ='Data Sheet'!B64/'Data Sheet'!B$66 -> 0.19751527 | D36: ='Data Sheet'!C64/'Data Sheet'!C$66 -> 0.15328486 | E36: ='Data Sheet'!D64/'Data Sheet'!D$66 -> 0.13395427 | F36: ='Data Sheet'!E64/'Data Sheet'!E$66 -> 0.09577342 | G36: ='Data Sheet'!F64/'Data Sheet'!F$66 -> 0.13212602 | H36: ='Data Sheet'!G64/'Data Sheet'!G$66 -> 0.17411269 | I36: ='Data Sheet'!H64/'Data Sheet'!H$66 -> 0.15632926 | J36: ='Data Sheet'!I64/'Data Sheet'!I$66 -> 0.18102485 | ... L36: ='Data Sheet'!K64/'Data Sheet'!K$66 -> 0.14181271
B37: ='Data Sheet'!A65 -> Other Assets | C37: ='Data Sheet'!B74/'Data Sheet'!B66 -> 0.097631933 | D37: ='Data Sheet'!C74/'Data Sheet'!C66 -> 0.15817351 | E37: ='Data Sheet'!D74/'Data Sheet'!D66 -> 0.16002236 | F37: ='Data Sheet'!E74/'Data Sheet'!E66 -> 0.13343867 | G37: ='Data Sheet'!F74/'Data Sheet'!F66 -> 0.11602385 | H37: ='Data Sheet'!G74/'Data Sheet'!G66 -> 0.16409675 | I37: ='Data Sheet'!H74/'Data Sheet'!H66 -> 0.2105753 | J37: ='Data Sheet'!I74/'Data Sheet'!I66 -> 0.17901867 | ... L37: ='Data Sheet'!K74/'Data Sheet'!K66 -> 0.14294073
B38: ='Data Sheet'!A67 -> Receivables | C38: ='Data Sheet'!B67/'Data Sheet'!B$66 -> 0.14819358 | D38: ='Data Sheet'!C67/'Data Sheet'!C$66 -> 0.16562276 | E38: ='Data Sheet'!D67/'Data Sheet'!D$66 -> 0.17637333 | F38: ='Data Sheet'!E67/'Data Sheet'!E$66 -> 0.20138344 | G38: ='Data Sheet'!F67/'Data Sheet'!F$66 -> 0.17946071 | H38: ='Data Sheet'!G67/'Data Sheet'!G$66 -> 0.19445039 | I38: ='Data Sheet'!H67/'Data Sheet'!H$66 -> 0.20405149 | J38: ='Data Sheet'!I67/'Data Sheet'!I$66 -> 0.22197471 | ... L38: ='Data Sheet'!K67/'Data Sheet'!K$66 -> 0.22836514
B39: ='Data Sheet'!A68 -> Inventory | C39: ='Data Sheet'!B68/'Data Sheet'!B$66 -> 0.097610285 | D39: ='Data Sheet'!C68/'Data Sheet'!C$66 -> 0.094457271 | E39: ='Data Sheet'!D68/'Data Sheet'!D$66 -> 0.093492732 | F39: ='Data Sheet'!E68/'Data Sheet'!E$66 -> 0.096724728 | G39: ='Data Sheet'!F68/'Data Sheet'!F$66 -> 0.096707872 | H39: ='Data Sheet'!G68/'Data Sheet'!G$66 -> 0.093071559 | I39: ='Data Sheet'!H68/'Data Sheet'!H$66 -> 0.094474622 | J39: ='Data Sheet'!I68/'Data Sheet'!I$66 -> 0.10404999 | ... L39: ='Data Sheet'!K68/'Data Sheet'!K$66 -> 0.12070258
B40: ='Data Sheet'!A69 -> Cash & Bank | C40: ='Data Sheet'!B69/'Data Sheet'!B$66 -> 0.27210516 | D40: ='Data Sheet'!C69/'Data Sheet'!C$66 -> 0.2497574 | E40: ='Data Sheet'!D69/'Data Sheet'!D$66 -> 0.23276949 | F40: ='Data Sheet'!E69/'Data Sheet'!E$66 -> 0.20314815 | G40: ='Data Sheet'!F69/'Data Sheet'!F$66 -> 0.22987415 | H40: ='Data Sheet'!G69/'Data Sheet'!G$66 -> 0.14968003 | I40: ='Data Sheet'!H69/'Data Sheet'!H$66 -> 0.097699766 | J40: ='Data Sheet'!I69/'Data Sheet'!I$66 -> 0.1087046 | ... L40: ='Data Sheet'!K69/'Data Sheet'!K$66 -> 0.14389324

Sheet Data Sheet
A1: COMPANY NAME | B1: Infosys Ltd | E1: =IF(B2<>B3, "A NEW VERSION OF THE WORKSHEET IS AVAILABLE", "")
A2: LATEST VERSION | B2: 2.1 | E2: PLEASE DO NOT MAKE ANY CHANGES TO THIS SHEET
A3: CURRENT VERSION | B3: 2.1
A5: META
A6: Number of shares | B6: =IF(B9>0, B9/B8, 0) -> 405.97812
A7: Face Value | B7: 5
A8: Current Price | B8: 1051
A9: Market Capitalization | B9: 426683
A15: PROFIT & LOSS
A16: Report Date | B16: 43160 | C16: 43525 | D16: 43891 | E16: 44256 | F16: 44621 | G16: 44986 | H16: 45352 | I16: 45717 | J16: 46082 | K16: TTM
A17: Sales | B17: 70522 | C17: 82675 | D17: 90791 | E17: 100472 | F17: 121641 | G17: 146767 | H17: 153670 | I17: 162990 | J17: 178650 | K17: 184582
A18: Raw Material Cost | B18: 0 | C18: 0 | D18: 0 | E18: 0 | F18: 0 | G18: 0 | H18: 0 | I18: 0 | J18: 0 | K18: 0
A19: Change in Inventory | B19: 0 | C19: 0 | D19: 0 | E19: 0 | F19: 0 | G19: 0 | H19: 0 | I19: 0 | J19: 0 | K19: 0
A20: Power and Fuel | B20: 0 | C20: 0 | D20: 0 | E20: 0 | F20: 0 | G20: 0 | H20: 0 | I20: 0 | J20: 0 | K20: 0
A21: Other Mfr. Exp | B21: 7757.42 | C21: 9921 | D21: 10894.92 | E21: 13061.36 | F21: 20678.97 | G21: 26418.06 | H21: 27660.6 | I21: 30968.1 | J21: 33943.5 | K21: 0
A22: Employee Cost | B22: 38787.1 | C22: 45471.25 | D22: 50842.96 | E22: 55259.6 | F22: 64469.73 | G22: 77786.51 | H22: 82981.8 | I22: 86384.7 | J22: 94684.5 | K22: 0
A23: Selling and admin | B23: 0 | C23: 0 | D23: 0 | E23: 0 | F23: 0 | G23: 0 | H23: 0 | I23: 0 | J23: 0 | K23: 0
A24: Other Expenses | B24: 5641.76 | C24: 7440.75 | D24: 6355.37 | E24: 4018.88 | F24: 4865.64 | G24: 7338.35 | H24: 7683.5 | I24: 6519.6 | J24: 8932.5 | K24: 0
A25: Other Income | B25: 3311 | C25: 2882 | D25: 2803 | E25: 2201 | F25: 2295 | G25: 2701 | H25: 4711 | I25: 3600 | J25: 3033 | K25: 2975
A26: Depreciation | B26: 1863 | C26: 2011 | D26: 2893 | E26: 3267 | F26: 3476 | G26: 4225 | H26: 4678 | I26: 4812 | J26: 4902 | K26: 5007
A27: Interest | B27: 0 | C27: 0 | D27: 170 | E27: 195 | F27: 200 | G27: 284 | H27: 470 | I27: 416 | J27: 416 | K27: 430
A28: Profit before tax | B28: 20270 | C28: 21041 | D28: 22007 | E28: 26628 | F28: 30110 | G28: 33322 | H28: 35988 | I28: 37608 | J28: 39995 | K28: 41283
... A31: Dividend Amount | B31: 9457.11 | C31: 9246 | D31: 7487.55 | E31: 11459.57 | F31: 13066.14 | G31: 13982.64 | H31: 19161.04 | I31: 17922.5 | J31: 19452.84 | K31: 0
A32: EBITDA | B32: =SUM(B26:B28) -> 22133 | C32: =SUM(C26:C28) -> 23052 | D32: =SUM(D26:D28) -> 25070 | E32: =SUM(E26:E28) -> 30090 | F32: =SUM(F26:F28) -> 33786 | G32: =SUM(G26:G28) -> 37831 | H32: =SUM(H26:H28) -> 41136 | I32: =SUM(I26:I28) -> 42836 | ... K32: =SUM(K26:K28) -> 46720
B33: =B30+B29+B27+B26 -> 38162 | C33: =C30+C29+C27+C26 -> 38462 | D33: =D30+D29+D27+D26 -> 41709 | E33: =E30+E29+E27+E26 -> 49513 | F33: =F30+F29+F27+F26 -> 55932 | G33: =G30+G29+G27+G26 -> 61939 | H33: =H30+H29+H27+H26 -> 67384 | I33: =I30+I29+I27+I26 -> 69586 | ... K33: =K30+K29+K27+K26 -> 77045
A40: Quarters
A41: Report Date | B41: 45352 | C41: 45444 | D41: 45536 | E41: 45627 | F41: 45717 | G41: 45809 | H41: 45901 | I41: 45992 | J41: 46082 | K41: 46174
A42: Sales | B42: 37923 | C42: 39315 | D42: 40986 | E42: 41764 | F42: 40925 | G42: 42279 | H42: 44490 | I42: 45479 | J42: 46402 | K42: 48211
A43: Expenses | B43: 29139 | C43: 29878 | D43: 31177 | E43: 31649 | F43: 31051 | G43: 32336 | H43: 33955 | I43: 34845 | J43: 35235 | K43: 36802
A44: Other Income | B44: 2729 | C44: 838 | D44: 712 | E44: 859 | F44: 1190 | G44: 1042 | H44: 982 | I44: -150 | J44: 1159 | K44: 984
A45: Depreciation | B45: 1163 | C45: 1149 | D45: 1160 | E45: 1203 | F45: 1299 | G45: 1140 | H45: 1182 | I45: 1155 | J45: 1424 | K45: 1246
A46: Interest | B46: 110 | C46: 105 | D46: 108 | E46: 101 | F46: 102 | G46: 105 | H46: 106 | I46: 100 | J46: 105 | K46: 119
A47: Profit before tax | B47: 10240 | C47: 9021 | D47: 9253 | E47: 9670 | F47: 9663 | G47: 9740 | H47: 10229 | I47: 9229 | J47: 10797 | K47: 11028
A48: Tax | B48: 10240 | C48: 9021 | D48: 9253 | E48: 9670 | F48: 9663 | G48: 9740 | H48: 10229 | I48: 9229 | J48: 10797 | K48: 11028
A49: Net profit | B49: 7975 | C49: 6374 | D49: 6516 | E49: 6822 | F49: 7038 | G49: 6924 | H49: 7375 | I49: 6666 | J49: 8509 | K49: 7775
A50: Operating Profit | B50: 8784 | C50: 9437 | D50: 9809 | E50: 10115 | F50: 9874 | G50: 9943 | H50: 10535 | I50: 10634 | J50: 11167 | K50: 11409
A55: BALANCE SHEET
A56: Report Date | B56: 42795 | C56: 43160 | D56: 43525 | E56: 43891 | F56: 44256 | G56: 44621 | H56: 44986 | I56: 45352 | J56: 45717 | K56: 46082
A57: Equity Share Capital | B57: 1144 | C57: 1088 | D57: 2170 | E57: 2122 | F57: 2124 | G57: 2098 | H57: 2069 | I57: 2071 | J57: 2073 | K57: 2024
A58: Reserves | B58: 67838 | C58: 63835 | D58: 62778 | E58: 63328 | F58: 74227 | G58: 73252 | H58: 73338 | I58: 86045 | J58: 93745 | K58: 90828
...

Sheet Cash Flow Statement
B2: Cash Flow Statement - Infosys Ltd
B4: Particulars | C4: 42064 | D4: 42430 | E4: 42795 | F4: 43160 | G4: 43525 | H4: 43891 | I4: 44256 | J4: 44621 | K4: 44986 | L4: 45352 | M4: 45717 | N4: 46082
B6: Cash from Operating Activity - | C6: 8353 | D6: 10028 | E6: 11531 | F6: 13218 | G6: 14841 | H6: 17003 | I6: 23224 | J6: 23885 | K6: 22467 | L6: 25210 | M6: 35694 | N6: 33986
B7: Profit from operations | C7: 15946 | D7: 17839 | E7: 19340 | F7: 19963 | G7: 22126 | H7: 23920 | I7: 28845 | J7: 32921 | K7: 37605 | L7: 39523 | M7: 41591 | N7: 45273
B8: Receivables | C8: -1475 | D8: -1654 | E8: -1743 | F8: -1523 | G8: -2881 | H8: -3861 | I8: -1835 | J8: -7937 | K8: -7076 | L8: -2667 | M8: -1769 | N8: -5177
B9: Inventory | C9: 0 | D9: 0 | E9: 0 | F9: 0 | G9: 0 | H9: 0 | I9: 0 | J9: 0 | K9: 0 | L9: 0 | M9: 0 | N9: 0
B10: Payables | C10: 0 | D10: 242 | E10: -19 | F10: 328 | G10: 916 | H10: -373 | I10: -245 | J10: 1489 | K10: -279 | L10: 91 | M10: 176 | N10: -26
B11: Working capital changes | C11: -842 | D11: -1946 | E11: -2156 | F11: 84 | G11: -453 | H11: -2367 | I11: 768 | J11: -1424 | K11: -6344 | L11: -5082 | M11: -295 | N11: -2639
B12: Direct taxes | C12: -6751 | D12: -5865 | E12: -5653 | F12: -6829 | G12: -6832 | H12: -4550 | I12: -6389 | J12: -7612 | K12: -8794 | L12: -9231 | M12: -5602 | N12: -8648
B13: Cash from Investing Activity - | C13: 999 | D13: -885 | E13: -14664 | F13: 4533 | G13: -632 | H13: -331 | I13: -7373 | J13: -6485 | K13: -1071 | L13: -5093 | M13: -1864 | N13: 3546
B14: Fixed assets purchased | C14: -2247 | D14: -2723 | E14: -2760 | F14: -1998 | G14: -2445 | H14: -3307 | I14: -2107 | J14: -2161 | K14: -2579 | L14: -2201 | M14: -2237 | N14: -2727
B15: Fixed assets sold | C15: 0 | D15: 0 | E15: 0 | F15: 0 | G15: 0 | H15: 0 | I15: 0 | J15: 0 | K15: 0 | L15: 0 | M15: 0 | N15: 0
B16: Investments purchased | C16: -23923 | D16: -24577 | E16: -66410 | F16: -69159 | G16: -79410 | H16: -37482 | I16: -46738 | J16: -59951 | K16: -75800 | L16: -78092 | M16: -82742 | N16: -82617
... B32: Net Cash Flow | C32: 4417 | D32: 2330 | E32: -10072 | F32: -2754 | G32: -303 | H32: -919 | I32: 6065 | J32: -7242 | K32: -5299 | L32: 2613 | M32: 9669 | N32: -2254

Sheet Historical FS
B2: ="Historical Financial Statement - "&'Data Sheet'!$B$1 -> Historical Financial Statement - Infosys Ltd
B3: Particulars | C3: ='Data Sheet'!B56 -> 42795 | D3: ='Data Sheet'!C56 -> 43160 | E3: ='Data Sheet'!D56 -> 43525 | F3: ='Data Sheet'!E56 -> 43891 | G3: ='Data Sheet'!F56 -> 44256 | H3: ='Data Sheet'!G56 -> 44621 | I3: ='Data Sheet'!H56 -> 44986 | J3: ='Data Sheet'!I56 -> 45352 | ... L3: ='Data Sheet'!K56 -> 46082 | M3: LTM
A5: # | B5: Income Statement
B7: Sales | C7: ='Data Sheet'!B17 -> 70522 | D7: ='Data Sheet'!C17 -> 82675 | E7: ='Data Sheet'!D17 -> 90791 | F7: ='Data Sheet'!E17 -> 100472 | G7: ='Data Sheet'!F17 -> 121641 | H7: ='Data Sheet'!G17 -> 146767 | I7: ='Data Sheet'!H17 -> 153670 | J7: ='Data Sheet'!I17 -> 162990 | ... L7: ='Data Sheet'!K17 -> 184582
B8: Sales Growth | C8: - | D8: =D7/C7-1 -> 0.1723292 | E8: =E7/D7-1 -> 0.098167523 | F8: =F7/E7-1 -> 0.10662951 | G8: =G7/F7-1 -> 0.21069552 | H8: =H7/G7-1 -> 0.20655864 | I8: =I7/H7-1 -> 0.047033734 | J8: =J7/I7-1 -> 0.060649444 | K8: =K7/J7-1 -> 0.096079514 | L8: =L7/K7-1 -> 0.03320459
B10: Cost of Goods Sold | C10: =SUM('Data Sheet'!B18,'Data Sheet'!B20:B22)-'Data Sheet'!B19 -> 46544.52 | D10: =SUM('Data Sheet'!C18,'Data Sheet'!C20:C22)-'Data Sheet'!C19 -> 55392.25 | E10: =SUM('Data Sheet'!D18,'Data Sheet'!D20:D22)-'Data Sheet'!D19 -> 61737.88 | F10: =SUM('Data Sheet'!E18,'Data Sheet'!E20:E22)-'Data Sheet'!E19 -> 68320.96 | G10: =SUM('Data Sheet'!F18,'Data Sheet'!F20:F22)-'Data Sheet'!F19 -> 85148.7 | H10: =SUM('Data Sheet'!G18,'Data Sheet'!G20:G22)-'Data Sheet'!G19 -> 104204.57 | I10: =SUM('Data Sheet'!H18,'Data Sheet'!H20:H22)-'Data Sheet'!H19 -> 110642.4 | J10: =SUM('Data Sheet'!I18,'Data Sheet'!I20:I22)-'Data Sheet'!I19 -> 117352.8 | ... L10: =SUM('Data Sheet'!K18,'Data Sheet'!K20:K22)-'Data Sheet'!K19 -> 0
B11: COGS % Sales | C11: =C10/C7 -> 0.66 | D11: =D10/D7 -> 0.67 | E11: =E10/E7 -> 0.68 | F11: =F10/F7 -> 0.68 | G11: =G10/G7 -> 0.7 | H11: =H10/H7 -> 0.71 | I11: =I10/I7 -> 0.72 | J11: =J10/J7 -> 0.72 | ... L11: =L10/L7 -> 0
B13: Gross Profit | C13: =C7-C10 -> 23977.48 | D13: =D7-D10 -> 27282.75 | E13: =E7-E10 -> 29053.12 | F13: =F7-F10 -> 32151.04 | G13: =G7-G10 -> 36492.3 | H13: =H7-H10 -> 42562.43 | I13: =I7-I10 -> 43027.6 | J13: =J7-J10 -> 45637.2 | ... L13: =L7-L10 -> 184582
B14: Gross Profit % Sales | C14: =C13/C7 -> 0.34 | D14: =D13/D7 -> 0.33 | E14: =E13/E7 -> 0.32 | F14: =F13/F7 -> 0.32 | G14: =G13/G7 -> 0.3 | H14: =H13/H7 -> 0.29 | I14: =I13/I7 -> 0.28 | J14: =J13/J7 -> 0.28 | ... L14: =L13/L7 -> 1
B16: Selling % General Expenses | C16: ='Data Sheet'!B23 -> 0 | D16: ='Data Sheet'!C23 -> 0 | E16: ='Data Sheet'!D23 -> 0 | F16: ='Data Sheet'!E23 -> 0 | G16: ='Data Sheet'!F23 -> 0 | H16: ='Data Sheet'!G23 -> 0 | I16: ='Data Sheet'!H23 -> 0 | J16: ='Data Sheet'!I23 -> 0 | ... L16: ='Data Sheet'!K23 -> 0
B17: S&G % Sales | C17: =C16/C7 -> 0 | D17: =D16/D7 -> 0 | E17: =E16/E7 -> 0 | F17: =F16/F7 -> 0 | G17: =G16/G7 -> 0 | H17: =H16/H7 -> 0 | I17: =I16/I7 -> 0 | J17: =J16/J7 -> 0 | ... L17: =L16/L7 -> 0
B19: EBITDA | C19: =C13-C16 -> 23977.48 | D19: =D13-D16 -> 27282.75 | E19: =E13-E16 -> 29053.12 | F19: =F13-F16 -> 32151.04 | G19: =G13-G16 -> 36492.3 | H19: =H13-H16 -> 42562.43 | I19: =I13-I16 -> 43027.6 | J19: =J13-J16 -> 45637.2 | ... L19: =L13-L16 -> 184582
B20: EBITDA % Sales | C20: =C19/C7 -> 0.34 | D20: =D19/D7 -> 0.33 | E20: =E19/E7 -> 0.32 | F20: =F19/F7 -> 0.32 | G20: =G19/G7 -> 0.3 | H20: =H19/H7 -> 0.29 | I20: =I19/I7 -> 0.28 | J20: =J19/J7 -> 0.28 | ... L20: =L19/L7 -> 1
B22: Depreciation | C22: ='Data Sheet'!B26 -> 1863 | D22: ='Data Sheet'!C26 -> 2011 | E22: ='Data Sheet'!D26 -> 2893 | F22: ='Data Sheet'!E26 -> 3267 | G22: ='Data Sheet'!F26 -> 3476 | H22: ='Data Sheet'!G26 -> 4225 | I22: ='Data Sheet'!H26 -> 4678 | J22: ='Data Sheet'!I26 -> 4812 | ... L22: ='Data Sheet'!K26 -> 5007
B23: Depreciation % Sales | C23: =C22/C7 -> 0.026417288 | D23: =D22/D7 -> 0.024324161 | E23: =E22/E7 -> 0.031864392 | F23: =F22/F7 -> 0.032516522 | G23: =G22/G7 -> 0.028575891 | H23: =H22/H7 -> 0.028787125 | I23: =I22/I7 -> 0.030441856 | J23: =J22/J7 -> 0.029523284 | ... L23: =L22/L7 -> 0.027126155
B25: EBIT | C25: =C19-C22 -> 22114.48 | D25: =D19-D22 -> 25271.75 | E25: =E19-E22 -> 26160.12 | F25: =F19-F22 -> 28884.04 | G25: =G19-G22 -> 33016.3 | H25: =H19-H22 -> 38337.43 | I25: =I19-I22 -> 38349.6 | J25: =J19-J22 -> 40825.2 | ... L25: =L19-L22 -> 179575
B26: EBIT % Sales | C26: =C25/C7 -> 0.31358271 | D26: =D25/D7 -> 0.30567584 | E26: =E25/E7 -> 0.28813561 | F26: =F25/F7 -> 0.28748348 | G26: =G25/G7 -> 0.27142411 | H26: =H25/H7 -> 0.26121287 | I26: =I25/I7 -> 0.24955814 | J26: =J25/J7 -> 0.25047672 | ... L26: =L25/L7 -> 0.97287384
B28: Interest | C28: ='Data Sheet'!B27 -> 0 | D28: ='Data Sheet'!C27 -> 0 | E28: ='Data Sheet'!D27 -> 170 | F28: ='Data Sheet'!E27 -> 195 | G28: ='Data Sheet'!F27 -> 200 | H28: ='Data Sheet'!G27 -> 284 | I28: ='Data Sheet'!H27 -> 470 | J28: ='Data Sheet'!I27 -> 416 | ... L28: ='Data Sheet'!K27 -> 430
B29: Interest % Sales | C29: =C28/C7 -> 0 | D29: =D28/D7 -> 0 | E29: =E28/E7 -> 0.0018724323 | F29: =F28/F7 -> 0.0019408392 | G29: =G28/G7 -> 0.0016441825 | H29: =H28/H7 -> 0.0019350399 | I29: =I28/I7 -> 0.003058502 | J29: =J28/J7 -> 0.0025523038 | ... L29: =L28/L7 -> 0.0023295879
B31: Earning Before Tax | C31: =C25-C28 -> 22114.48 | D31: =D25-D28 -> 25271.75 | E31: =E25-E28 -> 25990.12 | F31: =F25-F28 -> 28689.04 | G31: =G25-G28 -> 32816.3 | H31: =H25-H28 -> 38053.43 | I31: =I25-I28 -> 37879.6 | J31: =J25-J28 -> 40409.2 | ... L31: =L25-L28 -> 179145
B32: EBT % Sales | C32: =C31/C7 -> 0.31358271 | D32: =D31/D7 -> 0.30567584 | E32: =E31/E7 -> 0.28626318 | F32: =F31/F7 -> 0.28554264 | G32: =G31/G7 -> 0.26977993 | H32: =H31/H7 -> 0.25927783 | I32: =I31/I7 -> 0.24649964 | J32: =J31/J7 -> 0.24792441 | ... L32: =L31/L7 -> 0.97054426
B34: Tax Rate | C34: ='Data Sheet'!B29 -> 20270 | D34: ='Data Sheet'!C29 -> 21041 | E34: ='Data Sheet'!D29 -> 22007 | F34: ='Data Sheet'!E29 -> 26628 | G34: ='Data Sheet'!F29 -> 30110 | H34: ='Data Sheet'!G29 -> 33322 | I34: ='Data Sheet'!H29 -> 35988 | J34: ='Data Sheet'!I29 -> 37608 | ... L34: ='Data Sheet'!K29 -> 41283
B35: Effective Tax Rate | C35: =C34/C31 -> 0.91659401 | D35: =D34/D31 -> 0.83258975 | E35: =E34/E31 -> 0.84674484 | F35: =F34/F31 -> 0.92815932 | G35: =G34/G31 -> 0.91753184 | H35: =H34/H31 -> 0.87566351 | I35: =I34/I31 -> 0.95006283 | J35: =J34/J31 -> 0.93067915 | ... L35: =L34/L31 -> 0.23044461
B37: Net Profit | C37: =C31-C34 -> 1844.48 | D37: =D31-D34 -> 4230.75 | E37: =E31-E34 -> 3983.12 | F37: =F31-F34 -> 2061.04 | G37: =G31-G34 -> 2706.3 | H37: =H31-H34 -> 4731.43 | I37: =I31-I34 -> 1891.6 | J37: =J31-J34 -> 2801.2 | ... L37: =L31-L34 -> 137862
B38: Net Profit % Sales | C38: =C37/C7 -> 0.026154675 | D38: =D37/D7 -> 0.051173269 | E38: =E37/E7 -> 0.043871309 | F38: =F37/F7 -> 0.020513576 | G38: =G37/G7 -> 0.022248255 | H38: =H37/H7 -> 0.032237696 | I38: =I37/I7 -> 0.012309494 | J38: =J37/J7 -> 0.01718633 | ... L38: =L37/L7 -> 0.74688756
B40: No. of Equity Shares | C40: ='Data Sheet'!B93 -> 459.41 | D40: ='Data Sheet'!C93 -> 459.41 | E40: ='Data Sheet'!D93 -> 459.41 | F40: ='Data Sheet'!E93 -> 459.41 | G40: ='Data Sheet'!F93 -> 459.41 | H40: ='Data Sheet'!G93 -> 459.41 | I40: ='Data Sheet'!H93 -> 459.41 | J40: ='Data Sheet'!I93 -> 459.41 | ... L40: ='Data Sheet'!K93 -> 459.41
B42: Earning per Share | C42: =C37/C40 -> 4.0148887 | D42: =D37/D40 -> 9.2090943 | E42: =E37/E40 -> 8.6700768 | F42: =F37/F40 -> 4.4862759 | G42: =G37/G40 -> 5.8908165 | H42: =H37/H40 -> 10.298927 | I42: =I37/I40 -> 4.117455 | J42: =J37/J40 -> 6.0973858 | ... L42: =L37/L40 -> 300.08489
B43: EPS Growth | C43: - | D43: =D42/C42-1 -> 1.2937359 | E43: =E42/D42-1 -> -0.058530993 | F43: =F42/E42-1 -> -0.48255639 | G43: =G42/F42-1 -> 0.31307495 | H43: =H42/G42-1 -> 0.74830211 | I43: =I42/H42-1 -> -0.60020543 | J43: =J42/I42-1 -> 0.48086276 | K43: =K42/J42-1 -> 0.68106526 | L43: =L42/K42-1 -> 28.276279
B45: Dividend per Share | C45: ='Data Sheet'!B31/'Historical FS'!C40 -> 20.585338 | D45: ='Data Sheet'!C31/'Historical FS'!D40 -> 20.125814 | E45: ='Data Sheet'!D31/'Historical FS'!E40 -> 16.298187 | F45: ='Data Sheet'!E31/'Historical FS'!F40 -> 24.944102 | G45: ='Data Sheet'!F31/'Historical FS'!G40 -> 28.441131 | H45: ='Data Sheet'!G31/'Historical FS'!H40 -> 30.436081 | I45: ='Data Sheet'!H31/'Historical FS'!I40 -> 41.70793 | J45: ='Data Sheet'!I31/'Historical FS'!J40 -> 39.011994 | ... L45: ='Data Sheet'!K31/'Historical FS'!L40 -> 0
B46: Dividend Payout Ratio | C46: =C45/C42 -> 5.12725 | D46: =D45/D42 -> 2.1854281 | E46: =E45/E42 -> 1.8798203 | F46: =F45/F42 -> 5.560091 | G46: =G45/G42 -> 4.8280457 | H46: =H45/H42 -> 2.9552672 | I46: =I45/I42 -> 10.129541 | J46: =J45/J42 -> 6.3981508 | ... L46: =L45/L42 -> 0
B48: Retained Earnings | C48: =(1-C46) -> -4.12725 | D48: =(1-D46) -> -1.1854281 | E48: =(1-E46) -> -0.87982034 | F48: =(1-F46) -> -4.560091 | G48: =(1-G46) -> -3.8280457 | H48: =(1-H46) -> -1.9552672 | I48: =(1-I46) -> -9.1295411 | J48: =(1-J46) -> -5.3981508 | ... L48: =(1-L46) -> 1
B50: Balance Sheet
B51: ='Data Sheet'!A57 -> Equity Share Capital | C51: ='Data Sheet'!B57 -> 1144 | D51: ='Data Sheet'!C57 -> 1088 | E51: ='Data Sheet'!D57 -> 2170 | F51: ='Data Sheet'!E57 -> 2122 | G51: ='Data Sheet'!F57 -> 2124 | H51: ='Data Sheet'!G57 -> 2098 | I51: ='Data Sheet'!H57 -> 2069 | ... L51: ='Data Sheet'!K57 -> 2024
B52: ='Data Sheet'!A58 -> Reserves | C52: ='Data Sheet'!B58 -> 67838 | D52: ='Data Sheet'!C58 -> 63835 | E52: ='Data Sheet'!D58 -> 62778 | F52: ='Data Sheet'!E58 -> 63328 | G52: ='Data Sheet'!F58 -> 74227 | H52: ='Data Sheet'!G58 -> 73252 | I52: ='Data Sheet'!H58 -> 73338 | ... L52: ='Data Sheet'!K58 -> 90828
B53: ='Data Sheet'!A59 -> Borrowings | C53: ='Data Sheet'!B59 -> 0 | D53: ='Data Sheet'!C59 -> 0 | E53: ='Data Sheet'!D59 -> 0 | F53: ='Data Sheet'!E59 -> 4633 | G53: ='Data Sheet'!F59 -> 5325 | H53: ='Data Sheet'!G59 -> 5474 | I53: ='Data Sheet'!H59 -> 8299 | ... L53: ='Data Sheet'!K59 -> 9176
B54: ='Data Sheet'!A60 -> Other Liabilities | C54: ='Data Sheet'!B60 -> 14166 | D54: ='Data Sheet'!C60 -> 14426 | E54: ='Data Sheet'!D60 -> 19118 | F54: ='Data Sheet'!E60 -> 21717 | G54: ='Data Sheet'!F60 -> 25835 | H54: ='Data Sheet'!G60 -> 35905 | I54: ='Data Sheet'!H60 -> 40890 | ... L54: ='Data Sheet'!K60 -> 52260
B55: Total Liabilities | C55: =SUM(C51:C54) -> 83148 | D55: =SUM(D51:D54) -> 79349 | E55: =SUM(E51:E54) -> 84066 | F55: =SUM(F51:F54) -> 91800 | G55: =SUM(G51:G54) -> 107511 | H55: =SUM(H51:H54) -> 116729 | I55: =SUM(I51:I54) -> 124596 | J55: =SUM(J51:J54) -> 136020 | ... L55: =SUM(L51:L54) -> 154288
B57: Fixed Asset Net Block | C57: ='Data Sheet'!B62 -> 14179 | D57: ='Data Sheet'!C62 -> 12574 | E57: ='Data Sheet'!D62 -> 15710 | F57: ='Data Sheet'!E62 -> 23789 | G57: ='Data Sheet'!F62 -> 25505 | H57: ='Data Sheet'!G62 -> 25800 | I57: ='Data Sheet'!H62 -> 29225 | J57: ='Data Sheet'!I62 -> 27622 | ... L57: ='Data Sheet'!K62 -> 33770
B58: ='Data Sheet'!A63 -> Capital Work in Progress | C58: ='Data Sheet'!B63 -> 1365 | D58: ='Data Sheet'!C63 -> 1606 | E58: ='Data Sheet'!D63 -> 1388 | F58: ='Data Sheet'!E63 -> 954 | G58: ='Data Sheet'!F63 -> 922 | H58: ='Data Sheet'!G63 -> 416 | I58: ='Data Sheet'!H63 -> 288 | ... L58: ='Data Sheet'!K63 -> 526
B59: ='Data Sheet'!A64 -> Investments | C59: ='Data Sheet'!B64 -> 16423 | D59: ='Data Sheet'!C64 -> 12163 | E59: ='Data Sheet'!D64 -> 11261 | F59: ='Data Sheet'!E64 -> 8792 | G59: ='Data Sheet'!F64 -> 14205 | H59: ='Data Sheet'!G64 -> 20324 | I59: ='Data Sheet'!H64 -> 19478 | ... L59: ='Data Sheet'!K64 -> 21880
...

Sheet Ratio Analysis
B2: ="Ratio Analysis - "&'Data Sheet'!$B$1 -> Ratio Analysis - Infosys Ltd
B3: Years | C3: ='Data Sheet'!B56 -> 42795 | D3: ='Data Sheet'!C56 -> 43160 | E3: ='Data Sheet'!D56 -> 43525 | F3: ='Data Sheet'!E56 -> 43891 | G3: ='Data Sheet'!F56 -> 44256 | H3: ='Data Sheet'!G56 -> 44621 | I3: ='Data Sheet'!H56 -> 44986 | J3: ='Data Sheet'!I56 -> 45352 | ... L3: ='Data Sheet'!K56 -> 46082 | M3: Trend | N3: Mean | O3: Median
B5: SalesGrowth | D5: =IFERROR('Historical FS'!D8,0) -> 0.1723292 | E5: =IFERROR('Historical FS'!E8,0) -> 0.098167523 | F5: =IFERROR('Historical FS'!F8,0) -> 0.10662951 | G5: =IFERROR('Historical FS'!G8,0) -> 0.21069552 | H5: =IFERROR('Historical FS'!H8,0) -> 0.20655864 | I5: =IFERROR('Historical FS'!I8,0) -> 0.047033734 | J5: =IFERROR('Historical FS'!J8,0) -> 0.060649444 | K5: =IFERROR('Historical FS'!K8,0) -> 0.096079514 | L5: =IFERROR('Historical FS'!L8,0) -> 0.03320459 | N5: =IFERROR(AVERAGE(D5:L5),0) -> 0.11459419 | O5: =IFERROR(MEDIAN(D5:L5),0) -> 0.098167523
