Workbook
Name UPDATE: '[1]Data Sheet'!$E$1
Name UPDATE: 'Data Sheet'!$E$1

Sheet AI Valuation Summary
A1: MAHINDRA & MAHINDRA LTD (M&M) - Institutional Valuation
A4: Current Price | B4: Intrinsic Value | C4: Margin of Safety | D4: Verdict | E4: WACC | F4: Altman Z-Score | G4: DuPont ROE
A5: =DCF!D44 -> 3055 | B5: =DCF!D42 -> 917.42829 | C5: =(B5-A5)/A5 -> -0.69969614 | D5: =IF(C5>0.15,"UNDERVALUED / BUY",IF(C5<-0.15,"OVERVALUED / SELL","FAIRLY VALUED / HOLD")) -> OVERVALUED / SELL | E5: =DCF!D20 -> 0.11887681 | F5: ='Altman''s Z Score'!I89 -> 3.1701491 | G5: ='Dupont Analysis'!I78 -> 0.21890723
B7: KEY VALUATION PARAMETERS & LIVE MODEL INPUTS
B8: Discount Rate (WACC) | C8: =WACC!K46 -> 0.11887681 | D8: 0
B9: Cost of Equity (Ke) | C9: =WACC!K29 -> 0.13579955 | D9: 0
B10: Risk-Free Rate (Rf) | C10: =WACC!K26 -> 0.07 | D10: 0
B11: Equity Risk Premium (ERP) | C11: =WACC!K27 -> 0.065 | D11: 0
B12: Levered Beta | C12: =WACC!K28 -> 1.0123008 | D12: 0
B13: Terminal Growth Rate | C13: =DCF!D19 -> 0.04 | D13: 0
B14: Cost of Debt (Kd) | C14: =WACC!K39 -> 0 | D14: 0
B15: Cash & Liquid Investments | C15: ='Data Sheet'!K69 -> 31979 | D15: #,##0.00
B16: Total Debt & Borrowings | C16: ='Data Sheet'!K59 -> 136936 | D16: #,##0.00
B17: Shares Outstanding | C17: ='Data Sheet'!K70/10000000 -> 111.8 | D17: #,##0.00
B18: Sector Median EV/Revenue | C18: =Comp_Valuation!O25 -> 3.0308712 | D18: 0.00"x"
B19: Sector Median EV/EBITDA | C19: =Comp_Valuation!P25 -> 20.20578 | D19: 0.00"x"
A20: 5-Year Discounted Cash Flow (DCF) Schedule (Amounts in ₹ Cr) | B20: Sector Median P/E | C20: =Comp_Valuation!Q25 -> 41.122955 | D20: 0.00"x"
A21: Year | B21: EBIT | C21: NOPAT | D21: Reinvest Rate | E21: FCFF | F21: Discount Factor | G21: PV of FCFF
A22: Year 1 | B22: =DCF!I8 -> 36584.352 | C22: =DCF!I10 -> 25609.046 | D22: =DCF!I11 -> 0.85 | E22: =DCF!I12 -> 3841.357 | F22: =DCF!I14 -> 0.94538534 | G22: =DCF!I16 -> 3631.5626
A23: Year 2 | B23: =DCF!J8 -> 38486.738 | C23: =DCF!J10 -> 26940.717 | D23: =DCF!J11 -> 0.7216207 | E23: =DCF!J12 -> 7499.738 | F23: =DCF!J14 -> 0.8449414 | G23: =DCF!J16 -> 6336.8391
A24: Year 3 | B24: =DCF!K8 -> 40488.049 | C24: =DCF!K10 -> 28341.634 | D24: =DCF!K11 -> 0.59324139 | E24: =DCF!K12 -> 11528.204 | F24: =DCF!K14 -> 0.75516929 | G24: =DCF!K16 -> 8705.7453
A25: Year 4 | B25: =DCF!L8 -> 42593.427 | C25: =DCF!L10 -> 29815.399 | D25: =DCF!L11 -> 0.46486209 | E25: =DCF!L12 -> 15955.35 | F25: =DCF!L14 -> 0.67493515 | G25: =DCF!L16 -> 10768.827
A26: Year 5 | B26: =DCF!M8 -> 44808.285 | C26: =DCF!M10 -> 31365.8 | D26: =DCF!M11 -> 0.33648278 | E26: =DCF!M12 -> 20811.748 | F26: =DCF!M14 -> 0.60322561 | G26: =DCF!M16 -> 12554.18
B28: Enterprise to Equity Value Bridge
B29: PV of 5-Year FCFFs | C29: =DCF!D33 -> 41997.153 | D29: ₹ Cr
B30: Terminal Value | C30: =DCF!D29 -> 274405.34 | D30: ₹ Cr
B31: PV of Terminal Value | C31: =DCF!D34 -> 165528.33 | D31: ₹ Cr
B32: Enterprise Value (Operating Assets) | C32: =DCF!D35 -> 207525.48 | D32: ₹ Cr
B33: Add: Estimated Cash & Liquid Assets | C33: =DCF!D37 -> 31979 | D33: ₹ Cr
B34: Less: Total Debt & Borrowings | C34: =DCF!D38 -> 136936 | D34: ₹ Cr
B35: Net Equity Value | C35: =DCF!D39 -> 102568.48 | D35: ₹ Cr
B36: Shares Outstanding | C36: =DCF!D40 -> 111.8 | D36: Cr shares
B37: Intrinsic Value per Share | C37: =DCF!D42 -> 917.42829 | D37: ₹
B38: Current Market Price | C38: =DCF!D44 -> 3055 | D38: ₹
B39: Margin of Safety / Discount | C39: =(C37-C38)/C38 -> -0.69969614 | D39: %

Sheet Profit & Loss
A1: ='Data Sheet'!B1 -> MAHINDRA & MAHINDRA LTD | H1: =UPDATE | M1: SCREENER.IN
A3: Narration | B3: ='Data Sheet'!B16 -> 42795 | C3: ='Data Sheet'!C16 -> 43160 | D3: ='Data Sheet'!D16 -> 43525 | E3: ='Data Sheet'!E16 -> 43891 | F3: ='Data Sheet'!F16 -> 44256 | G3: ='Data Sheet'!G16 -> 44621 | H3: ='Data Sheet'!H16 -> 44986 | I3: ='Data Sheet'!I16 -> 45352 | ... K3: ='Data Sheet'!K16 -> 46082 | L3: Trailing | M3: Best Case | N3: Worst Case
A4: Sales | B4: ='Data Sheet'!B17 -> 83773 | C4: ='Data Sheet'!C17 -> 92094 | D4: ='Data Sheet'!D17 -> 104721 | E4: ='Data Sheet'!E17 -> 75382 | F4: ='Data Sheet'!F17 -> 74278 | G4: ='Data Sheet'!G17 -> 90171 | H4: ='Data Sheet'!H17 -> 121362 | I4: ='Data Sheet'!I17 -> 139078 | ... K4: ='Data Sheet'!K17 -> 198639 | L4: =SUM(Quarters!H4:K4) -> 211376 | M4: =$K4+M23*K4 -> 247831.19 | N4: =$K4+N23*L4 -> 218882.09
A5: Expenses | B5: =SUM('Data Sheet'!B18,'Data Sheet'!B20:B24, -1*'Data Sheet'!B19) -> 72882.51 | C5: =SUM('Data Sheet'!C18,'Data Sheet'!C20:C24, -1*'Data Sheet'!C19) -> 79200.84 | D5: =SUM('Data Sheet'!D18,'Data Sheet'!D20:D24, -1*'Data Sheet'!D19) -> 89012.85 | E5: =SUM('Data Sheet'!E18,'Data Sheet'!E20:E24, -1*'Data Sheet'!E19) -> 65582.34 | F5: =SUM('Data Sheet'!F18,'Data Sheet'!F20:F24, -1*'Data Sheet'!F19) -> 63136.3 | G5: =SUM('Data Sheet'!G18,'Data Sheet'!G20:G24, -1*'Data Sheet'!G19) -> 74841.93 | H5: =SUM('Data Sheet'!H18,'Data Sheet'!H20:H24, -1*'Data Sheet'!H19) -> 100730.46 | I5: =SUM('Data Sheet'!I18,'Data Sheet'!I20:I24, -1*'Data Sheet'!I19) -> 114043.96 | ... K5: =SUM('Data Sheet'!K18,'Data Sheet'!K20:K24, -1*'Data Sheet'!K19) -> 160897.59 | L5: =SUM(Quarters!H5:K5) -> 171320 | M5: =M4-M6 -> 200869.24 | N5: =N4-N6 -> 182472
A6: Operating Profit | B6: =B4-B5 -> 10890.49 | C6: =C4-C5 -> 12893.16 | D6: =D4-D5 -> 15708.15 | E6: =E4-E5 -> 9799.66 | F6: =F4-F5 -> 11141.7 | G6: =G4-G5 -> 15329.07 | H6: =H4-H5 -> 20631.54 | I6: =I4-I5 -> 25034.04 | ... K6: =K4-K5 -> 37741.41 | L6: =SUM(Quarters!H6:K6) -> 40054 | M6: =M4*M24 -> 46961.957 | N6: =N4*N24 -> 36410.088
A7: Other Income | B7: ='Data Sheet'!B25 -> 2077 | C7: ='Data Sheet'!C25 -> 4366 | D7: ='Data Sheet'!D25 -> 2676 | E7: ='Data Sheet'!E25 -> 885 | F7: ='Data Sheet'!F25 -> 1152 | G7: ='Data Sheet'!G25 -> 3204 | H7: ='Data Sheet'!H25 -> 3922 | I7: ='Data Sheet'!I25 -> 3298 | ... K7: ='Data Sheet'!K25 -> 5118 | L7: =SUM(Quarters!H7:K7) -> 4368 | M7: 0 | N7: 0
A8: Depreciation | B8: ='Data Sheet'!B26 -> 2813 | C8: ='Data Sheet'!C26 -> 3280 | D8: ='Data Sheet'!D26 -> 3991 | E8: ='Data Sheet'!E26 -> 3367 | F8: ='Data Sheet'!F26 -> 3378 | G8: ='Data Sheet'!G26 -> 3508 | H8: ='Data Sheet'!H26 -> 4357 | I8: ='Data Sheet'!I26 -> 4724 | ... K8: ='Data Sheet'!K26 -> 7322 | L8: =SUM(Quarters!H8:K8) -> 7535 | M8: =+$L8 -> 7535 | N8: =+$L8 -> 7535
A9: Interest | B9: ='Data Sheet'!B27 -> 3648 | C9: ='Data Sheet'!C27 -> 3987 | D9: ='Data Sheet'!D27 -> 5021 | E9: ='Data Sheet'!E27 -> 6021 | F9: ='Data Sheet'!F27 -> 6102 | G9: ='Data Sheet'!G27 -> 5018 | H9: ='Data Sheet'!H27 -> 5830 | I9: ='Data Sheet'!I27 -> 7488 | ... K9: ='Data Sheet'!K27 -> 9591 | L9: =SUM(Quarters!H9:K9) -> 9719 | M9: =+$L9 -> 9719 | N9: =+$L9 -> 9719
A10: Profit before tax | B10: ='Data Sheet'!B28 -> 6350 | C10: ='Data Sheet'!C28 -> 10326 | D10: ='Data Sheet'!D28 -> 8871 | E10: ='Data Sheet'!E28 -> 1655 | F10: ='Data Sheet'!F28 -> 3158 | G10: ='Data Sheet'!G28 -> 9362 | H10: ='Data Sheet'!H28 -> 14060 | I10: ='Data Sheet'!I28 -> 15978 | ... K10: ='Data Sheet'!K28 -> 25185 | L10: =SUM(Quarters!H10:K10) -> 27169 | M10: =M6+M7-SUM(M8:M9) -> 29707.957 | N10: =N6+N7-SUM(N8:N9) -> 19156.088
A11: Tax | B11: ='Data Sheet'!B29 -> 6350 | C11: ='Data Sheet'!C29 -> 10326 | D11: ='Data Sheet'!D29 -> 8871 | E11: ='Data Sheet'!E29 -> 1655 | F11: ='Data Sheet'!F29 -> 3158 | G11: ='Data Sheet'!G29 -> 9362 | H11: ='Data Sheet'!H29 -> 14060 | I11: ='Data Sheet'!I29 -> 15978 | ... K11: ='Data Sheet'!K29 -> 25185 | L11: =SUM(Quarters!H11:K11) -> 27169 | M11: =IF($L10>0,$L11/$L10,0) -> 1 | N11: =IF($L10>0,$L11/$L10,0) -> 1
A12: Net profit | B12: ='Data Sheet'!B30 -> 4051 | C12: ='Data Sheet'!C30 -> 7958 | D12: ='Data Sheet'!D30 -> 6017 | E12: ='Data Sheet'!E30 -> -321 | F12: ='Data Sheet'!F30 -> 1512 | G12: ='Data Sheet'!G30 -> 7253 | H12: ='Data Sheet'!H30 -> 11374 | I12: ='Data Sheet'!I30 -> 12270 | ... K12: ='Data Sheet'!K30 -> 18622 | L12: =SUM(Quarters!H12:K12) -> 20243 | M12: =M10-M11*M10 -> 0 | N12: =N10-N11*N10 -> 0
A13: EPS | B13: =IF('Data Sheet'!B93>0,B12/'Data Sheet'!B93,0) -> 30.265222 | C13: =IF('Data Sheet'!C93>0,C12/'Data Sheet'!C93,0) -> 59.454613 | D13: =IF('Data Sheet'!D93>0,D12/'Data Sheet'!D93,0) -> 44.953306 | E13: =IF('Data Sheet'!E93>0,E12/'Data Sheet'!E93,0) -> -2.3982069 | F13: =IF('Data Sheet'!F93>0,F12/'Data Sheet'!F93,0) -> 11.296227 | G13: =IF('Data Sheet'!G93>0,G12/'Data Sheet'!G93,0) -> 54.187523 | H13: =IF('Data Sheet'!H93>0,H12/'Data Sheet'!H93,0) -> 84.975719 | I13: =IF('Data Sheet'!I93>0,I12/'Data Sheet'!I93,0) -> 91.66978 | ... K13: =IF('Data Sheet'!K93>0,K12/'Data Sheet'!K93,0) -> 139.12589 | L13: =IF('Data Sheet'!$B6>0,'Profit & Loss'!L12/'Data Sheet'!$B6,0) -> 162.82662 | M13: =IF('Data Sheet'!$B6>0,'Profit & Loss'!M12/'Data Sheet'!$B6,0) -> 0 | N13: =IF('Data Sheet'!$B6>0,'Profit & Loss'!N12/'Data Sheet'!$B6,0) -> 0
A14: Price to earning | B14: =IF(B15>0,B15/B13,"") -> 21.841241 | C14: =IF(C15>0,C15/C13,"") -> 12.321163 | D14: =IF(D15>0,D15/D13,"") -> 14.452775 | E14: =IF(E15>0,E15/E13,"") -> -190.57988 | F14: =IF(F15>0,F15/F13,"") -> 71.386667 | G14: =IF(G15>0,G15/G13,"") -> 13.514181 | H14: =IF(H15>0,H15/H13,"") -> 14.92897 | I14: =IF(I15>0,I15/I13,"") -> 21.382183 | ... K14: =IF(K15>0,K15/K13,"") -> 24.419611 | L14: =IF(L13>0,L15/L13,0) -> 18.762288 | M14: =M25 -> 22.28782 | N14: =N25 -> 18.762288
A15: Price | B15: ='Data Sheet'!B90 -> 661.03 | C15: ='Data Sheet'!C90 -> 732.55 | D15: ='Data Sheet'!D90 -> 649.7 | E15: ='Data Sheet'!E90 -> 457.05 | F15: ='Data Sheet'!F90 -> 806.4 | G15: ='Data Sheet'!G90 -> 732.3 | H15: ='Data Sheet'!H90 -> 1268.6 | I15: ='Data Sheet'!I90 -> 1960.1 | ... K15: ='Data Sheet'!K90 -> 3397.4 | L15: ='Data Sheet'!B8 -> 3055 | M15: =M13*M14 -> 0 | N15: =N13*N14 -> 0
A17: RATIOS:
A18: Dividend Payout | B18: =IF('Data Sheet'!B30>0, 'Data Sheet'!B31/'Data Sheet'!B30, 0) -> 0.22 | C18: =IF('Data Sheet'!C30>0, 'Data Sheet'!C31/'Data Sheet'!C30, 0) -> 0.11 | D18: =IF('Data Sheet'!D30>0, 'Data Sheet'!D31/'Data Sheet'!D30, 0) -> 0.17 | E18: =IF('Data Sheet'!E30>0, 'Data Sheet'!E31/'Data Sheet'!E30, 0) -> 0 | F18: =IF('Data Sheet'!F30>0, 'Data Sheet'!F31/'Data Sheet'!F30, 0) -> 0.54 | G18: =IF('Data Sheet'!G30>0, 'Data Sheet'!G31/'Data Sheet'!G30, 0) -> 0.2 | H18: =IF('Data Sheet'!H30>0, 'Data Sheet'!H31/'Data Sheet'!H30, 0) -> 0.18 | I18: =IF('Data Sheet'!I30>0, 'Data Sheet'!I31/'Data Sheet'!I30, 0) -> 0.21 | ... K18: =IF('Data Sheet'!K30>0, 'Data Sheet'!K31/'Data Sheet'!K30, 0) -> 0.22
A19: OPM | B19: =IF(B6>0,B6/B4,0) -> 0.13 | C19: =IF(C6>0,C6/C4,0) -> 0.14 | D19: =IF(D6>0,D6/D4,0) -> 0.15 | E19: =IF(E6>0,E6/E4,0) -> 0.13 | F19: =IF(F6>0,F6/F4,0) -> 0.15 | G19: =IF(G6>0,G6/G4,0) -> 0.17 | H19: =IF(H6>0,H6/H4,0) -> 0.17 | I19: =IF(I6>0,I6/I4,0) -> 0.18 | ... L19: =IF(L6>0,L6/L4,0) -> 0.18949171
G22: TRENDS: | H22: 10 YEARS | I22: 7 YEARS | J22: 5 YEARS | K22: 3 YEARS | L22: RECENT | M22: BEST | N22: WORST
G23: Sales Growth | H23: =IF(B4=0,"",POWER($K4/B4,1/9)-1) -> 0.10068303 | I23: =IF(D4=0,"",POWER($K4/D4,1/7)-1) -> 0.09576816 | J23: =IF(F4=0,"",POWER($K4/F4,1/5)-1) -> 0.21742121 | K23: =IF(H4=0,"",POWER($K4/H4, 1/3)-1) -> 0.1784937 | L23: =IF(ISERROR(MAX(IF(J4=0,"",(K4-J4)/J4),IF(K4=0,"",(L4-K4)/K4))),"",MAX(IF(J4=0,"",(K4-J4)/J4),IF(K4=0,"",(L4-K4)/K4))) -> 0.24764621 | M23: =MAX(K23:L23) -> 0.24764621 | N23: =MIN(H23:L23) -> 0.09576816
G24: OPM | H24: =IF(SUM(B4:$K$4)=0,"",SUMPRODUCT(B19:$K$19,B4:$K$4)/SUM(B4:$K$4)) -> 0.16634567 | I24: =IF(SUM(E4:$K$4)=0,"",SUMPRODUCT(E19:$K$19,E4:$K$4)/SUM(E4:$K$4)) -> 0.17471605 | J24: =IF(SUM(G4:$K$4)=0,"",SUMPRODUCT(G19:$K$19,G4:$K$4)/SUM(G4:$K$4)) -> 0.18206528 | K24: =IF(SUM(I4:$K$4)=0, "", SUMPRODUCT(I19:$K$19,I4:$K$4)/SUM(I4:$K$4)) -> 0.18720124 | L24: =L19 -> 0.18949171 | M24: =MAX(K24:L24) -> 0.18949171 | N24: =MIN(H24:L24) -> 0.16634567
G25: Price to Earning | H25: =IF(ISERROR(AVERAGEIF(B14:$L14,">0")),"",AVERAGEIF(B14:$L14,">0")) -> 23.759628 | I25: =IF(ISERROR(AVERAGEIF(E14:$L14,">0")),"",AVERAGEIF(E14:$L14,">0")) -> 26.9973 | J25: =IF(ISERROR(AVERAGEIF(G14:$L14,">0")),"",AVERAGEIF(G14:$L14,">0")) -> 19.599072 | K25: =IF(ISERROR(AVERAGEIF(I14:$L14,">0")),"",AVERAGEIF(I14:$L14,">0")) -> 22.28782 | L25: =L14 -> 18.762288 | M25: =MAX(K25:L25) -> 22.28782 | N25: =MIN(H25:L25) -> 18.762288

Sheet Quarters
A1: ='Profit & Loss'!A1 -> MAHINDRA & MAHINDRA LTD | E1: =UPDATE | J1: SCREENER.IN
A3: Narration | B3: ='Data Sheet'!B41 -> 45352 | C3: ='Data Sheet'!C41 -> 45444 | D3: ='Data Sheet'!D41 -> 45536 | E3: ='Data Sheet'!E41 -> 45627 | F3: ='Data Sheet'!F41 -> 45717 | G3: ='Data Sheet'!G41 -> 45809 | H3: ='Data Sheet'!H41 -> 45901 | I3: ='Data Sheet'!I41 -> 45992 | ... K3: ='Data Sheet'!K41 -> 46174
A4: Sales | B4: ='Data Sheet'!B42 -> 35452 | C4: ='Data Sheet'!C42 -> 37218 | D4: ='Data Sheet'!D42 -> 37924 | E4: ='Data Sheet'!E42 -> 41470 | F4: ='Data Sheet'!F42 -> 42599 | G4: ='Data Sheet'!G42 -> 45529 | H4: ='Data Sheet'!H42 -> 46106 | I4: ='Data Sheet'!I42 -> 52100 | ... K4: ='Data Sheet'!K42 -> 58188
A5: Expenses | B5: ='Data Sheet'!B43 -> 28848 | C5: ='Data Sheet'!C43 -> 29975 | D5: ='Data Sheet'!D43 -> 30790 | E5: ='Data Sheet'!E43 -> 33239 | F5: ='Data Sheet'!F43 -> 34658 | G5: ='Data Sheet'!G43 -> 37117 | H5: ='Data Sheet'!H43 -> 37166 | I5: ='Data Sheet'!I43 -> 41939 | ... K5: ='Data Sheet'!K43 -> 47360
A6: Operating Profit | B6: ='Data Sheet'!B50 -> 6604 | C6: ='Data Sheet'!C50 -> 7243 | D6: ='Data Sheet'!D50 -> 7133 | E6: ='Data Sheet'!E50 -> 8231 | F6: ='Data Sheet'!F50 -> 7942 | G6: ='Data Sheet'!G50 -> 8412 | H6: ='Data Sheet'!H50 -> 8940 | I6: ='Data Sheet'!I50 -> 10160 | ... K6: ='Data Sheet'!K50 -> 10827
A7: Other Income | B7: ='Data Sheet'!B44 -> 750 | C7: ='Data Sheet'!C44 -> 733 | D7: ='Data Sheet'!D44 -> 1126 | E7: ='Data Sheet'!E44 -> 719 | F7: ='Data Sheet'!F44 -> 1110 | G7: ='Data Sheet'!G44 -> 1210 | H7: ='Data Sheet'!H44 -> 1134 | I7: ='Data Sheet'!I44 -> 976 | ... K7: ='Data Sheet'!K44 -> 1121
A8: Depreciation | B8: ='Data Sheet'!B45 -> 1335 | C8: ='Data Sheet'!C45 -> 1248 | D8: ='Data Sheet'!D45 -> 1302 | E8: ='Data Sheet'!E45 -> 1495 | F8: ='Data Sheet'!F45 -> 2029 | G8: ='Data Sheet'!G45 -> 1548 | H8: ='Data Sheet'!H45 -> 1669 | I8: ='Data Sheet'!I45 -> 2163 | ... K8: ='Data Sheet'!K45 -> 1760
A9: Interest | B9: ='Data Sheet'!B46 -> 1989 | C9: ='Data Sheet'!C46 -> 2108 | D9: ='Data Sheet'!D46 -> 2217 | E9: ='Data Sheet'!E46 -> 2362 | F9: ='Data Sheet'!F46 -> 2397 | G9: ='Data Sheet'!G46 -> 2431 | H9: ='Data Sheet'!H46 -> 2347 | I9: ='Data Sheet'!I46 -> 2405 | ... K9: ='Data Sheet'!K46 -> 2560
A10: Profit before tax | B10: ='Data Sheet'!B47 -> 4030 | C10: ='Data Sheet'!C47 -> 4621 | D10: ='Data Sheet'!D47 -> 4740 | E10: ='Data Sheet'!E47 -> 5092 | F10: ='Data Sheet'!F47 -> 4627 | G10: ='Data Sheet'!G47 -> 5644 | H10: ='Data Sheet'!H47 -> 6058 | I10: ='Data Sheet'!I47 -> 6569 | ... K10: ='Data Sheet'!K47 -> 7628
A11: Tax | B11: ='Data Sheet'!B48 -> 4030 | C11: ='Data Sheet'!C48 -> 4621 | D11: ='Data Sheet'!D48 -> 4740 | E11: ='Data Sheet'!E48 -> 5092 | F11: ='Data Sheet'!F48 -> 4627 | G11: ='Data Sheet'!G48 -> 5644 | H11: ='Data Sheet'!H48 -> 6058 | I11: ='Data Sheet'!I48 -> 6569 | ... K11: ='Data Sheet'!K48 -> 7628
A12: Net profit | B12: ='Data Sheet'!B49 -> 3125 | C12: ='Data Sheet'!C49 -> 3546 | D12: ='Data Sheet'!D49 -> 3361 | E12: ='Data Sheet'!E49 -> 3624 | F12: ='Data Sheet'!F49 -> 3542 | G12: ='Data Sheet'!G49 -> 4377 | H12: ='Data Sheet'!H49 -> 3964 | I12: ='Data Sheet'!I49 -> 5021 | ... K12: ='Data Sheet'!K49 -> 5998
A14: OPM | B14: =IF(B4>0,B6/B4,"") -> 0.18628004 | C14: =IF(C4>0,C6/C4,"") -> 0.19461013 | D14: =IF(D4>0,D6/D4,"") -> 0.1880867 | E14: =IF(E4>0,E6/E4,"") -> 0.19848083 | F14: =IF(F4>0,F6/F4,"") -> 0.1864363 | G14: =IF(G4>0,G6/G4,"") -> 0.18476136 | H14: =IF(H4>0,H6/H4,"") -> 0.19390101 | I14: =IF(I4>0,I6/I4,"") -> 0.1950096 | ... K14: =IF(K4>0,K6/K4,"") -> 0.18606929

Sheet Balance Sheet
A1: ='Profit & Loss'!A1 -> MAHINDRA & MAHINDRA LTD | E1: =UPDATE | J1: SCREENER.IN
A3: Narration | B3: ='Data Sheet'!B56 -> 42795 | C3: ='Data Sheet'!C56 -> 43160 | D3: ='Data Sheet'!D56 -> 43525 | E3: ='Data Sheet'!E56 -> 43891 | F3: ='Data Sheet'!F56 -> 44256 | G3: ='Data Sheet'!G56 -> 44621 | H3: ='Data Sheet'!H56 -> 44986 | I3: ='Data Sheet'!I56 -> 45352 | ... K3: ='Data Sheet'!K56 -> 46082
A4: Equity Share Capital | B4: ='Data Sheet'!B57 -> 311 | C4: ='Data Sheet'!C57 -> 543 | D4: ='Data Sheet'!D57 -> 544 | E4: ='Data Sheet'!E57 -> 554 | F4: ='Data Sheet'!F57 -> 555 | G4: ='Data Sheet'!G57 -> 556 | H4: ='Data Sheet'!H57 -> 557 | I4: ='Data Sheet'!I57 -> 557 | ... K4: ='Data Sheet'!K57 -> 559
A5: Reserves | B5: ='Data Sheet'!B58 -> 29467 | C5: ='Data Sheet'!C58 -> 36232 | D5: ='Data Sheet'!D58 -> 39439 | E5: ='Data Sheet'!E58 -> 39415 | F5: ='Data Sheet'!F58 -> 41027 | G5: ='Data Sheet'!G58 -> 46567 | H5: ='Data Sheet'!H58 -> 55809 | I5: ='Data Sheet'!I58 -> 65633 | ... K5: ='Data Sheet'!K58 -> 92538
A6: Borrowings | B6: ='Data Sheet'!B59 -> 48762 | C6: ='Data Sheet'!C59 -> 55898 | D6: ='Data Sheet'!D59 -> 70848 | E6: ='Data Sheet'!E59 -> 82092 | F6: ='Data Sheet'!F59 -> 80625 | G6: ='Data Sheet'!G59 -> 77605 | H6: ='Data Sheet'!H59 -> 92647 | I6: ='Data Sheet'!I59 -> 108647 | ... K6: ='Data Sheet'!K59 -> 136936
A7: Other Liabilities | B7: ='Data Sheet'!B60 -> 35296 | C7: ='Data Sheet'!C60 -> 43696 | D7: ='Data Sheet'!D60 -> 51057 | E7: ='Data Sheet'!E60 -> 43655 | F7: ='Data Sheet'!F60 -> 42762 | G7: ='Data Sheet'!G60 -> 47661 | H7: ='Data Sheet'!H60 -> 55270 | I7: ='Data Sheet'!I60 -> 59884 | ... K7: ='Data Sheet'!K60 -> 86021
A8: Total | B8: ='Data Sheet'!B61 -> 113835 | C8: ='Data Sheet'!C61 -> 136369 | D8: ='Data Sheet'!D61 -> 161889 | E8: ='Data Sheet'!E61 -> 165716 | F8: ='Data Sheet'!F61 -> 164968 | G8: ='Data Sheet'!G61 -> 172388 | H8: ='Data Sheet'!H61 -> 204283 | I8: ='Data Sheet'!I61 -> 234722 | ... K8: ='Data Sheet'!K61 -> 316054
A10: Net Block | B10: ='Data Sheet'!B62 -> 20989 | C10: ='Data Sheet'!C62 -> 26182 | D10: ='Data Sheet'!D62 -> 28983 | E10: ='Data Sheet'!E62 -> 29689 | F10: ='Data Sheet'!F62 -> 21380 | G10: ='Data Sheet'!G62 -> 26018 | H10: ='Data Sheet'!H62 -> 27140 | I10: ='Data Sheet'!I62 -> 28129 | ... K10: ='Data Sheet'!K62 -> 38459
A11: Capital Work in Progress | B11: ='Data Sheet'!B63 -> 4279 | C11: ='Data Sheet'!C63 -> 4269 | D11: ='Data Sheet'!D63 -> 4760 | E11: ='Data Sheet'!E63 -> 6856 | F11: ='Data Sheet'!F63 -> 7873 | G11: ='Data Sheet'!G63 -> 6703 | H11: ='Data Sheet'!H63 -> 3969 | I11: ='Data Sheet'!I63 -> 8039 | ... K11: ='Data Sheet'!K63 -> 7740
A12: Investments | B12: ='Data Sheet'!B64 -> 14662 | C12: ='Data Sheet'!C64 -> 16018 | D12: ='Data Sheet'!D64 -> 18268 | E12: ='Data Sheet'!E64 -> 19210 | F12: ='Data Sheet'!F64 -> 28778 | G12: ='Data Sheet'!G64 -> 30060 | H12: ='Data Sheet'!H64 -> 35272 | I12: ='Data Sheet'!I64 -> 35208 | ... K12: ='Data Sheet'!K64 -> 40324
A13: Other Assets | B13: ='Data Sheet'!B65 -> 73905 | C13: ='Data Sheet'!C65 -> 89900 | D13: ='Data Sheet'!D65 -> 109878 | E13: ='Data Sheet'!E65 -> 109960 | F13: ='Data Sheet'!F65 -> 106938 | G13: ='Data Sheet'!G65 -> 109607 | H13: ='Data Sheet'!H65 -> 137902 | I13: ='Data Sheet'!I65 -> 163345 | ... K13: ='Data Sheet'!K65 -> 229531
A14: Total | B14: ='Data Sheet'!B66 -> 113835 | C14: ='Data Sheet'!C66 -> 136369 | D14: ='Data Sheet'!D66 -> 161889 | E14: ='Data Sheet'!E66 -> 165716 | F14: ='Data Sheet'!F66 -> 164968 | G14: ='Data Sheet'!G66 -> 172388 | H14: ='Data Sheet'!H66 -> 204283 | I14: ='Data Sheet'!I66 -> 234722 | ... K14: ='Data Sheet'!K66 -> 316054
A16: Working Capital | B16: =B13-B7 -> 38609 | C16: =C13-C7 -> 46204 | D16: =D13-D7 -> 58821 | E16: =E13-E7 -> 66305 | F16: =F13-F7 -> 64176 | G16: =G13-G7 -> 61946 | H16: =H13-H7 -> 82632 | I16: =I13-I7 -> 103461 | ... K16: =K13-K7 -> 143510
A17: Debtors | B17: ='Data Sheet'!B67 -> 7199 | C17: ='Data Sheet'!C67 -> 8490 | D17: ='Data Sheet'!D67 -> 8678 | E17: ='Data Sheet'!E67 -> 6928 | F17: ='Data Sheet'!F67 -> 6008 | G17: ='Data Sheet'!G67 -> 6374 | H17: ='Data Sheet'!H67 -> 7028 | I17: ='Data Sheet'!I67 -> 7459 | ... K17: ='Data Sheet'!K67 -> 9064
A18: Inventory | B18: ='Data Sheet'!B68 -> 8886 | C18: ='Data Sheet'!C68 -> 9336 | D18: ='Data Sheet'!D68 -> 12200 | E18: ='Data Sheet'!E68 -> 11112 | F18: ='Data Sheet'!F68 -> 9615 | G18: ='Data Sheet'!G68 -> 11596 | H18: ='Data Sheet'!H68 -> 16855 | I18: ='Data Sheet'!I68 -> 18590 | ... K18: ='Data Sheet'!K68 -> 22044
A20: Debtor Days | B20: =IF('Profit & Loss'!B4>0,'Balance Sheet'!B17/('Profit & Loss'!B4/365),0) -> 31.366132 | C20: =IF('Profit & Loss'!C4>0,'Balance Sheet'!C17/('Profit & Loss'!C4/365),0) -> 33.648772 | D20: =IF('Profit & Loss'!D4>0,'Balance Sheet'!D17/('Profit & Loss'!D4/365),0) -> 30.246751 | E20: =IF('Profit & Loss'!E4>0,'Balance Sheet'!E17/('Profit & Loss'!E4/365),0) -> 33.545409 | F20: =IF('Profit & Loss'!F4>0,'Balance Sheet'!F17/('Profit & Loss'!F4/365),0) -> 29.523143 | G20: =IF('Profit & Loss'!G4>0,'Balance Sheet'!G17/('Profit & Loss'!G4/365),0) -> 25.801089 | H20: =IF('Profit & Loss'!H4>0,'Balance Sheet'!H17/('Profit & Loss'!H4/365),0) -> 21.136929 | I20: =IF('Profit & Loss'!I4>0,'Balance Sheet'!I17/('Profit & Loss'!I4/365),0) -> 19.575598 | ... K20: =IF('Profit & Loss'!K4>0,'Balance Sheet'!K17/('Profit & Loss'!K4/365),0) -> 16.655138
A21: Inventory Turnover | B21: =IF('Balance Sheet'!B18>0,'Profit & Loss'!B4/'Balance Sheet'!B18,0) -> 9.4275264 | C21: =IF('Balance Sheet'!C18>0,'Profit & Loss'!C4/'Balance Sheet'!C18,0) -> 9.8643959 | D21: =IF('Balance Sheet'!D18>0,'Profit & Loss'!D4/'Balance Sheet'!D18,0) -> 8.5836885 | E21: =IF('Balance Sheet'!E18>0,'Profit & Loss'!E4/'Balance Sheet'!E18,0) -> 6.7838373 | F21: =IF('Balance Sheet'!F18>0,'Profit & Loss'!F4/'Balance Sheet'!F18,0) -> 7.725221 | G21: =IF('Balance Sheet'!G18>0,'Profit & Loss'!G4/'Balance Sheet'!G18,0) -> 7.7760435 | H21: =IF('Balance Sheet'!H18>0,'Profit & Loss'!H4/'Balance Sheet'!H18,0) -> 7.200356 | I21: =IF('Balance Sheet'!I18>0,'Profit & Loss'!I4/'Balance Sheet'!I18,0) -> 7.4813341 | ... K21: =IF('Balance Sheet'!K18>0,'Profit & Loss'!K4/'Balance Sheet'!K18,0) -> 9.0110234
A23: Return on Equity | B23: =IF(SUM('Balance Sheet'!B4:B5)>0,'Profit & Loss'!B12/SUM('Balance Sheet'!B4:B5),"") -> 0.13604003 | C23: =IF(SUM('Balance Sheet'!C4:C5)>0,'Profit & Loss'!C12/SUM('Balance Sheet'!C4:C5),"") -> 0.21639701 | D23: =IF(SUM('Balance Sheet'!D4:D5)>0,'Profit & Loss'!D12/SUM('Balance Sheet'!D4:D5),"") -> 0.15048896 | E23: =IF(SUM('Balance Sheet'!E4:E5)>0,'Profit & Loss'!E12/SUM('Balance Sheet'!E4:E5),"") -> -0.0080312242 | F23: =IF(SUM('Balance Sheet'!F4:F5)>0,'Profit & Loss'!F12/SUM('Balance Sheet'!F4:F5),"") -> 0.036361887 | G23: =IF(SUM('Balance Sheet'!G4:G5)>0,'Profit & Loss'!G12/SUM('Balance Sheet'!G4:G5),"") -> 0.15391635 | H23: =IF(SUM('Balance Sheet'!H4:H5)>0,'Profit & Loss'!H12/SUM('Balance Sheet'!H4:H5),"") -> 0.20178831 | I23: =IF(SUM('Balance Sheet'!I4:I5)>0,'Profit & Loss'!I12/SUM('Balance Sheet'!I4:I5),"") -> 0.18537543 | ... K23: =IF(SUM('Balance Sheet'!K4:K5)>0,'Profit & Loss'!K12/SUM('Balance Sheet'!K4:K5),"") -> 0.20002793
A24: Return on Capital Emp | C24: =IF((B4+B5+B6+C4+C5+C6)>0,('Profit & Loss'!C10+'Profit & Loss'!C9)*2/(B4+B5+B6+C4+C5+C6),"") -> 0.16719525 | D24: =IF((C4+C5+C6+D4+D5+D6)>0,('Profit & Loss'!D10+'Profit & Loss'!D9)*2/(C4+C5+C6+D4+D5+D6),"") -> 0.13652803 | E24: =IF((D4+D5+D6+E4+E5+E6)>0,('Profit & Loss'!E10+'Profit & Loss'!E9)*2/(D4+D5+D6+E4+E5+E6),"") -> 0.065918967 | F24: =IF((E4+E5+E6+F4+F5+F6)>0,('Profit & Loss'!F10+'Profit & Loss'!F9)*2/(E4+E5+E6+F4+F5+F6),"") -> 0.075818363 | G24: =IF((F4+F5+F6+G4+G5+G6)>0,('Profit & Loss'!G10+'Profit & Loss'!G9)*2/(F4+F5+F6+G4+G5+G6),"") -> 0.1164679 | H24: =IF((G4+G5+G6+H4+H5+H6)>0,('Profit & Loss'!H10+'Profit & Loss'!H9)*2/(G4+G5+G6+H4+H5+H6),"") -> 0.14531985 | I24: =IF((H4+H5+H6+I4+I5+I6)>0,('Profit & Loss'!I10+'Profit & Loss'!I9)*2/(H4+H5+H6+I4+I5+I6),"") -> 0.14491894 | J24: =IF((I4+I5+I6+J4+J5+J6)>0,('Profit & Loss'!J10+'Profit & Loss'!J9)*2/(I4+I5+I6+J4+J5+J6),"") -> 0.14787569 | K24: =IF((J4+J5+J6+K4+K5+K6)>0,('Profit & Loss'!K10+'Profit & Loss'!K9)*2/(J4+J5+J6+K4+K5+K6),"") -> 0.15948745

Sheet Cash Flow
A1: ='Balance Sheet'!A1 -> MAHINDRA & MAHINDRA LTD | E1: =UPDATE | J1: SCREENER.IN
A3: Narration | B3: ='Data Sheet'!B81 -> 42795 | C3: ='Data Sheet'!C81 -> 43160 | D3: ='Data Sheet'!D81 -> 43525 | E3: ='Data Sheet'!E81 -> 43891 | F3: ='Data Sheet'!F81 -> 44256 | G3: ='Data Sheet'!G81 -> 44621 | H3: ='Data Sheet'!H81 -> 44986 | I3: ='Data Sheet'!I81 -> 45352 | ... K3: ='Data Sheet'!K81 -> 46082
A4: Cash from Operating Activity | B4: ='Data Sheet'!B82 -> 183 | C4: ='Data Sheet'!C82 -> 682 | D4: ='Data Sheet'!D82 -> -4347 | E4: ='Data Sheet'!E82 -> -1457 | F4: ='Data Sheet'!F82 -> 17909 | G4: ='Data Sheet'!G82 -> 9248 | H4: ='Data Sheet'!H82 -> -7074 | I4: ='Data Sheet'!I82 -> -5630 | ... K4: ='Data Sheet'!K82 -> 11657
A5: Cash from Investing Activity | B5: ='Data Sheet'!B83 -> -5875 | C5: ='Data Sheet'!C83 -> -5467 | D5: ='Data Sheet'!D83 -> -7174 | E5: ='Data Sheet'!E83 -> -6870 | F5: ='Data Sheet'!F83 -> -19686 | G5: ='Data Sheet'!G83 -> -3252 | H5: ='Data Sheet'!H83 -> -8866 | I5: ='Data Sheet'!I83 -> -5615 | ... K5: ='Data Sheet'!K83 -> -17680
A6: Cash from Financing Activity | B6: ='Data Sheet'!B84 -> 6108 | C6: ='Data Sheet'!C84 -> 6314 | D6: ='Data Sheet'!D84 -> 13194 | E6: ='Data Sheet'!E84 -> 6933 | F6: ='Data Sheet'!F84 -> 406 | G6: ='Data Sheet'!G84 -> -5883 | H6: ='Data Sheet'!H84 -> 15946 | I6: ='Data Sheet'!I84 -> 12281 | ... K6: ='Data Sheet'!K84 -> 5391
A7: Net Cash Flow | B7: ='Data Sheet'!B85 -> 416 | C7: ='Data Sheet'!C85 -> 1529 | D7: ='Data Sheet'!D85 -> 1672 | E7: ='Data Sheet'!E85 -> -1394 | F7: ='Data Sheet'!F85 -> -1370 | G7: ='Data Sheet'!G85 -> 113 | H7: ='Data Sheet'!H85 -> 6 | I7: ='Data Sheet'!I85 -> 1037 | ... K7: ='Data Sheet'!K85 -> -632

Sheet Customization
A1: How to use it?
A3: You can customize this workbook as you want.
B4: You can add custom formating, add conditional formating, add your own formulas… do ANYTHING.
B5: Please don't edit the "Data Sheet" only.
A7: After customization, you can upload this back on Screener.
B8: Upload on: | C8: https://www.screener.in/excel/
A10: Download your customized workbooks now onwards.
B11: Now whenever you will "Export to excel" from Screener, it will export your customized file.
A14: TESTING:
B15: This is a testing feature currently.
B16: You can report any formula errors on the worksheet at: support@screener.in

Sheet Common Size Statement
B2: ="Common Size Statement - "&'Data Sheet'!$B$1 -> Common Size Statement - MAHINDRA & MAHINDRA LTD
B4: Particulars | C4: ='Data Sheet'!B$16 -> 42795 | D4: ='Data Sheet'!C$16 -> 43160 | E4: ='Data Sheet'!D$16 -> 43525 | F4: ='Data Sheet'!E$16 -> 43891 | G4: ='Data Sheet'!F$16 -> 44256 | H4: ='Data Sheet'!G$16 -> 44621 | I4: ='Data Sheet'!H$16 -> 44986 | J4: ='Data Sheet'!I$16 -> 45352 | ... L4: ='Data Sheet'!K$16 -> 46082
B6: ='Data Sheet'!A17 -> Sales | C6: ='Data Sheet'!B17/'Data Sheet'!B$17 -> 1 | D6: ='Data Sheet'!C17/'Data Sheet'!C$17 -> 1 | E6: ='Data Sheet'!D17/'Data Sheet'!D$17 -> 1 | F6: ='Data Sheet'!E17/'Data Sheet'!E$17 -> 1 | G6: ='Data Sheet'!F17/'Data Sheet'!F$17 -> 1 | H6: ='Data Sheet'!G17/'Data Sheet'!G$17 -> 1 | I6: ='Data Sheet'!H17/'Data Sheet'!H$17 -> 1 | J6: ='Data Sheet'!I17/'Data Sheet'!I$17 -> 1 | ... L6: ='Data Sheet'!K17/'Data Sheet'!K$17 -> 1
B7: ='Data Sheet'!A18 -> Raw Material Cost | C7: ='Data Sheet'!B18/'Data Sheet'!B$17 -> 0.6 | D7: ='Data Sheet'!C18/'Data Sheet'!C$17 -> 0.58 | E7: ='Data Sheet'!D18/'Data Sheet'!D$17 -> 0.57 | F7: ='Data Sheet'!E18/'Data Sheet'!E$17 -> 0.51 | G7: ='Data Sheet'!F18/'Data Sheet'!F$17 -> 0.52 | H7: ='Data Sheet'!G18/'Data Sheet'!G$17 -> 0.57 | I7: ='Data Sheet'!H18/'Data Sheet'!H$17 -> 0.61 | J7: ='Data Sheet'!I18/'Data Sheet'!I$17 -> 0.6 | ... L7: ='Data Sheet'!K18/'Data Sheet'!K$17 -> 0.62
B8: ='Data Sheet'!A19 -> Change in Inventory | C8: ='Data Sheet'!B19/'Data Sheet'!B$17 -> 0 | D8: ='Data Sheet'!C19/'Data Sheet'!C$17 -> 0 | E8: ='Data Sheet'!D19/'Data Sheet'!D$17 -> 0 | F8: ='Data Sheet'!E19/'Data Sheet'!E$17 -> 0 | G8: ='Data Sheet'!F19/'Data Sheet'!F$17 -> 0 | H8: ='Data Sheet'!G19/'Data Sheet'!G$17 -> 0 | I8: ='Data Sheet'!H19/'Data Sheet'!H$17 -> 0 | J8: ='Data Sheet'!I19/'Data Sheet'!I$17 -> 0 | ... L8: ='Data Sheet'!K19/'Data Sheet'!K$17 -> 0
B9: ='Data Sheet'!A20 -> Power and Fuel | C9: ='Data Sheet'!B20/'Data Sheet'!B$17 -> 0 | D9: ='Data Sheet'!C20/'Data Sheet'!C$17 -> 0 | E9: ='Data Sheet'!D20/'Data Sheet'!D$17 -> 0 | F9: ='Data Sheet'!E20/'Data Sheet'!E$17 -> 0 | G9: ='Data Sheet'!F20/'Data Sheet'!F$17 -> 0 | H9: ='Data Sheet'!G20/'Data Sheet'!G$17 -> 0 | I9: ='Data Sheet'!H20/'Data Sheet'!H$17 -> 0 | J9: ='Data Sheet'!I20/'Data Sheet'!I$17 -> 0 | ... L9: ='Data Sheet'!K20/'Data Sheet'!K$17 -> 0
B10: ='Data Sheet'!A21 -> Other Mfr. Exp | C10: ='Data Sheet'!B21/'Data Sheet'!B$17 -> 0.05 | D10: ='Data Sheet'!C21/'Data Sheet'!C$17 -> 0.05 | E10: ='Data Sheet'!D21/'Data Sheet'!D$17 -> 0.05 | F10: ='Data Sheet'!E21/'Data Sheet'!E$17 -> 0.05 | G10: ='Data Sheet'!F21/'Data Sheet'!F$17 -> 0.04 | H10: ='Data Sheet'!G21/'Data Sheet'!G$17 -> 0.04 | I10: ='Data Sheet'!H21/'Data Sheet'!H$17 -> 0.04 | J10: ='Data Sheet'!I21/'Data Sheet'!I$17 -> 0.03 | ... L10: ='Data Sheet'!K21/'Data Sheet'!K$17 -> 0.03
B11: ='Data Sheet'!A22 -> Employee Cost | C11: ='Data Sheet'!B22/'Data Sheet'!B$17 -> 0.11 | D11: ='Data Sheet'!C22/'Data Sheet'!C$17 -> 0.11 | E11: ='Data Sheet'!D22/'Data Sheet'!D$17 -> 0.11 | F11: ='Data Sheet'!E22/'Data Sheet'!E$17 -> 0.11 | G11: ='Data Sheet'!F22/'Data Sheet'!F$17 -> 0.11 | H11: ='Data Sheet'!G22/'Data Sheet'!G$17 -> 0.09 | I11: ='Data Sheet'!H22/'Data Sheet'!H$17 -> 0.08 | J11: ='Data Sheet'!I22/'Data Sheet'!I$17 -> 0.08 | ... L11: ='Data Sheet'!K22/'Data Sheet'!K$17 -> 0.06
B12: ='Data Sheet'!A23 -> Selling and admin | C12: ='Data Sheet'!B23/'Data Sheet'!B$17 -> 0 | D12: ='Data Sheet'!C23/'Data Sheet'!C$17 -> 0 | E12: ='Data Sheet'!D23/'Data Sheet'!D$17 -> 0 | F12: ='Data Sheet'!E23/'Data Sheet'!E$17 -> 0 | G12: ='Data Sheet'!F23/'Data Sheet'!F$17 -> 0 | H12: ='Data Sheet'!G23/'Data Sheet'!G$17 -> 0 | I12: ='Data Sheet'!H23/'Data Sheet'!H$17 -> 0 | J12: ='Data Sheet'!I23/'Data Sheet'!I$17 -> 0 | ... L12: ='Data Sheet'!K23/'Data Sheet'!K$17 -> 0
B13: ='Data Sheet'!A24 -> Other Expenses | C13: ='Data Sheet'!B24/'Data Sheet'!B$17 -> 0.11 | D13: ='Data Sheet'!C24/'Data Sheet'!C$17 -> 0.12 | E13: ='Data Sheet'!D24/'Data Sheet'!D$17 -> 0.12 | F13: ='Data Sheet'!E24/'Data Sheet'!E$17 -> 0.2 | G13: ='Data Sheet'!F24/'Data Sheet'!F$17 -> 0.18 | H13: ='Data Sheet'!G24/'Data Sheet'!G$17 -> 0.13 | I13: ='Data Sheet'!H24/'Data Sheet'!H$17 -> 0.1 | J13: ='Data Sheet'!I24/'Data Sheet'!I$17 -> 0.11 | ... L13: ='Data Sheet'!K24/'Data Sheet'!K$17 -> 0.1
B14: ='Data Sheet'!A25 -> Other Income | C14: ='Data Sheet'!B25/'Data Sheet'!B$17 -> 0.024793191 | D14: ='Data Sheet'!C25/'Data Sheet'!C$17 -> 0.047408083 | E14: ='Data Sheet'!D25/'Data Sheet'!D$17 -> 0.025553614 | F14: ='Data Sheet'!E25/'Data Sheet'!E$17 -> 0.011740203 | G14: ='Data Sheet'!F25/'Data Sheet'!F$17 -> 0.015509303 | H14: ='Data Sheet'!G25/'Data Sheet'!G$17 -> 0.035532488 | I14: ='Data Sheet'!H25/'Data Sheet'!H$17 -> 0.032316541 | J14: ='Data Sheet'!I25/'Data Sheet'!I$17 -> 0.023713312 | ... L14: ='Data Sheet'!K25/'Data Sheet'!K$17 -> 0.025765333
B15: ='Data Sheet'!A26 -> Depreciation | C15: ='Data Sheet'!B26/'Data Sheet'!B$17 -> 0.033578838 | D15: ='Data Sheet'!C26/'Data Sheet'!C$17 -> 0.035615784 | E15: ='Data Sheet'!D26/'Data Sheet'!D$17 -> 0.03811079 | F15: ='Data Sheet'!E26/'Data Sheet'!E$17 -> 0.044665835 | G15: ='Data Sheet'!F26/'Data Sheet'!F$17 -> 0.0454778 | H15: ='Data Sheet'!G26/'Data Sheet'!G$17 -> 0.03890386 | I15: ='Data Sheet'!H26/'Data Sheet'!H$17 -> 0.035900859 | J15: ='Data Sheet'!I26/'Data Sheet'!I$17 -> 0.033966551 | ... L15: ='Data Sheet'!K26/'Data Sheet'!K$17 -> 0.036860838
B16: ='Data Sheet'!A27 -> Interest | C16: ='Data Sheet'!B27/'Data Sheet'!B$17 -> 0.04354625 | D16: ='Data Sheet'!C27/'Data Sheet'!C$17 -> 0.043292723 | E16: ='Data Sheet'!D27/'Data Sheet'!D$17 -> 0.047946448 | F16: ='Data Sheet'!E27/'Data Sheet'!E$17 -> 0.079873179 | G16: ='Data Sheet'!F27/'Data Sheet'!F$17 -> 0.082150839 | H16: ='Data Sheet'!G27/'Data Sheet'!G$17 -> 0.055649821 | I16: ='Data Sheet'!H27/'Data Sheet'!H$17 -> 0.048038101 | J16: ='Data Sheet'!I27/'Data Sheet'!I$17 -> 0.053840291 | ... L16: ='Data Sheet'!K27/'Data Sheet'!K$17 -> 0.04828357
B17: ='Data Sheet'!A28 -> Profit before tax | C17: ='Data Sheet'!B28/'Data Sheet'!B$17 -> 0.075800079 | D17: ='Data Sheet'!C28/'Data Sheet'!C$17 -> 0.11212457 | E17: ='Data Sheet'!D28/'Data Sheet'!D$17 -> 0.084710803 | F17: ='Data Sheet'!E28/'Data Sheet'!E$17 -> 0.021954843 | G17: ='Data Sheet'!F28/'Data Sheet'!F$17 -> 0.042515954 | H17: ='Data Sheet'!G28/'Data Sheet'!G$17 -> 0.10382495 | I17: ='Data Sheet'!H28/'Data Sheet'!H$17 -> 0.11585175 | J17: ='Data Sheet'!I28/'Data Sheet'!I$17 -> 0.11488517 | ... L17: ='Data Sheet'!K28/'Data Sheet'!K$17 -> 0.12678779
... B21: ='Data Sheet'!A32 -> EBITDA | C21: ='Data Sheet'!B32/'Data Sheet'!B$17 -> 0 | D21: ='Data Sheet'!C32/'Data Sheet'!C$17 -> 0 | E21: ='Data Sheet'!D32/'Data Sheet'!D$17 -> 0 | F21: ='Data Sheet'!E32/'Data Sheet'!E$17 -> 0 | G21: ='Data Sheet'!F32/'Data Sheet'!F$17 -> 0 | H21: ='Data Sheet'!G32/'Data Sheet'!G$17 -> 0 | I21: ='Data Sheet'!H32/'Data Sheet'!H$17 -> 0 | J21: ='Data Sheet'!I32/'Data Sheet'!I$17 -> 0 | ... L21: ='Data Sheet'!K32/'Data Sheet'!K$17 -> 0
B23: ="Common Size Balance Sheet - "&'Data Sheet'!$B$1 -> Common Size Balance Sheet - MAHINDRA & MAHINDRA LTD
B25: Particulars | C25: ='Data Sheet'!B$16 -> 42795 | D25: ='Data Sheet'!C$16 -> 43160 | E25: ='Data Sheet'!D$16 -> 43525 | F25: ='Data Sheet'!E$16 -> 43891 | G25: ='Data Sheet'!F$16 -> 44256 | H25: ='Data Sheet'!G$16 -> 44621 | I25: ='Data Sheet'!H$16 -> 44986 | J25: ='Data Sheet'!I$16 -> 45352 | ... L25: ='Data Sheet'!K$16 -> 46082
B27: Total Liabilities | C27: ='Data Sheet'!B61/'Data Sheet'!B$61 -> 1 | D27: ='Data Sheet'!C61/'Data Sheet'!C$61 -> 1 | E27: ='Data Sheet'!D61/'Data Sheet'!D$61 -> 1 | F27: ='Data Sheet'!E61/'Data Sheet'!E$61 -> 1 | G27: ='Data Sheet'!F61/'Data Sheet'!F$61 -> 1 | H27: ='Data Sheet'!G61/'Data Sheet'!G$61 -> 1 | I27: ='Data Sheet'!H61/'Data Sheet'!H$61 -> 1 | J27: ='Data Sheet'!I61/'Data Sheet'!I$61 -> 1 | ... L27: ='Data Sheet'!K61/'Data Sheet'!K$61 -> 1
B28: ='Data Sheet'!A57 -> Equity Share Capital | C28: ='Data Sheet'!B57/'Data Sheet'!B$61 -> 0.0027320244 | D28: ='Data Sheet'!C57/'Data Sheet'!C$61 -> 0.0039818434 | E28: ='Data Sheet'!D57/'Data Sheet'!D$61 -> 0.0033603271 | F28: ='Data Sheet'!E57/'Data Sheet'!E$61 -> 0.0033430689 | G28: ='Data Sheet'!F57/'Data Sheet'!F$61 -> 0.0033642888 | H28: ='Data Sheet'!G57/'Data Sheet'!G$61 -> 0.0032252825 | I28: ='Data Sheet'!H57/'Data Sheet'!H$61 -> 0.0027266097 | J28: ='Data Sheet'!I57/'Data Sheet'!I$61 -> 0.00237302 | ... L28: ='Data Sheet'!K57/'Data Sheet'!K$61 -> 0.0017686851
B29: ='Data Sheet'!A58 -> Reserves | C29: ='Data Sheet'!B58/'Data Sheet'!B$61 -> 0.25885712 | D29: ='Data Sheet'!C58/'Data Sheet'!C$61 -> 0.26569088 | E29: ='Data Sheet'!D58/'Data Sheet'!D$61 -> 0.24361754 | F29: ='Data Sheet'!E58/'Data Sheet'!E$61 -> 0.23784668 | G29: ='Data Sheet'!F58/'Data Sheet'!F$61 -> 0.24869672 | H29: ='Data Sheet'!G58/'Data Sheet'!G$61 -> 0.27012901 | I29: ='Data Sheet'!H58/'Data Sheet'!H$61 -> 0.27319454 | J29: ='Data Sheet'!I58/'Data Sheet'!I$61 -> 0.27962015 | ... L29: ='Data Sheet'!K58/'Data Sheet'!K$61 -> 0.29279174
B30: ='Data Sheet'!A59 -> Borrowings | C30: ='Data Sheet'!B59/'Data Sheet'!B$61 -> 0.42835683 | D30: ='Data Sheet'!C59/'Data Sheet'!C$61 -> 0.40990254 | E30: ='Data Sheet'!D59/'Data Sheet'!D$61 -> 0.43763319 | F30: ='Data Sheet'!E59/'Data Sheet'!E$61 -> 0.49537763 | G30: ='Data Sheet'!F59/'Data Sheet'!F$61 -> 0.48873115 | H30: ='Data Sheet'!G59/'Data Sheet'!G$61 -> 0.45017635 | I30: ='Data Sheet'!H59/'Data Sheet'!H$61 -> 0.45352281 | J30: ='Data Sheet'!I59/'Data Sheet'!I$61 -> 0.46287523 | ... L30: ='Data Sheet'!K59/'Data Sheet'!K$61 -> 0.43326773
B31: ='Data Sheet'!A60 -> Other Liabilities | C31: ='Data Sheet'!B60/'Data Sheet'!B$61 -> 0.31006281 | D31: ='Data Sheet'!C60/'Data Sheet'!C$61 -> 0.32042473 | E31: ='Data Sheet'!D60/'Data Sheet'!D$61 -> 0.31538276 | F31: ='Data Sheet'!E60/'Data Sheet'!E$61 -> 0.26343262 | G31: ='Data Sheet'!F60/'Data Sheet'!F$61 -> 0.25921391 | H31: ='Data Sheet'!G60/'Data Sheet'!G$61 -> 0.27647516 | I31: ='Data Sheet'!H60/'Data Sheet'!H$61 -> 0.27055604 | J31: ='Data Sheet'!I60/'Data Sheet'!I$61 -> 0.25512734 | ... L31: ='Data Sheet'!K60/'Data Sheet'!K$61 -> 0.27217184
B33: Total Assets | C33: ='Data Sheet'!B66/'Data Sheet'!B$66 -> 1 | D33: ='Data Sheet'!C66/'Data Sheet'!C$66 -> 1 | E33: ='Data Sheet'!D66/'Data Sheet'!D$66 -> 1 | F33: ='Data Sheet'!E66/'Data Sheet'!E$66 -> 1 | G33: ='Data Sheet'!F66/'Data Sheet'!F$66 -> 1 | H33: ='Data Sheet'!G66/'Data Sheet'!G$66 -> 1 | I33: ='Data Sheet'!H66/'Data Sheet'!H$66 -> 1 | J33: ='Data Sheet'!I66/'Data Sheet'!I$66 -> 1 | ... L33: ='Data Sheet'!K66/'Data Sheet'!K$66 -> 1
B34: Fixed Assets Net Block | C34: ='Data Sheet'!B62/'Data Sheet'!B$66 -> 0.1843809 | D34: ='Data Sheet'!C62/'Data Sheet'!C$66 -> 0.19199378 | E34: ='Data Sheet'!D62/'Data Sheet'!D$66 -> 0.17903008 | F34: ='Data Sheet'!E62/'Data Sheet'!E$66 -> 0.17915591 | G34: ='Data Sheet'!F62/'Data Sheet'!F$66 -> 0.12960089 | H34: ='Data Sheet'!G62/'Data Sheet'!G$66 -> 0.15092698 | I34: ='Data Sheet'!H62/'Data Sheet'!H$66 -> 0.13285491 | J34: ='Data Sheet'!I62/'Data Sheet'!I$66 -> 0.11983964 | ... L34: ='Data Sheet'!K62/'Data Sheet'!K$66 -> 0.1216849
B35: ='Data Sheet'!A63 -> Capital Work in Progress | C35: ='Data Sheet'!B63/'Data Sheet'!B$66 -> 0.037589494 | D35: ='Data Sheet'!C63/'Data Sheet'!C$66 -> 0.031304769 | E35: ='Data Sheet'!D63/'Data Sheet'!D$66 -> 0.029402862 | F35: ='Data Sheet'!E63/'Data Sheet'!E$66 -> 0.041371986 | G35: ='Data Sheet'!F63/'Data Sheet'!F$66 -> 0.047724407 | H35: ='Data Sheet'!G63/'Data Sheet'!G$66 -> 0.038883217 | I35: ='Data Sheet'!H63/'Data Sheet'!H$66 -> 0.019428929 | J35: ='Data Sheet'!I63/'Data Sheet'!I$66 -> 0.034249027 | ... L35: ='Data Sheet'!K63/'Data Sheet'!K$66 -> 0.024489486
B36: ='Data Sheet'!A64 -> Investments | C36: ='Data Sheet'!B64/'Data Sheet'!B$66 -> 0.12880046 | D36: ='Data Sheet'!C64/'Data Sheet'!C$66 -> 0.11746071 | E36: ='Data Sheet'!D64/'Data Sheet'!D$66 -> 0.11284275 | F36: ='Data Sheet'!E64/'Data Sheet'!E$66 -> 0.11592121 | G36: ='Data Sheet'!F64/'Data Sheet'!F$66 -> 0.17444595 | H36: ='Data Sheet'!G64/'Data Sheet'!G$66 -> 0.17437409 | I36: ='Data Sheet'!H64/'Data Sheet'!H$66 -> 0.17266243 | J36: ='Data Sheet'!I64/'Data Sheet'!I$66 -> 0.14999872 | ... L36: ='Data Sheet'!K64/'Data Sheet'!K$66 -> 0.12758579
B37: ='Data Sheet'!A65 -> Other Assets | C37: ='Data Sheet'!B74/'Data Sheet'!B66 -> 0 | D37: ='Data Sheet'!C74/'Data Sheet'!C66 -> 0 | E37: ='Data Sheet'!D74/'Data Sheet'!D66 -> 0 | F37: ='Data Sheet'!E74/'Data Sheet'!E66 -> 0 | G37: ='Data Sheet'!F74/'Data Sheet'!F66 -> 0 | H37: ='Data Sheet'!G74/'Data Sheet'!G66 -> 0 | I37: ='Data Sheet'!H74/'Data Sheet'!H66 -> 0 | J37: ='Data Sheet'!I74/'Data Sheet'!I66 -> 0 | ... L37: ='Data Sheet'!K74/'Data Sheet'!K66 -> 0
B38: ='Data Sheet'!A67 -> Receivables | C38: ='Data Sheet'!B67/'Data Sheet'!B$66 -> 0.063240655 | D38: ='Data Sheet'!C67/'Data Sheet'!C$66 -> 0.062257551 | E38: ='Data Sheet'!D67/'Data Sheet'!D$66 -> 0.05360463 | F38: ='Data Sheet'!E67/'Data Sheet'!E$66 -> 0.041806464 | G38: ='Data Sheet'!F67/'Data Sheet'!F$66 -> 0.036419184 | H38: ='Data Sheet'!G67/'Data Sheet'!G$66 -> 0.036974731 | I38: ='Data Sheet'!H67/'Data Sheet'!H$66 -> 0.034403254 | J38: ='Data Sheet'!I67/'Data Sheet'!I$66 -> 0.031778018 | ... L38: ='Data Sheet'!K67/'Data Sheet'!K$66 -> 0.028678644
B39: ='Data Sheet'!A68 -> Inventory | C39: ='Data Sheet'!B68/'Data Sheet'!B$66 -> 0.078060351 | D39: ='Data Sheet'!C68/'Data Sheet'!C$66 -> 0.068461307 | E39: ='Data Sheet'!D68/'Data Sheet'!D$66 -> 0.075360278 | F39: ='Data Sheet'!E68/'Data Sheet'!E$66 -> 0.067054479 | G39: ='Data Sheet'!F68/'Data Sheet'!F$66 -> 0.058284031 | H39: ='Data Sheet'!G68/'Data Sheet'!G$66 -> 0.067266863 | I39: ='Data Sheet'!H68/'Data Sheet'!H$66 -> 0.082508089 | J39: ='Data Sheet'!I68/'Data Sheet'!I$66 -> 0.079200075 | ... L39: ='Data Sheet'!K68/'Data Sheet'!K$66 -> 0.069747575
B40: ='Data Sheet'!A69 -> Cash & Bank | C40: ='Data Sheet'!B69/'Data Sheet'!B$66 -> 0.040883735 | D40: ='Data Sheet'!C69/'Data Sheet'!C$66 -> 0.048016778 | E40: ='Data Sheet'!D69/'Data Sheet'!D$66 -> 0.053956723 | F40: ='Data Sheet'!E69/'Data Sheet'!E$66 -> 0.047738299 | G40: ='Data Sheet'!F69/'Data Sheet'!F$66 -> 0.077906018 | H40: ='Data Sheet'!G69/'Data Sheet'!G$66 -> 0.064494048 | I40: ='Data Sheet'!H69/'Data Sheet'!H$66 -> 0.055183251 | J40: ='Data Sheet'!I69/'Data Sheet'!I$66 -> 0.051179693 | ... L40: ='Data Sheet'!K69/'Data Sheet'!K$66 -> 0.10118208

Sheet Data Sheet
A1: COMPANY NAME | B1: MAHINDRA & MAHINDRA LTD | E1: =IF(B2<>B3, "A NEW VERSION OF THE WORKSHEET IS AVAILABLE", "")
A2: LATEST VERSION | B2: 2.1 | E2: PLEASE DO NOT MAKE ANY CHANGES TO THIS SHEET
A3: CURRENT VERSION | B3: 2.1
A5: META
A6: Number of shares | B6: =IF(B9>0, B9/B8, 0) -> 124.32242
A7: Face Value | B7: 5
A8: Current Price | B8: 3055
A9: Market Capitalization | B9: 379805
A15: PROFIT & LOSS
A16: Report Date | B16: 42795 | C16: 43160 | D16: 43525 | E16: 43891 | F16: 44256 | G16: 44621 | H16: 44986 | I16: 45352 | J16: 45717 | K16: 46082
A17: Sales | B17: 83773 | C17: 92094 | D17: 104721 | E17: 75382 | F17: 74278 | G17: 90171 | H17: 121362 | I17: 139078 | J17: 159211 | K17: 198639
A18: Raw Material Cost | B18: 50263.8 | C18: 53414.52 | D18: 59690.97 | E18: 38444.82 | F18: 38624.56 | G18: 51397.47 | H18: 74030.82 | I18: 83446.8 | J18: 95526.6 | K18: 123156.18
A19: Change in Inventory | B19: 0 | C19: 0 | D19: 0 | E19: 0 | F19: 0 | G19: 0 | H19: 0 | I19: 0 | J19: 0 | K19: 0
A20: Power and Fuel | B20: 0 | C20: 0 | D20: 0 | E20: 0 | F20: 0 | G20: 0 | H20: 0 | I20: 0 | J20: 0 | K20: 0
A21: Other Mfr. Exp | B21: 4188.65 | C21: 4604.7 | D21: 5236.05 | E21: 3769.1 | F21: 2971.12 | G21: 3606.84 | H21: 4854.48 | I21: 4172.34 | J21: 4776.33 | K21: 5959.17
A22: Employee Cost | B22: 9215.03 | C22: 10130.34 | D22: 11519.31 | E22: 8292.02 | F22: 8170.58 | G22: 8115.39 | H22: 9708.96 | I22: 11126.24 | J22: 11144.77 | K22: 11918.34
A23: Selling and admin | B23: 0 | C23: 0 | D23: 0 | E23: 0 | F23: 0 | G23: 0 | H23: 0 | I23: 0 | J23: 0 | K23: 0
A24: Other Expenses | B24: 9215.03 | C24: 11051.28 | D24: 12566.52 | E24: 15076.4 | F24: 13370.04 | G24: 11722.23 | H24: 12136.2 | I24: 15298.58 | J24: 17513.21 | K24: 19863.9
A25: Other Income | B25: 2077 | C25: 4366 | D25: 2676 | E25: 885 | F25: 1152 | G25: 3204 | H25: 3922 | I25: 3298 | J25: 3718 | K25: 5118
A26: Depreciation | B26: 2813 | C26: 3280 | D26: 3991 | E26: 3367 | F26: 3378 | G26: 3508 | H26: 4357 | I26: 4724 | J26: 6074 | K26: 7322
A27: Interest | B27: 3648 | C27: 3987 | D27: 5021 | E27: 6021 | F27: 6102 | G27: 5018 | H27: 5830 | I27: 7488 | J27: 9083 | K27: 9591
... A32: EBITDA | B32: 0 | C32: 0 | D32: 0 | E32: 0 | F32: 0 | G32: 0 | H32: 0 | I32: 0 | J32: 0 | K32: 0
B33: =B30+B29+B27+B26 -> 16862 | C33: =C30+C29+C27+C26 -> 25551 | D33: =D30+D29+D27+D26 -> 23900 | E33: =E30+E29+E27+E26 -> 10722 | F33: =F30+F29+F27+F26 -> 14150 | G33: =G30+G29+G27+G26 -> 25141 | H33: =H30+H29+H27+H26 -> 35621 | I33: =I30+I29+I27+I26 -> 40460 | ... K33: =K30+K29+K27+K26 -> 60720
A40: Quarters
A41: Report Date | B41: 45352 | C41: 45444 | D41: 45536 | E41: 45627 | F41: 45717 | G41: 45809 | H41: 45901 | I41: 45992 | J41: 46082 | K41: 46174
A42: Sales | B42: 35452 | C42: 37218 | D42: 37924 | E42: 41470 | F42: 42599 | G42: 45529 | H42: 46106 | I42: 52100 | J42: 54982 | K42: 58188
A43: Expenses | B43: 28848 | C43: 29975 | D43: 30790 | E43: 33239 | F43: 34658 | G43: 37117 | H43: 37166 | I43: 41939 | J43: 44855 | K43: 47360
A44: Other Income | B44: 750 | C44: 733 | D44: 1126 | E44: 719 | F44: 1110 | G44: 1210 | H44: 1134 | I44: 976 | J44: 1137 | K44: 1121
A45: Depreciation | B45: 1335 | C45: 1248 | D45: 1302 | E45: 1495 | F45: 2029 | G45: 1548 | H45: 1669 | I45: 2163 | J45: 1943 | K45: 1760
A46: Interest | B46: 1989 | C46: 2108 | D46: 2217 | E46: 2362 | F46: 2397 | G46: 2431 | H46: 2347 | I46: 2405 | J46: 2407 | K46: 2560
A47: Profit before tax | B47: 4030 | C47: 4621 | D47: 4740 | E47: 5092 | F47: 4627 | G47: 5644 | H47: 6058 | I47: 6569 | J47: 6914 | K47: 7628
A48: Tax | B48: 4030 | C48: 4621 | D48: 4740 | E48: 5092 | F48: 4627 | G48: 5644 | H48: 6058 | I48: 6569 | J48: 6914 | K48: 7628
A49: Net profit | B49: 3125 | C49: 3546 | D49: 3361 | E49: 3624 | F49: 3542 | G49: 4377 | H49: 3964 | I49: 5021 | J49: 5260 | K49: 5998
A50: Operating Profit | B50: 6604 | C50: 7243 | D50: 7133 | E50: 8231 | F50: 7942 | G50: 8412 | H50: 8940 | I50: 10160 | J50: 10127 | K50: 10827
A55: BALANCE SHEET
A56: Report Date | B56: 42795 | C56: 43160 | D56: 43525 | E56: 43891 | F56: 44256 | G56: 44621 | H56: 44986 | I56: 45352 | J56: 45717 | K56: 46082
A57: Equity Share Capital | B57: 311 | C57: 543 | D57: 544 | E57: 554 | F57: 555 | G57: 556 | H57: 557 | I57: 557 | J57: 558 | K57: 559
A58: Reserves | B58: 29467 | C58: 36232 | D58: 39439 | E58: 39415 | F58: 41027 | G58: 46567 | H58: 55809 | I58: 65633 | J58: 76481 | K58: 92538
A59: Borrowings | B59: 48762 | C59: 55898 | D59: 70848 | E59: 82092 | F59: 80625 | G59: 77605 | H59: 92647 | I59: 108647 | J59: 129025 | K59: 136936
A60: Other Liabilities | B60: 35296 | C60: 43696 | D60: 51057 | E60: 43655 | F60: 42762 | G60: 47661 | H60: 55270 | I60: 59884 | J60: 69950 | K60: 86021
...

Sheet Cash Flow Statement
B2: Cash Flow Statement - MAHINDRA & MAHINDRA LTD
B4: Particulars | C4: 42064 | D4: 42430 | E4: 42795 | F4: 43160 | G4: 43525 | H4: 43891 | I4: 44256 | J4: 44621 | K4: 44986 | L4: 45352 | M4: 45717 | N4: 46082
B6: Cash from Operating Activity - | C6: 1055 | D6: 2385 | E6: 183 | F6: 682 | G6: -4347 | H6: -1457 | I6: 17909 | J6: 9248 | K6: -7074 | L6: -5630 | M6: 3176 | N6: 11657
B7: Profit from operations | C7: 6454 | D7: 7595 | E7: 7911 | F7: 10159 | G7: 11112 | H7: 7774 | I7: 7588 | J7: 10515 | K7: 15642 | L7: 17541 | M7: 22050 | N7: 28938
B8: Receivables | C8: -575 | D8: 177 | E8: -8609 | F8: -11918 | G8: -13712 | H8: -1516 | I8: 4896 | J8: -2506 | K8: -21702 | L8: -21777 | M8: -20952 | N8: -19186
B9: Inventory | C9: -62 | D9: -1113 | E9: 241 | F9: -256 | G9: -2276 | H9: 1316 | I9: 226 | J9: -2173 | K9: -5252 | L9: -1753 | M9: -1646 | N9: -593
B10: Payables | C10: 1169 | D10: 1939 | E10: 2645 | F10: 5361 | G10: 3466 | H10: -6775 | I10: 7049 | J10: 4972 | K10: 7013 | L10: 4354 | M10: 8485 | N10: 8763
B11: Working capital changes | C11: -3698 | D11: -3238 | E11: -5724 | F11: -6813 | G11: -12522 | H11: -6974 | I11: 12171 | J11: 293 | K11: -19941 | L11: -19175 | M11: -14113 | N11: -11016
B12: Direct taxes | C12: -1701 | D12: -1973 | E12: -2005 | F12: -2664 | G12: -2937 | H12: -2257 | I12: -1850 | J12: -1560 | K12: -2775 | L12: -3996 | M12: -4761 | N12: -6265
B13: Cash from Investing Activity - | C13: -4357 | D13: -5506 | E13: -5875 | F13: -5467 | G13: -7174 | H13: -6870 | I13: -19686 | J13: -3252 | K13: -8866 | L13: -5615 | M13: -18616 | N13: -17680
B14: Fixed assets purchased | C14: -4759 | D14: -4172 | E14: -5026 | F14: -5906 | G14: -7340 | H14: -6896 | I14: -5989 | J14: -6040 | K14: -6305 | L14: -9946 | M14: -10392 | N14: -9605
B15: Fixed assets sold | C15: 43 | D15: 59 | E15: 63 | F15: 115 | G15: 142 | H15: 102 | I15: 1364 | J15: 120 | K15: 138 | L15: 273 | M15: 583 | N15: 493
B16: Investments purchased | C16: -80047 | D16: -87898 | E16: -132173 | F16: -155159 | G16: -196474 | H16: -198568 | I16: -120055 | J16: -87740 | K16: -50165 | L16: -49927 | M16: -90595 | N16: -141518
... B32: Net Cash Flow | C32: -1633 | D32: -154 | E32: 416 | F32: 1529 | G32: 1672 | H32: -1394 | I32: -1370 | J32: 113 | K32: 6 | L32: 1037 | M32: 394 | N32: -632

Sheet Historical FS
B2: ="Historical Financial Statement - "&'Data Sheet'!$B$1 -> Historical Financial Statement - MAHINDRA & MAHINDRA LTD
B3: Particulars | C3: ='Data Sheet'!B56 -> 42795 | D3: ='Data Sheet'!C56 -> 43160 | E3: ='Data Sheet'!D56 -> 43525 | F3: ='Data Sheet'!E56 -> 43891 | G3: ='Data Sheet'!F56 -> 44256 | H3: ='Data Sheet'!G56 -> 44621 | I3: ='Data Sheet'!H56 -> 44986 | J3: ='Data Sheet'!I56 -> 45352 | ... L3: ='Data Sheet'!K56 -> 46082 | M3: LTM
A5: # | B5: Income Statement
B7: Sales | C7: ='Data Sheet'!B17 -> 83773 | D7: ='Data Sheet'!C17 -> 92094 | E7: ='Data Sheet'!D17 -> 104721 | F7: ='Data Sheet'!E17 -> 75382 | G7: ='Data Sheet'!F17 -> 74278 | H7: ='Data Sheet'!G17 -> 90171 | I7: ='Data Sheet'!H17 -> 121362 | J7: ='Data Sheet'!I17 -> 139078 | ... L7: ='Data Sheet'!K17 -> 198639
B8: Sales Growth | C8: - | D8: =D7/C7-1 -> 0.099327946 | E8: =E7/D7-1 -> 0.13710991 | F8: =F7/E7-1 -> -0.28016348 | G8: =G7/F7-1 -> -0.014645406 | H8: =H7/G7-1 -> 0.21396645 | I8: =I7/H7-1 -> 0.34590944 | J8: =J7/I7-1 -> 0.1459765 | K8: =K7/J7-1 -> 0.14476049 | L8: =L7/K7-1 -> 0.24764621
B10: Cost of Goods Sold | C10: =SUM('Data Sheet'!B18,'Data Sheet'!B20:B22)-'Data Sheet'!B19 -> 63667.48 | D10: =SUM('Data Sheet'!C18,'Data Sheet'!C20:C22)-'Data Sheet'!C19 -> 68149.56 | E10: =SUM('Data Sheet'!D18,'Data Sheet'!D20:D22)-'Data Sheet'!D19 -> 76446.33 | F10: =SUM('Data Sheet'!E18,'Data Sheet'!E20:E22)-'Data Sheet'!E19 -> 50505.94 | G10: =SUM('Data Sheet'!F18,'Data Sheet'!F20:F22)-'Data Sheet'!F19 -> 49766.26 | H10: =SUM('Data Sheet'!G18,'Data Sheet'!G20:G22)-'Data Sheet'!G19 -> 63119.7 | I10: =SUM('Data Sheet'!H18,'Data Sheet'!H20:H22)-'Data Sheet'!H19 -> 88594.26 | J10: =SUM('Data Sheet'!I18,'Data Sheet'!I20:I22)-'Data Sheet'!I19 -> 98745.38 | ... L10: =SUM('Data Sheet'!K18,'Data Sheet'!K20:K22)-'Data Sheet'!K19 -> 141033.69
B11: COGS % Sales | C11: =C10/C7 -> 0.76 | D11: =D10/D7 -> 0.74 | E11: =E10/E7 -> 0.73 | F11: =F10/F7 -> 0.67 | G11: =G10/G7 -> 0.67 | H11: =H10/H7 -> 0.7 | I11: =I10/I7 -> 0.73 | J11: =J10/J7 -> 0.71 | ... L11: =L10/L7 -> 0.71
B13: Gross Profit | C13: =C7-C10 -> 20105.52 | D13: =D7-D10 -> 23944.44 | E13: =E7-E10 -> 28274.67 | F13: =F7-F10 -> 24876.06 | G13: =G7-G10 -> 24511.74 | H13: =H7-H10 -> 27051.3 | I13: =I7-I10 -> 32767.74 | J13: =J7-J10 -> 40332.62 | ... L13: =L7-L10 -> 57605.31
B14: Gross Profit % Sales | C14: =C13/C7 -> 0.24 | D14: =D13/D7 -> 0.26 | E14: =E13/E7 -> 0.27 | F14: =F13/F7 -> 0.33 | G14: =G13/G7 -> 0.33 | H14: =H13/H7 -> 0.3 | I14: =I13/I7 -> 0.27 | J14: =J13/J7 -> 0.29 | ... L14: =L13/L7 -> 0.29
B16: Selling % General Expenses | C16: ='Data Sheet'!B23 -> 0 | D16: ='Data Sheet'!C23 -> 0 | E16: ='Data Sheet'!D23 -> 0 | F16: ='Data Sheet'!E23 -> 0 | G16: ='Data Sheet'!F23 -> 0 | H16: ='Data Sheet'!G23 -> 0 | I16: ='Data Sheet'!H23 -> 0 | J16: ='Data Sheet'!I23 -> 0 | ... L16: ='Data Sheet'!K23 -> 0
B17: S&G % Sales | C17: =C16/C7 -> 0 | D17: =D16/D7 -> 0 | E17: =E16/E7 -> 0 | F17: =F16/F7 -> 0 | G17: =G16/G7 -> 0 | H17: =H16/H7 -> 0 | I17: =I16/I7 -> 0 | J17: =J16/J7 -> 0 | ... L17: =L16/L7 -> 0
B19: EBITDA | C19: =C13-C16 -> 20105.52 | D19: =D13-D16 -> 23944.44 | E19: =E13-E16 -> 28274.67 | F19: =F13-F16 -> 24876.06 | G19: =G13-G16 -> 24511.74 | H19: =H13-H16 -> 27051.3 | I19: =I13-I16 -> 32767.74 | J19: =J13-J16 -> 40332.62 | ... L19: =L13-L16 -> 57605.31
B20: EBITDA % Sales | C20: =C19/C7 -> 0.24 | D20: =D19/D7 -> 0.26 | E20: =E19/E7 -> 0.27 | F20: =F19/F7 -> 0.33 | G20: =G19/G7 -> 0.33 | H20: =H19/H7 -> 0.3 | I20: =I19/I7 -> 0.27 | J20: =J19/J7 -> 0.29 | ... L20: =L19/L7 -> 0.29
B22: Depreciation | C22: ='Data Sheet'!B26 -> 2813 | D22: ='Data Sheet'!C26 -> 3280 | E22: ='Data Sheet'!D26 -> 3991 | F22: ='Data Sheet'!E26 -> 3367 | G22: ='Data Sheet'!F26 -> 3378 | H22: ='Data Sheet'!G26 -> 3508 | I22: ='Data Sheet'!H26 -> 4357 | J22: ='Data Sheet'!I26 -> 4724 | ... L22: ='Data Sheet'!K26 -> 7322
B23: Depreciation % Sales | C23: =C22/C7 -> 0.033578838 | D23: =D22/D7 -> 0.035615784 | E23: =E22/E7 -> 0.03811079 | F23: =F22/F7 -> 0.044665835 | G23: =G22/G7 -> 0.0454778 | H23: =H22/H7 -> 0.03890386 | I23: =I22/I7 -> 0.035900859 | J23: =J22/J7 -> 0.033966551 | ... L23: =L22/L7 -> 0.036860838
B25: EBIT | C25: =C19-C22 -> 17292.52 | D25: =D19-D22 -> 20664.44 | E25: =E19-E22 -> 24283.67 | F25: =F19-F22 -> 21509.06 | G25: =G19-G22 -> 21133.74 | H25: =H19-H22 -> 23543.3 | I25: =I19-I22 -> 28410.74 | J25: =J19-J22 -> 35608.62 | ... L25: =L19-L22 -> 50283.31
B26: EBIT % Sales | C26: =C25/C7 -> 0.20642116 | D26: =D25/D7 -> 0.22438422 | E26: =E25/E7 -> 0.23188921 | F26: =F25/F7 -> 0.28533416 | G26: =G25/G7 -> 0.2845222 | H26: =H25/H7 -> 0.26109614 | I26: =I25/I7 -> 0.23409914 | J26: =J25/J7 -> 0.25603345 | ... L26: =L25/L7 -> 0.25313916
B28: Interest | C28: ='Data Sheet'!B27 -> 3648 | D28: ='Data Sheet'!C27 -> 3987 | E28: ='Data Sheet'!D27 -> 5021 | F28: ='Data Sheet'!E27 -> 6021 | G28: ='Data Sheet'!F27 -> 6102 | H28: ='Data Sheet'!G27 -> 5018 | I28: ='Data Sheet'!H27 -> 5830 | J28: ='Data Sheet'!I27 -> 7488 | ... L28: ='Data Sheet'!K27 -> 9591
B29: Interest % Sales | C29: =C28/C7 -> 0.04354625 | D29: =D28/D7 -> 0.043292723 | E29: =E28/E7 -> 0.047946448 | F29: =F28/F7 -> 0.079873179 | G29: =G28/G7 -> 0.082150839 | H29: =H28/H7 -> 0.055649821 | I29: =I28/I7 -> 0.048038101 | J29: =J28/J7 -> 0.053840291 | ... L29: =L28/L7 -> 0.04828357
B31: Earning Before Tax | C31: =C25-C28 -> 13644.52 | D31: =D25-D28 -> 16677.44 | E31: =E25-E28 -> 19262.67 | F31: =F25-F28 -> 15488.06 | G31: =G25-G28 -> 15031.74 | H31: =H25-H28 -> 18525.3 | I31: =I25-I28 -> 22580.74 | J31: =J25-J28 -> 28120.62 | ... L31: =L25-L28 -> 40692.31
B32: EBT % Sales | C32: =C31/C7 -> 0.16287491 | D32: =D31/D7 -> 0.18109149 | E32: =E31/E7 -> 0.18394276 | F32: =F31/F7 -> 0.20546099 | G32: =G31/G7 -> 0.20237136 | H32: =H31/H7 -> 0.20544632 | I32: =I31/I7 -> 0.18606104 | J32: =J31/J7 -> 0.20219316 | ... L32: =L31/L7 -> 0.20485559
B34: Tax Rate | C34: ='Data Sheet'!B29 -> 6350 | D34: ='Data Sheet'!C29 -> 10326 | E34: ='Data Sheet'!D29 -> 8871 | F34: ='Data Sheet'!E29 -> 1655 | G34: ='Data Sheet'!F29 -> 3158 | H34: ='Data Sheet'!G29 -> 9362 | I34: ='Data Sheet'!H29 -> 14060 | J34: ='Data Sheet'!I29 -> 15978 | ... L34: ='Data Sheet'!K29 -> 25185
B35: Effective Tax Rate | C35: =C34/C31 -> 0.4653883 | D35: =D34/D31 -> 0.61915978 | E35: =E34/E31 -> 0.46052806 | F35: =F34/F31 -> 0.10685651 | G35: =G34/G31 -> 0.21008879 | H35: =H34/H31 -> 0.50536294 | I35: =I34/I31 -> 0.62265453 | J35: =J34/J31 -> 0.56819515 | ... L35: =L34/L31 -> 0.61891301
B37: Net Profit | C37: =C31-C34 -> 7294.52 | D37: =D31-D34 -> 6351.44 | E37: =E31-E34 -> 10391.67 | F37: =F31-F34 -> 13833.06 | G37: =G31-G34 -> 11873.74 | H37: =H31-H34 -> 9163.3 | I37: =I31-I34 -> 8520.74 | J37: =J31-J34 -> 12142.62 | ... L37: =L31-L34 -> 15507.31
B38: Net Profit % Sales | C38: =C37/C7 -> 0.087074833 | D38: =D37/D7 -> 0.068966925 | E38: =E37/E7 -> 0.099231959 | F38: =F37/F7 -> 0.18350614 | G38: =G37/G7 -> 0.15985541 | H38: =H37/H7 -> 0.10162136 | I38: =I37/I7 -> 0.070209291 | J38: =J37/J7 -> 0.087307985 | ... L38: =L37/L7 -> 0.078067801
B40: No. of Equity Shares | C40: ='Data Sheet'!B93 -> 133.85 | D40: ='Data Sheet'!C93 -> 133.85 | E40: ='Data Sheet'!D93 -> 133.85 | F40: ='Data Sheet'!E93 -> 133.85 | G40: ='Data Sheet'!F93 -> 133.85 | H40: ='Data Sheet'!G93 -> 133.85 | I40: ='Data Sheet'!H93 -> 133.85 | J40: ='Data Sheet'!I93 -> 133.85 | ... L40: ='Data Sheet'!K93 -> 133.85
B42: Earning per Share | C42: =C37/C40 -> 54.497721 | D42: =D37/D40 -> 47.451924 | E42: =E37/E40 -> 77.636683 | F42: =F37/F40 -> 103.34748 | G42: =G37/G40 -> 88.709301 | H42: =H37/H40 -> 68.45947 | I42: =I37/I40 -> 63.658872 | J42: =J37/J40 -> 90.718117 | ... L42: =L37/L40 -> 115.85588
B43: EPS Growth | C43: - | D43: =D42/C42-1 -> -0.12928609 | E43: =E42/D42-1 -> 0.63611244 | F43: =F42/E42-1 -> 0.33116814 | G43: =G42/F42-1 -> -0.14164039 | H43: =H42/G42-1 -> -0.2282718 | I43: =I42/H42-1 -> -0.070123209 | J43: =J42/I42-1 -> 0.42506637 | K43: =K42/J42-1 -> 0.11395234 | L43: =L42/K42-1 -> 0.14645616
B45: Dividend per Share | C45: ='Data Sheet'!B31/'Historical FS'!C40 -> 6.6583489 | D45: ='Data Sheet'!C31/'Historical FS'!D40 -> 6.5400075 | E45: ='Data Sheet'!D31/'Historical FS'!E40 -> 7.642062 | F45: ='Data Sheet'!E31/'Historical FS'!F40 -> -4.9163242 | G45: ='Data Sheet'!F31/'Historical FS'!G40 -> 6.0999626 | H45: ='Data Sheet'!G31/'Historical FS'!H40 -> 10.837505 | I45: ='Data Sheet'!H31/'Historical FS'!I40 -> 15.295629 | J45: ='Data Sheet'!I31/'Historical FS'!J40 -> 19.250654 | ... L45: ='Data Sheet'!K31/'Historical FS'!L40 -> 30.607695
B46: Dividend Payout Ratio | C46: =C45/C42 -> 0.12217665 | D46: =D45/D42 -> 0.13782386 | E46: =E45/E42 -> 0.098433649 | F46: =F45/F42 -> -0.047570819 | G46: =G45/G42 -> 0.068763507 | H46: =H45/H42 -> 0.15830541 | I46: =I45/I42 -> 0.24027491 | J46: =J45/J42 -> 0.21220297 | ... L46: =L45/L42 -> 0.26418766
B48: Retained Earnings | C48: =(1-C46) -> 0.87782335 | D48: =(1-D46) -> 0.86217614 | E48: =(1-E46) -> 0.90156635 | F48: =(1-F46) -> 1.0475708 | G48: =(1-G46) -> 0.93123649 | H48: =(1-H46) -> 0.84169459 | I48: =(1-I46) -> 0.75972509 | J48: =(1-J46) -> 0.78779703 | ... L48: =(1-L46) -> 0.73581234
B50: Balance Sheet
B51: ='Data Sheet'!A57 -> Equity Share Capital | C51: ='Data Sheet'!B57 -> 311 | D51: ='Data Sheet'!C57 -> 543 | E51: ='Data Sheet'!D57 -> 544 | F51: ='Data Sheet'!E57 -> 554 | G51: ='Data Sheet'!F57 -> 555 | H51: ='Data Sheet'!G57 -> 556 | I51: ='Data Sheet'!H57 -> 557 | ... L51: ='Data Sheet'!K57 -> 559
B52: ='Data Sheet'!A58 -> Reserves | C52: ='Data Sheet'!B58 -> 29467 | D52: ='Data Sheet'!C58 -> 36232 | E52: ='Data Sheet'!D58 -> 39439 | F52: ='Data Sheet'!E58 -> 39415 | G52: ='Data Sheet'!F58 -> 41027 | H52: ='Data Sheet'!G58 -> 46567 | I52: ='Data Sheet'!H58 -> 55809 | ... L52: ='Data Sheet'!K58 -> 92538
B53: ='Data Sheet'!A59 -> Borrowings | C53: ='Data Sheet'!B59 -> 48762 | D53: ='Data Sheet'!C59 -> 55898 | E53: ='Data Sheet'!D59 -> 70848 | F53: ='Data Sheet'!E59 -> 82092 | G53: ='Data Sheet'!F59 -> 80625 | H53: ='Data Sheet'!G59 -> 77605 | I53: ='Data Sheet'!H59 -> 92647 | ... L53: ='Data Sheet'!K59 -> 136936
B54: ='Data Sheet'!A60 -> Other Liabilities | C54: ='Data Sheet'!B60 -> 35296 | D54: ='Data Sheet'!C60 -> 43696 | E54: ='Data Sheet'!D60 -> 51057 | F54: ='Data Sheet'!E60 -> 43655 | G54: ='Data Sheet'!F60 -> 42762 | H54: ='Data Sheet'!G60 -> 47661 | I54: ='Data Sheet'!H60 -> 55270 | ... L54: ='Data Sheet'!K60 -> 86021
B55: Total Liabilities | C55: =SUM(C51:C54) -> 113836 | D55: =SUM(D51:D54) -> 136369 | E55: =SUM(E51:E54) -> 161888 | F55: =SUM(F51:F54) -> 165716 | G55: =SUM(G51:G54) -> 164969 | H55: =SUM(H51:H54) -> 172389 | I55: =SUM(I51:I54) -> 204283 | J55: =SUM(J51:J54) -> 234721 | ... L55: =SUM(L51:L54) -> 316054
B57: Fixed Asset Net Block | C57: ='Data Sheet'!B62 -> 20989 | D57: ='Data Sheet'!C62 -> 26182 | E57: ='Data Sheet'!D62 -> 28983 | F57: ='Data Sheet'!E62 -> 29689 | G57: ='Data Sheet'!F62 -> 21380 | H57: ='Data Sheet'!G62 -> 26018 | I57: ='Data Sheet'!H62 -> 27140 | J57: ='Data Sheet'!I62 -> 28129 | ... L57: ='Data Sheet'!K62 -> 38459
B58: ='Data Sheet'!A63 -> Capital Work in Progress | C58: ='Data Sheet'!B63 -> 4279 | D58: ='Data Sheet'!C63 -> 4269 | E58: ='Data Sheet'!D63 -> 4760 | F58: ='Data Sheet'!E63 -> 6856 | G58: ='Data Sheet'!F63 -> 7873 | H58: ='Data Sheet'!G63 -> 6703 | I58: ='Data Sheet'!H63 -> 3969 | ... L58: ='Data Sheet'!K63 -> 7740
B59: ='Data Sheet'!A64 -> Investments | C59: ='Data Sheet'!B64 -> 14662 | D59: ='Data Sheet'!C64 -> 16018 | E59: ='Data Sheet'!D64 -> 18268 | F59: ='Data Sheet'!E64 -> 19210 | G59: ='Data Sheet'!F64 -> 28778 | H59: ='Data Sheet'!G64 -> 30060 | I59: ='Data Sheet'!H64 -> 35272 | ... L59: ='Data Sheet'!K64 -> 40324
...

Sheet Ratio Analysis
B2: ="Ratio Analysis - "&'Data Sheet'!$B$1 -> Ratio Analysis - MAHINDRA & MAHINDRA LTD
